[2022-02-09 20:31:47,571] {taskinstance.py:1032} INFO - Dependencies all met for <TaskInstance: green_taxi_gcs_dag.local_to_gcs_task scheduled__2019-03-02T00:00:00+00:00 [queued]>
[2022-02-09 20:31:47,599] {taskinstance.py:1032} INFO - Dependencies all met for <TaskInstance: green_taxi_gcs_dag.local_to_gcs_task scheduled__2019-03-02T00:00:00+00:00 [queued]>
[2022-02-09 20:31:47,601] {taskinstance.py:1238} INFO - 
--------------------------------------------------------------------------------
[2022-02-09 20:31:47,603] {taskinstance.py:1239} INFO - Starting attempt 1 of 2
[2022-02-09 20:31:47,604] {taskinstance.py:1240} INFO - 
--------------------------------------------------------------------------------
[2022-02-09 20:31:47,630] {taskinstance.py:1259} INFO - Executing <Task(PythonOperator): local_to_gcs_task> on 2019-03-02 00:00:00+00:00
[2022-02-09 20:31:47,641] {standard_task_runner.py:52} INFO - Started process 130 to run task
[2022-02-09 20:31:47,660] {standard_task_runner.py:76} INFO - Running: ['***', 'tasks', 'run', 'green_taxi_gcs_dag', 'local_to_gcs_task', 'scheduled__2019-03-02T00:00:00+00:00', '--job-id', '23', '--raw', '--subdir', 'DAGS_FOLDER/green_gcs_dag.py', '--cfg-path', '/tmp/tmp0id_2egv', '--error-file', '/tmp/tmpb1pjz68g']
[2022-02-09 20:31:47,661] {standard_task_runner.py:77} INFO - Job 23: Subtask local_to_gcs_task
[2022-02-09 20:31:47,880] {logging_mixin.py:109} INFO - Running <TaskInstance: green_taxi_gcs_dag.local_to_gcs_task scheduled__2019-03-02T00:00:00+00:00 [running]> on host 4f97b6b16bdb
[2022-02-09 20:31:48,056] {warnings.py:110} WARNING - /home/***/.local/lib/python3.7/site-packages/***/utils/context.py:152: AirflowContextDeprecationWarning: Accessing 'execution_date' from the template is deprecated and will be removed in a future version. Please use 'data_interval_start' or 'logical_date' instead.
  warnings.warn(_create_deprecation_warning(key, self._deprecation_replacements[key]))

[2022-02-09 20:31:48,144] {taskinstance.py:1426} INFO - Exporting the following env vars:
AIRFLOW_CTX_DAG_OWNER=***
AIRFLOW_CTX_DAG_ID=green_taxi_gcs_dag
AIRFLOW_CTX_TASK_ID=local_to_gcs_task
AIRFLOW_CTX_EXECUTION_DATE=2019-03-02T00:00:00+00:00
AIRFLOW_CTX_DAG_RUN_ID=scheduled__2019-03-02T00:00:00+00:00
[2022-02-09 20:31:51,262] {python.py:175} INFO - Done. Returned value was: None
[2022-02-09 20:31:51,308] {taskinstance.py:1277} INFO - Marking task as SUCCESS. dag_id=green_taxi_gcs_dag, task_id=local_to_gcs_task, execution_date=20190302T000000, start_date=20220209T203147, end_date=20220209T203151
[2022-02-09 20:31:51,420] {local_task_job.py:154} INFO - Task exited with return code 0
[2022-02-09 20:31:51,552] {local_task_job.py:264} INFO - 1 downstream tasks scheduled from follow-on schedule check
[2022-02-09 20:43:00,628] {taskinstance.py:1032} INFO - Dependencies all met for <TaskInstance: green_taxi_gcs_dag.local_to_gcs_task scheduled__2019-03-02T00:00:00+00:00 [queued]>
[2022-02-09 20:43:00,666] {taskinstance.py:1032} INFO - Dependencies all met for <TaskInstance: green_taxi_gcs_dag.local_to_gcs_task scheduled__2019-03-02T00:00:00+00:00 [queued]>
[2022-02-09 20:43:00,667] {taskinstance.py:1238} INFO - 
--------------------------------------------------------------------------------
[2022-02-09 20:43:00,667] {taskinstance.py:1239} INFO - Starting attempt 1 of 2
[2022-02-09 20:43:00,667] {taskinstance.py:1240} INFO - 
--------------------------------------------------------------------------------
[2022-02-09 20:43:00,698] {taskinstance.py:1259} INFO - Executing <Task(PythonOperator): local_to_gcs_task> on 2019-03-02 00:00:00+00:00
[2022-02-09 20:43:00,705] {standard_task_runner.py:52} INFO - Started process 610 to run task
[2022-02-09 20:43:00,715] {standard_task_runner.py:76} INFO - Running: ['***', 'tasks', 'run', 'green_taxi_gcs_dag', 'local_to_gcs_task', 'scheduled__2019-03-02T00:00:00+00:00', '--job-id', '128', '--raw', '--subdir', 'DAGS_FOLDER/green_gcs_dag.py', '--cfg-path', '/tmp/tmprma0yvxg', '--error-file', '/tmp/tmpifjg4fjp']
[2022-02-09 20:43:00,718] {standard_task_runner.py:77} INFO - Job 128: Subtask local_to_gcs_task
[2022-02-09 20:43:00,904] {logging_mixin.py:109} INFO - Running <TaskInstance: green_taxi_gcs_dag.local_to_gcs_task scheduled__2019-03-02T00:00:00+00:00 [running]> on host 4f97b6b16bdb
[2022-02-09 20:43:01,046] {warnings.py:110} WARNING - /home/***/.local/lib/python3.7/site-packages/***/utils/context.py:152: AirflowContextDeprecationWarning: Accessing 'execution_date' from the template is deprecated and will be removed in a future version. Please use 'data_interval_start' or 'logical_date' instead.
  warnings.warn(_create_deprecation_warning(key, self._deprecation_replacements[key]))

[2022-02-09 20:43:01,117] {taskinstance.py:1426} INFO - Exporting the following env vars:
AIRFLOW_CTX_DAG_OWNER=***
AIRFLOW_CTX_DAG_ID=green_taxi_gcs_dag
AIRFLOW_CTX_TASK_ID=local_to_gcs_task
AIRFLOW_CTX_EXECUTION_DATE=2019-03-02T00:00:00+00:00
AIRFLOW_CTX_DAG_RUN_ID=scheduled__2019-03-02T00:00:00+00:00
[2022-02-09 20:43:02,846] {python.py:175} INFO - Done. Returned value was: None
[2022-02-09 20:43:02,877] {taskinstance.py:1277} INFO - Marking task as SUCCESS. dag_id=green_taxi_gcs_dag, task_id=local_to_gcs_task, execution_date=20190302T000000, start_date=20220209T204300, end_date=20220209T204302
[2022-02-09 20:43:02,938] {local_task_job.py:154} INFO - Task exited with return code 0
[2022-02-09 20:43:03,073] {local_task_job.py:264} INFO - 1 downstream tasks scheduled from follow-on schedule check
[2022-02-20 00:01:07,398] {taskinstance.py:1032} INFO - Dependencies all met for <TaskInstance: green_taxi_gcs_dag.local_to_gcs_task scheduled__2019-03-02T00:00:00+00:00 [queued]>
[2022-02-20 00:01:07,414] {taskinstance.py:1032} INFO - Dependencies all met for <TaskInstance: green_taxi_gcs_dag.local_to_gcs_task scheduled__2019-03-02T00:00:00+00:00 [queued]>
[2022-02-20 00:01:07,414] {taskinstance.py:1238} INFO - 
--------------------------------------------------------------------------------
[2022-02-20 00:01:07,414] {taskinstance.py:1239} INFO - Starting attempt 1 of 2
[2022-02-20 00:01:07,414] {taskinstance.py:1240} INFO - 
--------------------------------------------------------------------------------
[2022-02-20 00:01:07,432] {taskinstance.py:1259} INFO - Executing <Task(PythonOperator): local_to_gcs_task> on 2019-03-02 00:00:00+00:00
[2022-02-20 00:01:07,439] {standard_task_runner.py:52} INFO - Started process 393 to run task
[2022-02-20 00:01:07,443] {standard_task_runner.py:76} INFO - Running: ['***', 'tasks', 'run', 'green_taxi_gcs_dag', 'local_to_gcs_task', 'scheduled__2019-03-02T00:00:00+00:00', '--job-id', '319', '--raw', '--subdir', 'DAGS_FOLDER/green_gcs_dag.py', '--cfg-path', '/tmp/tmpfgoz6yjm', '--error-file', '/tmp/tmppyfhoe5z']
[2022-02-20 00:01:07,444] {standard_task_runner.py:77} INFO - Job 319: Subtask local_to_gcs_task
[2022-02-20 00:01:07,529] {logging_mixin.py:109} INFO - Running <TaskInstance: green_taxi_gcs_dag.local_to_gcs_task scheduled__2019-03-02T00:00:00+00:00 [running]> on host da07aa254901
[2022-02-20 00:01:07,604] {warnings.py:110} WARNING - /home/***/.local/lib/python3.7/site-packages/***/utils/context.py:152: AirflowContextDeprecationWarning: Accessing 'execution_date' from the template is deprecated and will be removed in a future version. Please use 'data_interval_start' or 'logical_date' instead.
  warnings.warn(_create_deprecation_warning(key, self._deprecation_replacements[key]))

[2022-02-20 00:01:07,630] {taskinstance.py:1426} INFO - Exporting the following env vars:
AIRFLOW_CTX_DAG_OWNER=***
AIRFLOW_CTX_DAG_ID=green_taxi_gcs_dag
AIRFLOW_CTX_TASK_ID=local_to_gcs_task
AIRFLOW_CTX_EXECUTION_DATE=2019-03-02T00:00:00+00:00
AIRFLOW_CTX_DAG_RUN_ID=scheduled__2019-03-02T00:00:00+00:00
[2022-02-20 00:01:09,867] {python.py:175} INFO - Done. Returned value was: None
[2022-02-20 00:01:09,986] {taskinstance.py:1277} INFO - Marking task as SUCCESS. dag_id=green_taxi_gcs_dag, task_id=local_to_gcs_task, execution_date=20190302T000000, start_date=20220220T000107, end_date=20220220T000109
[2022-02-20 00:01:10,082] {local_task_job.py:154} INFO - Task exited with return code 0
[2022-02-20 00:01:10,189] {local_task_job.py:264} INFO - 1 downstream tasks scheduled from follow-on schedule check
[2022-02-20 01:59:27,663] {taskinstance.py:1032} INFO - Dependencies all met for <TaskInstance: green_taxi_gcs_dag.local_to_gcs_task scheduled__2019-03-02T00:00:00+00:00 [queued]>
[2022-02-20 01:59:27,677] {taskinstance.py:1032} INFO - Dependencies all met for <TaskInstance: green_taxi_gcs_dag.local_to_gcs_task scheduled__2019-03-02T00:00:00+00:00 [queued]>
[2022-02-20 01:59:27,677] {taskinstance.py:1238} INFO - 
--------------------------------------------------------------------------------
[2022-02-20 01:59:27,677] {taskinstance.py:1239} INFO - Starting attempt 1 of 2
[2022-02-20 01:59:27,677] {taskinstance.py:1240} INFO - 
--------------------------------------------------------------------------------
[2022-02-20 01:59:27,692] {taskinstance.py:1259} INFO - Executing <Task(PythonOperator): local_to_gcs_task> on 2019-03-02 00:00:00+00:00
[2022-02-20 01:59:27,698] {standard_task_runner.py:52} INFO - Started process 266 to run task
[2022-02-20 01:59:27,702] {standard_task_runner.py:76} INFO - Running: ['***', 'tasks', 'run', 'green_taxi_gcs_dag', 'local_to_gcs_task', 'scheduled__2019-03-02T00:00:00+00:00', '--job-id', '526', '--raw', '--subdir', 'DAGS_FOLDER/green_gcs_dag.py', '--cfg-path', '/tmp/tmpgbi3wzol', '--error-file', '/tmp/tmpq1i8fqce']
[2022-02-20 01:59:27,703] {standard_task_runner.py:77} INFO - Job 526: Subtask local_to_gcs_task
[2022-02-20 01:59:27,803] {logging_mixin.py:109} INFO - Running <TaskInstance: green_taxi_gcs_dag.local_to_gcs_task scheduled__2019-03-02T00:00:00+00:00 [running]> on host 5484a3a1f7c3
[2022-02-20 01:59:27,865] {warnings.py:110} WARNING - /home/***/.local/lib/python3.7/site-packages/***/utils/context.py:152: AirflowContextDeprecationWarning: Accessing 'execution_date' from the template is deprecated and will be removed in a future version. Please use 'data_interval_start' or 'logical_date' instead.
  warnings.warn(_create_deprecation_warning(key, self._deprecation_replacements[key]))

[2022-02-20 01:59:27,896] {taskinstance.py:1426} INFO - Exporting the following env vars:
AIRFLOW_CTX_DAG_OWNER=***
AIRFLOW_CTX_DAG_ID=green_taxi_gcs_dag
AIRFLOW_CTX_TASK_ID=local_to_gcs_task
AIRFLOW_CTX_EXECUTION_DATE=2019-03-02T00:00:00+00:00
AIRFLOW_CTX_DAG_RUN_ID=scheduled__2019-03-02T00:00:00+00:00
[2022-02-20 01:59:29,759] {python.py:175} INFO - Done. Returned value was: None
[2022-02-20 01:59:29,773] {taskinstance.py:1277} INFO - Marking task as SUCCESS. dag_id=green_taxi_gcs_dag, task_id=local_to_gcs_task, execution_date=20190302T000000, start_date=20220220T015927, end_date=20220220T015929
[2022-02-20 01:59:29,800] {local_task_job.py:154} INFO - Task exited with return code 0
[2022-02-20 01:59:29,838] {local_task_job.py:264} INFO - 1 downstream tasks scheduled from follow-on schedule check
[2022-02-23 20:11:28,916] {taskinstance.py:1032} INFO - Dependencies all met for <TaskInstance: green_taxi_gcs_dag.local_to_gcs_task scheduled__2019-03-02T00:00:00+00:00 [queued]>
[2022-02-23 20:11:28,952] {taskinstance.py:1032} INFO - Dependencies all met for <TaskInstance: green_taxi_gcs_dag.local_to_gcs_task scheduled__2019-03-02T00:00:00+00:00 [queued]>
[2022-02-23 20:11:28,952] {taskinstance.py:1238} INFO - 
--------------------------------------------------------------------------------
[2022-02-23 20:11:28,952] {taskinstance.py:1239} INFO - Starting attempt 1 of 2
[2022-02-23 20:11:28,952] {taskinstance.py:1240} INFO - 
--------------------------------------------------------------------------------
[2022-02-23 20:11:28,996] {taskinstance.py:1259} INFO - Executing <Task(PythonOperator): local_to_gcs_task> on 2019-03-02 00:00:00+00:00
[2022-02-23 20:11:29,006] {standard_task_runner.py:52} INFO - Started process 503 to run task
[2022-02-23 20:11:29,034] {standard_task_runner.py:76} INFO - Running: ['***', 'tasks', 'run', 'green_taxi_gcs_dag', 'local_to_gcs_task', 'scheduled__2019-03-02T00:00:00+00:00', '--job-id', '23', '--raw', '--subdir', 'DAGS_FOLDER/green_gcs_dag.py', '--cfg-path', '/tmp/tmped8vgk_i', '--error-file', '/tmp/tmp_j95_qvx']
[2022-02-23 20:11:29,036] {standard_task_runner.py:77} INFO - Job 23: Subtask local_to_gcs_task
[2022-02-23 20:11:29,222] {logging_mixin.py:109} INFO - Running <TaskInstance: green_taxi_gcs_dag.local_to_gcs_task scheduled__2019-03-02T00:00:00+00:00 [running]> on host 1bb54b80b2ee
[2022-02-23 20:11:29,466] {warnings.py:110} WARNING - /home/***/.local/lib/python3.7/site-packages/***/utils/context.py:152: AirflowContextDeprecationWarning: Accessing 'execution_date' from the template is deprecated and will be removed in a future version. Please use 'data_interval_start' or 'logical_date' instead.
  warnings.warn(_create_deprecation_warning(key, self._deprecation_replacements[key]))

[2022-02-23 20:11:29,614] {taskinstance.py:1426} INFO - Exporting the following env vars:
AIRFLOW_CTX_DAG_OWNER=***
AIRFLOW_CTX_DAG_ID=green_taxi_gcs_dag
AIRFLOW_CTX_TASK_ID=local_to_gcs_task
AIRFLOW_CTX_EXECUTION_DATE=2019-03-02T00:00:00+00:00
AIRFLOW_CTX_DAG_RUN_ID=scheduled__2019-03-02T00:00:00+00:00
[2022-02-23 20:11:30,175] {taskinstance.py:1700} ERROR - Task failed with exception
Traceback (most recent call last):
  File "/home/airflow/.local/lib/python3.7/site-packages/google/cloud/storage/blob.py", line 2594, in upload_from_file
    retry=retry,
  File "/home/airflow/.local/lib/python3.7/site-packages/google/cloud/storage/blob.py", line 2412, in _do_upload
    retry=retry,
  File "/home/airflow/.local/lib/python3.7/site-packages/google/cloud/storage/blob.py", line 2237, in _do_resumable_upload
    retry=retry,
  File "/home/airflow/.local/lib/python3.7/site-packages/google/cloud/storage/blob.py", line 2112, in _initiate_resumable_upload
    timeout=timeout,
  File "/home/airflow/.local/lib/python3.7/site-packages/google/resumable_media/requests/upload.py", line 421, in initiate
    retriable_request, self._get_status_code, self._retry_strategy
  File "/home/airflow/.local/lib/python3.7/site-packages/google/resumable_media/requests/_request_helpers.py", line 147, in wait_and_retry
    response = func()
  File "/home/airflow/.local/lib/python3.7/site-packages/google/resumable_media/requests/upload.py", line 416, in retriable_request
    self._process_initiate_response(result)
  File "/home/airflow/.local/lib/python3.7/site-packages/google/resumable_media/_upload.py", line 503, in _process_initiate_response
    callback=self._make_invalid,
  File "/home/airflow/.local/lib/python3.7/site-packages/google/resumable_media/_helpers.py", line 104, in require_status_code
    *status_codes
google.resumable_media.common.InvalidResponse: ('Request failed with status code', 403, 'Expected one of', <HTTPStatus.OK: 200>, <HTTPStatus.CREATED: 201>)

During handling of the above exception, another exception occurred:

Traceback (most recent call last):
  File "/home/airflow/.local/lib/python3.7/site-packages/airflow/models/taskinstance.py", line 1329, in _run_raw_task
    self._execute_task_with_callbacks(context)
  File "/home/airflow/.local/lib/python3.7/site-packages/airflow/models/taskinstance.py", line 1455, in _execute_task_with_callbacks
    result = self._execute_task(context, self.task)
  File "/home/airflow/.local/lib/python3.7/site-packages/airflow/models/taskinstance.py", line 1511, in _execute_task
    result = execute_callable(context=context)
  File "/home/airflow/.local/lib/python3.7/site-packages/airflow/operators/python.py", line 174, in execute
    return_value = self.execute_callable()
  File "/home/airflow/.local/lib/python3.7/site-packages/airflow/operators/python.py", line 185, in execute_callable
    return self.python_callable(*self.op_args, **self.op_kwargs)
  File "/opt/airflow/dags/green_gcs_dag.py", line 52, in upload_to_gcs
    blob.upload_from_filename(local_file)
  File "/home/airflow/.local/lib/python3.7/site-packages/google/cloud/storage/blob.py", line 2735, in upload_from_filename
    retry=retry,
  File "/home/airflow/.local/lib/python3.7/site-packages/google/cloud/storage/blob.py", line 2598, in upload_from_file
    _raise_from_invalid_response(exc)
  File "/home/airflow/.local/lib/python3.7/site-packages/google/cloud/storage/blob.py", line 4466, in _raise_from_invalid_response
    raise exceptions.from_http_status(response.status_code, message, response=response)
google.api_core.exceptions.Forbidden: 403 POST https://storage.googleapis.com/upload/storage/v1/b/data_lake_taxi_us/o?uploadType=resumable: {
  "error": {
    "code": 403,
    "message": "airflow-ingestion@clear-rock-338918.iam.gserviceaccount.com does not have storage.objects.create access to the Google Cloud Storage bucket.",
    "errors": [
      {
        "message": "airflow-ingestion@clear-rock-338918.iam.gserviceaccount.com does not have storage.objects.create access to the Google Cloud Storage bucket.",
        "domain": "global",
        "reason": "forbidden"
      }
    ]
  }
}
: ('Request failed with status code', 403, 'Expected one of', <HTTPStatus.OK: 200>, <HTTPStatus.CREATED: 201>)
[2022-02-23 20:11:30,256] {taskinstance.py:1277} INFO - Marking task as UP_FOR_RETRY. dag_id=green_taxi_gcs_dag, task_id=local_to_gcs_task, execution_date=20190302T000000, start_date=20220223T201128, end_date=20220223T201130
[2022-02-23 20:11:30,324] {standard_task_runner.py:92} ERROR - Failed to execute job 23 for task local_to_gcs_task
Traceback (most recent call last):
  File "/home/airflow/.local/lib/python3.7/site-packages/google/cloud/storage/blob.py", line 2594, in upload_from_file
    retry=retry,
  File "/home/airflow/.local/lib/python3.7/site-packages/google/cloud/storage/blob.py", line 2412, in _do_upload
    retry=retry,
  File "/home/airflow/.local/lib/python3.7/site-packages/google/cloud/storage/blob.py", line 2237, in _do_resumable_upload
    retry=retry,
  File "/home/airflow/.local/lib/python3.7/site-packages/google/cloud/storage/blob.py", line 2112, in _initiate_resumable_upload
    timeout=timeout,
  File "/home/airflow/.local/lib/python3.7/site-packages/google/resumable_media/requests/upload.py", line 421, in initiate
    retriable_request, self._get_status_code, self._retry_strategy
  File "/home/airflow/.local/lib/python3.7/site-packages/google/resumable_media/requests/_request_helpers.py", line 147, in wait_and_retry
    response = func()
  File "/home/airflow/.local/lib/python3.7/site-packages/google/resumable_media/requests/upload.py", line 416, in retriable_request
    self._process_initiate_response(result)
  File "/home/airflow/.local/lib/python3.7/site-packages/google/resumable_media/_upload.py", line 503, in _process_initiate_response
    callback=self._make_invalid,
  File "/home/airflow/.local/lib/python3.7/site-packages/google/resumable_media/_helpers.py", line 104, in require_status_code
    *status_codes
google.resumable_media.common.InvalidResponse: ('Request failed with status code', 403, 'Expected one of', <HTTPStatus.OK: 200>, <HTTPStatus.CREATED: 201>)

During handling of the above exception, another exception occurred:

Traceback (most recent call last):
  File "/home/airflow/.local/lib/python3.7/site-packages/airflow/task/task_runner/standard_task_runner.py", line 85, in _start_by_fork
    args.func(args, dag=self.dag)
  File "/home/airflow/.local/lib/python3.7/site-packages/airflow/cli/cli_parser.py", line 48, in command
    return func(*args, **kwargs)
  File "/home/airflow/.local/lib/python3.7/site-packages/airflow/utils/cli.py", line 92, in wrapper
    return f(*args, **kwargs)
  File "/home/airflow/.local/lib/python3.7/site-packages/airflow/cli/commands/task_command.py", line 298, in task_run
    _run_task_by_selected_method(args, dag, ti)
  File "/home/airflow/.local/lib/python3.7/site-packages/airflow/cli/commands/task_command.py", line 107, in _run_task_by_selected_method
    _run_raw_task(args, ti)
  File "/home/airflow/.local/lib/python3.7/site-packages/airflow/cli/commands/task_command.py", line 184, in _run_raw_task
    error_file=args.error_file,
  File "/home/airflow/.local/lib/python3.7/site-packages/airflow/utils/session.py", line 70, in wrapper
    return func(*args, session=session, **kwargs)
  File "/home/airflow/.local/lib/python3.7/site-packages/airflow/models/taskinstance.py", line 1329, in _run_raw_task
    self._execute_task_with_callbacks(context)
  File "/home/airflow/.local/lib/python3.7/site-packages/airflow/models/taskinstance.py", line 1455, in _execute_task_with_callbacks
    result = self._execute_task(context, self.task)
  File "/home/airflow/.local/lib/python3.7/site-packages/airflow/models/taskinstance.py", line 1511, in _execute_task
    result = execute_callable(context=context)
  File "/home/airflow/.local/lib/python3.7/site-packages/airflow/operators/python.py", line 174, in execute
    return_value = self.execute_callable()
  File "/home/airflow/.local/lib/python3.7/site-packages/airflow/operators/python.py", line 185, in execute_callable
    return self.python_callable(*self.op_args, **self.op_kwargs)
  File "/opt/airflow/dags/green_gcs_dag.py", line 52, in upload_to_gcs
    blob.upload_from_filename(local_file)
  File "/home/airflow/.local/lib/python3.7/site-packages/google/cloud/storage/blob.py", line 2735, in upload_from_filename
    retry=retry,
  File "/home/airflow/.local/lib/python3.7/site-packages/google/cloud/storage/blob.py", line 2598, in upload_from_file
    _raise_from_invalid_response(exc)
  File "/home/airflow/.local/lib/python3.7/site-packages/google/cloud/storage/blob.py", line 4466, in _raise_from_invalid_response
    raise exceptions.from_http_status(response.status_code, message, response=response)
google.api_core.exceptions.Forbidden: 403 POST https://storage.googleapis.com/upload/storage/v1/b/data_lake_taxi_us/o?uploadType=resumable: {
  "error": {
    "code": 403,
    "message": "airflow-ingestion@clear-rock-338918.iam.gserviceaccount.com does not have storage.objects.create access to the Google Cloud Storage bucket.",
    "errors": [
      {
        "message": "airflow-ingestion@clear-rock-338918.iam.gserviceaccount.com does not have storage.objects.create access to the Google Cloud Storage bucket.",
        "domain": "global",
        "reason": "forbidden"
      }
    ]
  }
}
: ('Request failed with status code', 403, 'Expected one of', <HTTPStatus.OK: 200>, <HTTPStatus.CREATED: 201>)
[2022-02-23 20:11:30,352] {local_task_job.py:154} INFO - Task exited with return code 1
[2022-02-23 20:11:30,614] {local_task_job.py:264} INFO - 0 downstream tasks scheduled from follow-on schedule check
