[2022-02-03 16:46:20,094] {taskinstance.py:1032} INFO - Dependencies all met for <TaskInstance: yellow_taxi_gcs_dag.local_to_gcs_task scheduled__2019-01-02T00:00:00+00:00 [queued]>
[2022-02-03 16:46:20,119] {taskinstance.py:1032} INFO - Dependencies all met for <TaskInstance: yellow_taxi_gcs_dag.local_to_gcs_task scheduled__2019-01-02T00:00:00+00:00 [queued]>
[2022-02-03 16:46:20,120] {taskinstance.py:1238} INFO - 
--------------------------------------------------------------------------------
[2022-02-03 16:46:20,120] {taskinstance.py:1239} INFO - Starting attempt 1 of 2
[2022-02-03 16:46:20,120] {taskinstance.py:1240} INFO - 
--------------------------------------------------------------------------------
[2022-02-03 16:46:20,170] {taskinstance.py:1259} INFO - Executing <Task(PythonOperator): local_to_gcs_task> on 2019-01-02 00:00:00+00:00
[2022-02-03 16:46:20,180] {standard_task_runner.py:52} INFO - Started process 962 to run task
[2022-02-03 16:46:20,190] {standard_task_runner.py:76} INFO - Running: ['***', 'tasks', 'run', 'yellow_taxi_gcs_dag', 'local_to_gcs_task', 'scheduled__2019-01-02T00:00:00+00:00', '--job-id', '22', '--raw', '--subdir', 'DAGS_FOLDER/yellow_taxi_gcs_dag.py', '--cfg-path', '/tmp/tmpqkgra7sl', '--error-file', '/tmp/tmpv5omluhc']
[2022-02-03 16:46:20,192] {standard_task_runner.py:77} INFO - Job 22: Subtask local_to_gcs_task
[2022-02-03 16:46:20,376] {logging_mixin.py:109} INFO - Running <TaskInstance: yellow_taxi_gcs_dag.local_to_gcs_task scheduled__2019-01-02T00:00:00+00:00 [running]> on host 7e458922b35d
[2022-02-03 16:46:20,470] {warnings.py:110} WARNING - /home/***/.local/lib/python3.7/site-packages/***/utils/context.py:152: AirflowContextDeprecationWarning: Accessing 'execution_date' from the template is deprecated and will be removed in a future version. Please use 'data_interval_start' or 'logical_date' instead.
  warnings.warn(_create_deprecation_warning(key, self._deprecation_replacements[key]))

[2022-02-03 16:46:20,524] {taskinstance.py:1426} INFO - Exporting the following env vars:
AIRFLOW_CTX_DAG_OWNER=***
AIRFLOW_CTX_DAG_ID=yellow_taxi_gcs_dag
AIRFLOW_CTX_TASK_ID=local_to_gcs_task
AIRFLOW_CTX_EXECUTION_DATE=2019-01-02T00:00:00+00:00
AIRFLOW_CTX_DAG_RUN_ID=scheduled__2019-01-02T00:00:00+00:00
[2022-02-03 16:46:38,119] {python.py:175} INFO - Done. Returned value was: None
[2022-02-03 16:46:38,133] {taskinstance.py:1277} INFO - Marking task as SUCCESS. dag_id=yellow_taxi_gcs_dag, task_id=local_to_gcs_task, execution_date=20190102T000000, start_date=20220203T164620, end_date=20220203T164638
[2022-02-03 16:46:38,166] {local_task_job.py:154} INFO - Task exited with return code 0
[2022-02-03 16:46:38,206] {local_task_job.py:264} INFO - 0 downstream tasks scheduled from follow-on schedule check
[2022-02-03 16:57:41,302] {taskinstance.py:1032} INFO - Dependencies all met for <TaskInstance: yellow_taxi_gcs_dag.local_to_gcs_task scheduled__2019-01-02T00:00:00+00:00 [queued]>
[2022-02-03 16:57:41,336] {taskinstance.py:1032} INFO - Dependencies all met for <TaskInstance: yellow_taxi_gcs_dag.local_to_gcs_task scheduled__2019-01-02T00:00:00+00:00 [queued]>
[2022-02-03 16:57:41,336] {taskinstance.py:1238} INFO - 
--------------------------------------------------------------------------------
[2022-02-03 16:57:41,336] {taskinstance.py:1239} INFO - Starting attempt 1 of 2
[2022-02-03 16:57:41,336] {taskinstance.py:1240} INFO - 
--------------------------------------------------------------------------------
[2022-02-03 16:57:41,362] {taskinstance.py:1259} INFO - Executing <Task(PythonOperator): local_to_gcs_task> on 2019-01-02 00:00:00+00:00
[2022-02-03 16:57:41,376] {standard_task_runner.py:52} INFO - Started process 1506 to run task
[2022-02-03 16:57:41,384] {standard_task_runner.py:76} INFO - Running: ['***', 'tasks', 'run', 'yellow_taxi_gcs_dag', 'local_to_gcs_task', 'scheduled__2019-01-02T00:00:00+00:00', '--job-id', '35', '--raw', '--subdir', 'DAGS_FOLDER/yellow_taxi_gcs_dag.py', '--cfg-path', '/tmp/tmpsrsox3em', '--error-file', '/tmp/tmp43ltpg0j']
[2022-02-03 16:57:41,385] {standard_task_runner.py:77} INFO - Job 35: Subtask local_to_gcs_task
[2022-02-03 16:57:41,475] {logging_mixin.py:109} INFO - Running <TaskInstance: yellow_taxi_gcs_dag.local_to_gcs_task scheduled__2019-01-02T00:00:00+00:00 [running]> on host 7e458922b35d
[2022-02-03 16:57:41,544] {warnings.py:110} WARNING - /home/***/.local/lib/python3.7/site-packages/***/utils/context.py:152: AirflowContextDeprecationWarning: Accessing 'execution_date' from the template is deprecated and will be removed in a future version. Please use 'data_interval_start' or 'logical_date' instead.
  warnings.warn(_create_deprecation_warning(key, self._deprecation_replacements[key]))

[2022-02-03 16:57:41,589] {taskinstance.py:1426} INFO - Exporting the following env vars:
AIRFLOW_CTX_DAG_OWNER=***
AIRFLOW_CTX_DAG_ID=yellow_taxi_gcs_dag
AIRFLOW_CTX_TASK_ID=local_to_gcs_task
AIRFLOW_CTX_EXECUTION_DATE=2019-01-02T00:00:00+00:00
AIRFLOW_CTX_DAG_RUN_ID=scheduled__2019-01-02T00:00:00+00:00
[2022-02-03 16:57:56,530] {python.py:175} INFO - Done. Returned value was: None
[2022-02-03 16:57:56,548] {taskinstance.py:1277} INFO - Marking task as SUCCESS. dag_id=yellow_taxi_gcs_dag, task_id=local_to_gcs_task, execution_date=20190102T000000, start_date=20220203T165741, end_date=20220203T165756
[2022-02-03 16:57:56,595] {local_task_job.py:154} INFO - Task exited with return code 0
[2022-02-03 16:57:56,724] {local_task_job.py:264} INFO - 1 downstream tasks scheduled from follow-on schedule check
[2022-02-03 17:12:56,814] {taskinstance.py:1032} INFO - Dependencies all met for <TaskInstance: yellow_taxi_gcs_dag.local_to_gcs_task scheduled__2019-01-02T00:00:00+00:00 [queued]>
[2022-02-03 17:12:56,828] {taskinstance.py:1032} INFO - Dependencies all met for <TaskInstance: yellow_taxi_gcs_dag.local_to_gcs_task scheduled__2019-01-02T00:00:00+00:00 [queued]>
[2022-02-03 17:12:56,828] {taskinstance.py:1238} INFO - 
--------------------------------------------------------------------------------
[2022-02-03 17:12:56,828] {taskinstance.py:1239} INFO - Starting attempt 1 of 2
[2022-02-03 17:12:56,828] {taskinstance.py:1240} INFO - 
--------------------------------------------------------------------------------
[2022-02-03 17:12:56,844] {taskinstance.py:1259} INFO - Executing <Task(PythonOperator): local_to_gcs_task> on 2019-01-02 00:00:00+00:00
[2022-02-03 17:12:56,854] {standard_task_runner.py:52} INFO - Started process 2176 to run task
[2022-02-03 17:12:56,858] {standard_task_runner.py:76} INFO - Running: ['***', 'tasks', 'run', 'yellow_taxi_gcs_dag', 'local_to_gcs_task', 'scheduled__2019-01-02T00:00:00+00:00', '--job-id', '48', '--raw', '--subdir', 'DAGS_FOLDER/yellow_taxi_gcs_dag.py', '--cfg-path', '/tmp/tmpf2mbqhzh', '--error-file', '/tmp/tmpb89uq19x']
[2022-02-03 17:12:56,859] {standard_task_runner.py:77} INFO - Job 48: Subtask local_to_gcs_task
[2022-02-03 17:12:56,923] {logging_mixin.py:109} INFO - Running <TaskInstance: yellow_taxi_gcs_dag.local_to_gcs_task scheduled__2019-01-02T00:00:00+00:00 [running]> on host 7e458922b35d
[2022-02-03 17:12:56,966] {warnings.py:110} WARNING - /home/***/.local/lib/python3.7/site-packages/***/utils/context.py:152: AirflowContextDeprecationWarning: Accessing 'execution_date' from the template is deprecated and will be removed in a future version. Please use 'data_interval_start' or 'logical_date' instead.
  warnings.warn(_create_deprecation_warning(key, self._deprecation_replacements[key]))

[2022-02-03 17:12:56,988] {taskinstance.py:1426} INFO - Exporting the following env vars:
AIRFLOW_CTX_DAG_OWNER=***
AIRFLOW_CTX_DAG_ID=yellow_taxi_gcs_dag
AIRFLOW_CTX_TASK_ID=local_to_gcs_task
AIRFLOW_CTX_EXECUTION_DATE=2019-01-02T00:00:00+00:00
AIRFLOW_CTX_DAG_RUN_ID=scheduled__2019-01-02T00:00:00+00:00
[2022-02-03 17:13:17,984] {python.py:175} INFO - Done. Returned value was: None
[2022-02-03 17:13:18,010] {taskinstance.py:1277} INFO - Marking task as SUCCESS. dag_id=yellow_taxi_gcs_dag, task_id=local_to_gcs_task, execution_date=20190102T000000, start_date=20220203T171256, end_date=20220203T171318
[2022-02-03 17:13:18,110] {local_task_job.py:154} INFO - Task exited with return code 0
[2022-02-03 17:13:18,192] {local_task_job.py:264} INFO - 1 downstream tasks scheduled from follow-on schedule check
<<<<<<< HEAD
[2022-02-19 23:54:02,019] {taskinstance.py:1032} INFO - Dependencies all met for <TaskInstance: yellow_taxi_gcs_dag.local_to_gcs_task scheduled__2019-01-02T00:00:00+00:00 [queued]>
[2022-02-19 23:54:02,055] {taskinstance.py:1032} INFO - Dependencies all met for <TaskInstance: yellow_taxi_gcs_dag.local_to_gcs_task scheduled__2019-01-02T00:00:00+00:00 [queued]>
[2022-02-19 23:54:02,055] {taskinstance.py:1238} INFO - 
--------------------------------------------------------------------------------
[2022-02-19 23:54:02,056] {taskinstance.py:1239} INFO - Starting attempt 1 of 2
[2022-02-19 23:54:02,056] {taskinstance.py:1240} INFO - 
--------------------------------------------------------------------------------
[2022-02-19 23:54:02,085] {taskinstance.py:1259} INFO - Executing <Task(PythonOperator): local_to_gcs_task> on 2019-01-02 00:00:00+00:00
[2022-02-19 23:54:02,103] {standard_task_runner.py:52} INFO - Started process 899 to run task
[2022-02-19 23:54:02,120] {standard_task_runner.py:76} INFO - Running: ['***', 'tasks', 'run', 'yellow_taxi_gcs_dag', 'local_to_gcs_task', 'scheduled__2019-01-02T00:00:00+00:00', '--job-id', '255', '--raw', '--subdir', 'DAGS_FOLDER/yellow_taxi_gcs_dag.py', '--cfg-path', '/tmp/tmp5w2cemai', '--error-file', '/tmp/tmpew61taim']
[2022-02-19 23:54:02,121] {standard_task_runner.py:77} INFO - Job 255: Subtask local_to_gcs_task
[2022-02-19 23:54:02,286] {logging_mixin.py:109} INFO - Running <TaskInstance: yellow_taxi_gcs_dag.local_to_gcs_task scheduled__2019-01-02T00:00:00+00:00 [running]> on host 812dd7ecce85
[2022-02-19 23:54:02,389] {warnings.py:110} WARNING - /home/***/.local/lib/python3.7/site-packages/***/utils/context.py:152: AirflowContextDeprecationWarning: Accessing 'execution_date' from the template is deprecated and will be removed in a future version. Please use 'data_interval_start' or 'logical_date' instead.
  warnings.warn(_create_deprecation_warning(key, self._deprecation_replacements[key]))

[2022-02-19 23:54:02,445] {taskinstance.py:1426} INFO - Exporting the following env vars:
AIRFLOW_CTX_DAG_OWNER=***
AIRFLOW_CTX_DAG_ID=yellow_taxi_gcs_dag
AIRFLOW_CTX_TASK_ID=local_to_gcs_task
AIRFLOW_CTX_EXECUTION_DATE=2019-01-02T00:00:00+00:00
AIRFLOW_CTX_DAG_RUN_ID=scheduled__2019-01-02T00:00:00+00:00
[2022-02-19 23:54:02,990] {taskinstance.py:1700} ERROR - Task failed with exception
Traceback (most recent call last):
  File "/home/airflow/.local/lib/python3.7/site-packages/google/cloud/storage/blob.py", line 2594, in upload_from_file
    retry=retry,
  File "/home/airflow/.local/lib/python3.7/site-packages/google/cloud/storage/blob.py", line 2412, in _do_upload
    retry=retry,
  File "/home/airflow/.local/lib/python3.7/site-packages/google/cloud/storage/blob.py", line 2237, in _do_resumable_upload
    retry=retry,
  File "/home/airflow/.local/lib/python3.7/site-packages/google/cloud/storage/blob.py", line 2112, in _initiate_resumable_upload
    timeout=timeout,
  File "/home/airflow/.local/lib/python3.7/site-packages/google/resumable_media/requests/upload.py", line 421, in initiate
    retriable_request, self._get_status_code, self._retry_strategy
  File "/home/airflow/.local/lib/python3.7/site-packages/google/resumable_media/requests/_request_helpers.py", line 147, in wait_and_retry
    response = func()
  File "/home/airflow/.local/lib/python3.7/site-packages/google/resumable_media/requests/upload.py", line 416, in retriable_request
    self._process_initiate_response(result)
  File "/home/airflow/.local/lib/python3.7/site-packages/google/resumable_media/_upload.py", line 503, in _process_initiate_response
    callback=self._make_invalid,
  File "/home/airflow/.local/lib/python3.7/site-packages/google/resumable_media/_helpers.py", line 104, in require_status_code
    *status_codes
google.resumable_media.common.InvalidResponse: ('Request failed with status code', 404, 'Expected one of', <HTTPStatus.OK: 200>, <HTTPStatus.CREATED: 201>)

During handling of the above exception, another exception occurred:

Traceback (most recent call last):
  File "/home/airflow/.local/lib/python3.7/site-packages/airflow/models/taskinstance.py", line 1329, in _run_raw_task
    self._execute_task_with_callbacks(context)
  File "/home/airflow/.local/lib/python3.7/site-packages/airflow/models/taskinstance.py", line 1455, in _execute_task_with_callbacks
    result = self._execute_task(context, self.task)
  File "/home/airflow/.local/lib/python3.7/site-packages/airflow/models/taskinstance.py", line 1511, in _execute_task
    result = execute_callable(context=context)
  File "/home/airflow/.local/lib/python3.7/site-packages/airflow/operators/python.py", line 174, in execute
    return_value = self.execute_callable()
  File "/home/airflow/.local/lib/python3.7/site-packages/airflow/operators/python.py", line 185, in execute_callable
    return self.python_callable(*self.op_args, **self.op_kwargs)
  File "/opt/airflow/dags/yellow_taxi_gcs_dag.py", line 52, in upload_to_gcs
    blob.upload_from_filename(local_file)
  File "/home/airflow/.local/lib/python3.7/site-packages/google/cloud/storage/blob.py", line 2735, in upload_from_filename
    retry=retry,
  File "/home/airflow/.local/lib/python3.7/site-packages/google/cloud/storage/blob.py", line 2598, in upload_from_file
    _raise_from_invalid_response(exc)
  File "/home/airflow/.local/lib/python3.7/site-packages/google/cloud/storage/blob.py", line 4466, in _raise_from_invalid_response
    raise exceptions.from_http_status(response.status_code, message, response=response)
google.api_core.exceptions.NotFound: 404 POST https://storage.googleapis.com/upload/storage/v1/b/dtc_data_lake_clear-rock-338918/o?uploadType=resumable: {
  "error": {
    "code": 404,
    "message": "The specified bucket does not exist.",
    "errors": [
      {
        "message": "The specified bucket does not exist.",
        "domain": "global",
        "reason": "notFound"
      }
    ]
  }
}
: ('Request failed with status code', 404, 'Expected one of', <HTTPStatus.OK: 200>, <HTTPStatus.CREATED: 201>)
[2022-02-19 23:54:03,041] {taskinstance.py:1277} INFO - Marking task as UP_FOR_RETRY. dag_id=yellow_taxi_gcs_dag, task_id=local_to_gcs_task, execution_date=20190102T000000, start_date=20220219T235402, end_date=20220219T235403
[2022-02-19 23:54:03,106] {standard_task_runner.py:92} ERROR - Failed to execute job 255 for task local_to_gcs_task
Traceback (most recent call last):
  File "/home/airflow/.local/lib/python3.7/site-packages/google/cloud/storage/blob.py", line 2594, in upload_from_file
    retry=retry,
  File "/home/airflow/.local/lib/python3.7/site-packages/google/cloud/storage/blob.py", line 2412, in _do_upload
    retry=retry,
  File "/home/airflow/.local/lib/python3.7/site-packages/google/cloud/storage/blob.py", line 2237, in _do_resumable_upload
    retry=retry,
  File "/home/airflow/.local/lib/python3.7/site-packages/google/cloud/storage/blob.py", line 2112, in _initiate_resumable_upload
    timeout=timeout,
  File "/home/airflow/.local/lib/python3.7/site-packages/google/resumable_media/requests/upload.py", line 421, in initiate
    retriable_request, self._get_status_code, self._retry_strategy
  File "/home/airflow/.local/lib/python3.7/site-packages/google/resumable_media/requests/_request_helpers.py", line 147, in wait_and_retry
    response = func()
  File "/home/airflow/.local/lib/python3.7/site-packages/google/resumable_media/requests/upload.py", line 416, in retriable_request
    self._process_initiate_response(result)
  File "/home/airflow/.local/lib/python3.7/site-packages/google/resumable_media/_upload.py", line 503, in _process_initiate_response
    callback=self._make_invalid,
  File "/home/airflow/.local/lib/python3.7/site-packages/google/resumable_media/_helpers.py", line 104, in require_status_code
    *status_codes
google.resumable_media.common.InvalidResponse: ('Request failed with status code', 404, 'Expected one of', <HTTPStatus.OK: 200>, <HTTPStatus.CREATED: 201>)

During handling of the above exception, another exception occurred:

Traceback (most recent call last):
  File "/home/airflow/.local/lib/python3.7/site-packages/airflow/task/task_runner/standard_task_runner.py", line 85, in _start_by_fork
    args.func(args, dag=self.dag)
  File "/home/airflow/.local/lib/python3.7/site-packages/airflow/cli/cli_parser.py", line 48, in command
    return func(*args, **kwargs)
  File "/home/airflow/.local/lib/python3.7/site-packages/airflow/utils/cli.py", line 92, in wrapper
    return f(*args, **kwargs)
  File "/home/airflow/.local/lib/python3.7/site-packages/airflow/cli/commands/task_command.py", line 298, in task_run
    _run_task_by_selected_method(args, dag, ti)
  File "/home/airflow/.local/lib/python3.7/site-packages/airflow/cli/commands/task_command.py", line 107, in _run_task_by_selected_method
    _run_raw_task(args, ti)
  File "/home/airflow/.local/lib/python3.7/site-packages/airflow/cli/commands/task_command.py", line 184, in _run_raw_task
    error_file=args.error_file,
  File "/home/airflow/.local/lib/python3.7/site-packages/airflow/utils/session.py", line 70, in wrapper
    return func(*args, session=session, **kwargs)
  File "/home/airflow/.local/lib/python3.7/site-packages/airflow/models/taskinstance.py", line 1329, in _run_raw_task
    self._execute_task_with_callbacks(context)
  File "/home/airflow/.local/lib/python3.7/site-packages/airflow/models/taskinstance.py", line 1455, in _execute_task_with_callbacks
    result = self._execute_task(context, self.task)
  File "/home/airflow/.local/lib/python3.7/site-packages/airflow/models/taskinstance.py", line 1511, in _execute_task
    result = execute_callable(context=context)
  File "/home/airflow/.local/lib/python3.7/site-packages/airflow/operators/python.py", line 174, in execute
    return_value = self.execute_callable()
  File "/home/airflow/.local/lib/python3.7/site-packages/airflow/operators/python.py", line 185, in execute_callable
    return self.python_callable(*self.op_args, **self.op_kwargs)
  File "/opt/airflow/dags/yellow_taxi_gcs_dag.py", line 52, in upload_to_gcs
    blob.upload_from_filename(local_file)
  File "/home/airflow/.local/lib/python3.7/site-packages/google/cloud/storage/blob.py", line 2735, in upload_from_filename
    retry=retry,
  File "/home/airflow/.local/lib/python3.7/site-packages/google/cloud/storage/blob.py", line 2598, in upload_from_file
    _raise_from_invalid_response(exc)
  File "/home/airflow/.local/lib/python3.7/site-packages/google/cloud/storage/blob.py", line 4466, in _raise_from_invalid_response
    raise exceptions.from_http_status(response.status_code, message, response=response)
google.api_core.exceptions.NotFound: 404 POST https://storage.googleapis.com/upload/storage/v1/b/dtc_data_lake_clear-rock-338918/o?uploadType=resumable: {
  "error": {
    "code": 404,
    "message": "The specified bucket does not exist.",
    "errors": [
      {
        "message": "The specified bucket does not exist.",
        "domain": "global",
        "reason": "notFound"
      }
    ]
  }
}
: ('Request failed with status code', 404, 'Expected one of', <HTTPStatus.OK: 200>, <HTTPStatus.CREATED: 201>)
[2022-02-19 23:54:03,190] {local_task_job.py:154} INFO - Task exited with return code 1
[2022-02-19 23:54:03,375] {local_task_job.py:264} INFO - 0 downstream tasks scheduled from follow-on schedule check
=======
>>>>>>> origin/master
