[2022-02-03 13:33:04,156] {taskinstance.py:1032} INFO - Dependencies all met for <TaskInstance: yellow_taxi_gcs_dag.format_to_parquet_task manual__2022-02-03T13:23:59.393871+00:00 [queued]>
[2022-02-03 13:33:04,190] {taskinstance.py:1032} INFO - Dependencies all met for <TaskInstance: yellow_taxi_gcs_dag.format_to_parquet_task manual__2022-02-03T13:23:59.393871+00:00 [queued]>
[2022-02-03 13:33:04,190] {taskinstance.py:1238} INFO - 
--------------------------------------------------------------------------------
[2022-02-03 13:33:04,191] {taskinstance.py:1239} INFO - Starting attempt 2 of 2
[2022-02-03 13:33:04,191] {taskinstance.py:1240} INFO - 
--------------------------------------------------------------------------------
[2022-02-03 13:33:04,211] {taskinstance.py:1259} INFO - Executing <Task(PythonOperator): format_to_parquet_task> on 2022-02-03 13:23:59.393871+00:00
[2022-02-03 13:33:04,218] {standard_task_runner.py:52} INFO - Started process 868 to run task
[2022-02-03 13:33:04,226] {standard_task_runner.py:76} INFO - Running: ['***', 'tasks', 'run', 'yellow_taxi_gcs_dag', 'format_to_parquet_task', 'manual__2022-02-03T13:23:59.393871+00:00', '--job-id', '17', '--raw', '--subdir', 'DAGS_FOLDER/yellow_taxi_gcs_dag.py', '--cfg-path', '/tmp/tmposofn8h2', '--error-file', '/tmp/tmphtple8bj']
[2022-02-03 13:33:04,227] {standard_task_runner.py:77} INFO - Job 17: Subtask format_to_parquet_task
[2022-02-03 13:33:04,326] {logging_mixin.py:109} INFO - Running <TaskInstance: yellow_taxi_gcs_dag.format_to_parquet_task manual__2022-02-03T13:23:59.393871+00:00 [running]> on host 2b92176b720f
[2022-02-03 13:33:04,413] {taskinstance.py:1426} INFO - Exporting the following env vars:
AIRFLOW_CTX_DAG_OWNER=***
AIRFLOW_CTX_DAG_ID=yellow_taxi_gcs_dag
AIRFLOW_CTX_TASK_ID=format_to_parquet_task
AIRFLOW_CTX_EXECUTION_DATE=2022-02-03T13:23:59.393871+00:00
AIRFLOW_CTX_DAG_RUN_ID=manual__2022-02-03T13:23:59.393871+00:00
[2022-02-03 13:33:14,596] {local_task_job.py:212} WARNING - State of this instance has been externally set to restarting. Terminating instance.
[2022-02-03 13:33:14,631] {process_utils.py:124} INFO - Sending Signals.SIGTERM to group 868. PIDs of all processes in the group: [868]
[2022-02-03 13:33:14,631] {process_utils.py:75} INFO - Sending the signal Signals.SIGTERM to group 868
[2022-02-03 13:33:15,570] {taskinstance.py:1408} ERROR - Received SIGTERM. Terminating subprocesses.
[2022-02-03 13:33:15,732] {taskinstance.py:1700} ERROR - Task failed with exception
Traceback (most recent call last):
  File "pyarrow/_csv.pyx", line 876, in pyarrow._csv.read_csv
  File "pyarrow/error.pxi", line 143, in pyarrow.lib.pyarrow_internal_check_status
  File "pyarrow/error.pxi", line 132, in pyarrow.lib.check_status
pyarrow.lib.ArrowCancelled: Operation cancelled. Detail: received signal 15

During handling of the above exception, another exception occurred:

Traceback (most recent call last):
  File "/home/airflow/.local/lib/python3.7/site-packages/airflow/models/taskinstance.py", line 1329, in _run_raw_task
    self._execute_task_with_callbacks(context)
  File "/home/airflow/.local/lib/python3.7/site-packages/airflow/models/taskinstance.py", line 1455, in _execute_task_with_callbacks
    result = self._execute_task(context, self.task)
  File "/home/airflow/.local/lib/python3.7/site-packages/airflow/models/taskinstance.py", line 1511, in _execute_task
    result = execute_callable(context=context)
  File "/home/airflow/.local/lib/python3.7/site-packages/airflow/operators/python.py", line 174, in execute
    return_value = self.execute_callable()
  File "/home/airflow/.local/lib/python3.7/site-packages/airflow/operators/python.py", line 185, in execute_callable
    return self.python_callable(*self.op_args, **self.op_kwargs)
  File "/opt/airflow/dags/yellow_taxi_gcs_dag.py", line 33, in format_to_parquet
    table = pv.read_csv(src_file)
  File "pyarrow/_csv.pyx", line 867, in pyarrow._csv.read_csv
  File "pyarrow/error.pxi", line 231, in pyarrow.lib.SignalStopHandler.__exit__
  File "/home/airflow/.local/lib/python3.7/site-packages/airflow/models/taskinstance.py", line 1410, in signal_handler
    raise AirflowException("Task received SIGTERM signal")
airflow.exceptions.AirflowException: Task received SIGTERM signal
[2022-02-03 13:33:15,761] {taskinstance.py:1277} INFO - Marking task as UP_FOR_RETRY. dag_id=yellow_taxi_gcs_dag, task_id=format_to_parquet_task, execution_date=20220203T132359, start_date=20220203T133304, end_date=20220203T133315
[2022-02-03 13:33:15,817] {standard_task_runner.py:92} ERROR - Failed to execute job 17 for task format_to_parquet_task
Traceback (most recent call last):
  File "pyarrow/_csv.pyx", line 876, in pyarrow._csv.read_csv
  File "pyarrow/error.pxi", line 143, in pyarrow.lib.pyarrow_internal_check_status
  File "pyarrow/error.pxi", line 132, in pyarrow.lib.check_status
pyarrow.lib.ArrowCancelled: Operation cancelled. Detail: received signal 15

During handling of the above exception, another exception occurred:

Traceback (most recent call last):
  File "/home/airflow/.local/lib/python3.7/site-packages/airflow/task/task_runner/standard_task_runner.py", line 85, in _start_by_fork
    args.func(args, dag=self.dag)
  File "/home/airflow/.local/lib/python3.7/site-packages/airflow/cli/cli_parser.py", line 48, in command
    return func(*args, **kwargs)
  File "/home/airflow/.local/lib/python3.7/site-packages/airflow/utils/cli.py", line 92, in wrapper
    return f(*args, **kwargs)
  File "/home/airflow/.local/lib/python3.7/site-packages/airflow/cli/commands/task_command.py", line 298, in task_run
    _run_task_by_selected_method(args, dag, ti)
  File "/home/airflow/.local/lib/python3.7/site-packages/airflow/cli/commands/task_command.py", line 107, in _run_task_by_selected_method
    _run_raw_task(args, ti)
  File "/home/airflow/.local/lib/python3.7/site-packages/airflow/cli/commands/task_command.py", line 184, in _run_raw_task
    error_file=args.error_file,
  File "/home/airflow/.local/lib/python3.7/site-packages/airflow/utils/session.py", line 70, in wrapper
    return func(*args, session=session, **kwargs)
  File "/home/airflow/.local/lib/python3.7/site-packages/airflow/models/taskinstance.py", line 1329, in _run_raw_task
    self._execute_task_with_callbacks(context)
  File "/home/airflow/.local/lib/python3.7/site-packages/airflow/models/taskinstance.py", line 1455, in _execute_task_with_callbacks
    result = self._execute_task(context, self.task)
  File "/home/airflow/.local/lib/python3.7/site-packages/airflow/models/taskinstance.py", line 1511, in _execute_task
    result = execute_callable(context=context)
  File "/home/airflow/.local/lib/python3.7/site-packages/airflow/operators/python.py", line 174, in execute
    return_value = self.execute_callable()
  File "/home/airflow/.local/lib/python3.7/site-packages/airflow/operators/python.py", line 185, in execute_callable
    return self.python_callable(*self.op_args, **self.op_kwargs)
  File "/opt/airflow/dags/yellow_taxi_gcs_dag.py", line 33, in format_to_parquet
    table = pv.read_csv(src_file)
  File "pyarrow/_csv.pyx", line 867, in pyarrow._csv.read_csv
  File "pyarrow/error.pxi", line 231, in pyarrow.lib.SignalStopHandler.__exit__
  File "/home/airflow/.local/lib/python3.7/site-packages/airflow/models/taskinstance.py", line 1410, in signal_handler
    raise AirflowException("Task received SIGTERM signal")
airflow.exceptions.AirflowException: Task received SIGTERM signal
[2022-02-03 13:33:16,861] {process_utils.py:70} INFO - Process psutil.Process(pid=868, status='terminated', exitcode=1, started='13:33:04') (868) terminated with exit code 1
