[2022-02-09 20:23:39,264] {taskinstance.py:1032} INFO - Dependencies all met for <TaskInstance: green_taxi_gcs_dag.local_to_gcs_task scheduled__2019-01-02T00:00:00+00:00 [queued]>
[2022-02-09 20:23:39,299] {taskinstance.py:1032} INFO - Dependencies all met for <TaskInstance: green_taxi_gcs_dag.local_to_gcs_task scheduled__2019-01-02T00:00:00+00:00 [queued]>
[2022-02-09 20:23:39,300] {taskinstance.py:1238} INFO - 
--------------------------------------------------------------------------------
[2022-02-09 20:23:39,300] {taskinstance.py:1239} INFO - Starting attempt 1 of 2
[2022-02-09 20:23:39,300] {taskinstance.py:1240} INFO - 
--------------------------------------------------------------------------------
[2022-02-09 20:23:39,350] {taskinstance.py:1259} INFO - Executing <Task(PythonOperator): local_to_gcs_task> on 2019-01-02 00:00:00+00:00
[2022-02-09 20:23:39,369] {standard_task_runner.py:52} INFO - Started process 163 to run task
[2022-02-09 20:23:39,379] {standard_task_runner.py:76} INFO - Running: ['***', 'tasks', 'run', 'green_taxi_gcs_dag', 'local_to_gcs_task', 'scheduled__2019-01-02T00:00:00+00:00', '--job-id', '7', '--raw', '--subdir', 'DAGS_FOLDER/green_gcs_dag.py', '--cfg-path', '/tmp/tmpe21_dl5y', '--error-file', '/tmp/tmpjw_hqzor']
[2022-02-09 20:23:39,381] {standard_task_runner.py:77} INFO - Job 7: Subtask local_to_gcs_task
[2022-02-09 20:23:39,505] {logging_mixin.py:109} INFO - Running <TaskInstance: green_taxi_gcs_dag.local_to_gcs_task scheduled__2019-01-02T00:00:00+00:00 [running]> on host c9ca302aeee6
[2022-02-09 20:23:39,623] {warnings.py:110} WARNING - /home/***/.local/lib/python3.7/site-packages/***/utils/context.py:152: AirflowContextDeprecationWarning: Accessing 'execution_date' from the template is deprecated and will be removed in a future version. Please use 'data_interval_start' or 'logical_date' instead.
  warnings.warn(_create_deprecation_warning(key, self._deprecation_replacements[key]))

[2022-02-09 20:23:39,690] {taskinstance.py:1426} INFO - Exporting the following env vars:
AIRFLOW_CTX_DAG_OWNER=***
AIRFLOW_CTX_DAG_ID=green_taxi_gcs_dag
AIRFLOW_CTX_TASK_ID=local_to_gcs_task
AIRFLOW_CTX_EXECUTION_DATE=2019-01-02T00:00:00+00:00
AIRFLOW_CTX_DAG_RUN_ID=scheduled__2019-01-02T00:00:00+00:00
[2022-02-09 20:23:39,743] {taskinstance.py:1700} ERROR - Task failed with exception
Traceback (most recent call last):
  File "/home/airflow/.local/lib/python3.7/site-packages/airflow/models/taskinstance.py", line 1329, in _run_raw_task
    self._execute_task_with_callbacks(context)
  File "/home/airflow/.local/lib/python3.7/site-packages/airflow/models/taskinstance.py", line 1455, in _execute_task_with_callbacks
    result = self._execute_task(context, self.task)
  File "/home/airflow/.local/lib/python3.7/site-packages/airflow/models/taskinstance.py", line 1511, in _execute_task
    result = execute_callable(context=context)
  File "/home/airflow/.local/lib/python3.7/site-packages/airflow/operators/python.py", line 174, in execute
    return_value = self.execute_callable()
  File "/home/airflow/.local/lib/python3.7/site-packages/airflow/operators/python.py", line 185, in execute_callable
    return self.python_callable(*self.op_args, **self.op_kwargs)
  File "/opt/airflow/dags/green_gcs_dag.py", line 49, in upload_to_gcs
    bucket = client.bucket(bucket)
  File "/home/airflow/.local/lib/python3.7/site-packages/google/cloud/storage/client.py", line 279, in bucket
    return Bucket(client=self, name=bucket_name, user_project=user_project)
  File "/home/airflow/.local/lib/python3.7/site-packages/google/cloud/storage/bucket.py", line 611, in __init__
    name = _validate_name(name)
  File "/home/airflow/.local/lib/python3.7/site-packages/google/cloud/storage/_helpers.py", line 80, in _validate_name
    if not all([name[0].isalnum(), name[-1].isalnum()]):
IndexError: string index out of range
[2022-02-09 20:23:39,769] {taskinstance.py:1277} INFO - Marking task as UP_FOR_RETRY. dag_id=green_taxi_gcs_dag, task_id=local_to_gcs_task, execution_date=20190102T000000, start_date=20220209T202339, end_date=20220209T202339
[2022-02-09 20:23:39,801] {standard_task_runner.py:92} ERROR - Failed to execute job 7 for task local_to_gcs_task
Traceback (most recent call last):
  File "/home/airflow/.local/lib/python3.7/site-packages/airflow/task/task_runner/standard_task_runner.py", line 85, in _start_by_fork
    args.func(args, dag=self.dag)
  File "/home/airflow/.local/lib/python3.7/site-packages/airflow/cli/cli_parser.py", line 48, in command
    return func(*args, **kwargs)
  File "/home/airflow/.local/lib/python3.7/site-packages/airflow/utils/cli.py", line 92, in wrapper
    return f(*args, **kwargs)
  File "/home/airflow/.local/lib/python3.7/site-packages/airflow/cli/commands/task_command.py", line 298, in task_run
    _run_task_by_selected_method(args, dag, ti)
  File "/home/airflow/.local/lib/python3.7/site-packages/airflow/cli/commands/task_command.py", line 107, in _run_task_by_selected_method
    _run_raw_task(args, ti)
  File "/home/airflow/.local/lib/python3.7/site-packages/airflow/cli/commands/task_command.py", line 184, in _run_raw_task
    error_file=args.error_file,
  File "/home/airflow/.local/lib/python3.7/site-packages/airflow/utils/session.py", line 70, in wrapper
    return func(*args, session=session, **kwargs)
  File "/home/airflow/.local/lib/python3.7/site-packages/airflow/models/taskinstance.py", line 1329, in _run_raw_task
    self._execute_task_with_callbacks(context)
  File "/home/airflow/.local/lib/python3.7/site-packages/airflow/models/taskinstance.py", line 1455, in _execute_task_with_callbacks
    result = self._execute_task(context, self.task)
  File "/home/airflow/.local/lib/python3.7/site-packages/airflow/models/taskinstance.py", line 1511, in _execute_task
    result = execute_callable(context=context)
  File "/home/airflow/.local/lib/python3.7/site-packages/airflow/operators/python.py", line 174, in execute
    return_value = self.execute_callable()
  File "/home/airflow/.local/lib/python3.7/site-packages/airflow/operators/python.py", line 185, in execute_callable
    return self.python_callable(*self.op_args, **self.op_kwargs)
  File "/opt/airflow/dags/green_gcs_dag.py", line 49, in upload_to_gcs
    bucket = client.bucket(bucket)
  File "/home/airflow/.local/lib/python3.7/site-packages/google/cloud/storage/client.py", line 279, in bucket
    return Bucket(client=self, name=bucket_name, user_project=user_project)
  File "/home/airflow/.local/lib/python3.7/site-packages/google/cloud/storage/bucket.py", line 611, in __init__
    name = _validate_name(name)
  File "/home/airflow/.local/lib/python3.7/site-packages/google/cloud/storage/_helpers.py", line 80, in _validate_name
    if not all([name[0].isalnum(), name[-1].isalnum()]):
IndexError: string index out of range
[2022-02-09 20:23:39,833] {local_task_job.py:154} INFO - Task exited with return code 1
[2022-02-09 20:23:39,935] {local_task_job.py:264} INFO - 0 downstream tasks scheduled from follow-on schedule check
[2022-02-09 20:42:27,528] {taskinstance.py:1032} INFO - Dependencies all met for <TaskInstance: green_taxi_gcs_dag.local_to_gcs_task scheduled__2019-01-02T00:00:00+00:00 [queued]>
[2022-02-09 20:42:27,557] {taskinstance.py:1032} INFO - Dependencies all met for <TaskInstance: green_taxi_gcs_dag.local_to_gcs_task scheduled__2019-01-02T00:00:00+00:00 [queued]>
[2022-02-09 20:42:27,557] {taskinstance.py:1238} INFO - 
--------------------------------------------------------------------------------
[2022-02-09 20:42:27,557] {taskinstance.py:1239} INFO - Starting attempt 1 of 2
[2022-02-09 20:42:27,557] {taskinstance.py:1240} INFO - 
--------------------------------------------------------------------------------
[2022-02-09 20:42:27,582] {taskinstance.py:1259} INFO - Executing <Task(PythonOperator): local_to_gcs_task> on 2019-01-02 00:00:00+00:00
[2022-02-09 20:42:27,592] {standard_task_runner.py:52} INFO - Started process 549 to run task
[2022-02-09 20:42:27,609] {standard_task_runner.py:76} INFO - Running: ['***', 'tasks', 'run', 'green_taxi_gcs_dag', 'local_to_gcs_task', 'scheduled__2019-01-02T00:00:00+00:00', '--job-id', '120', '--raw', '--subdir', 'DAGS_FOLDER/green_gcs_dag.py', '--cfg-path', '/tmp/tmpe8isaw3w', '--error-file', '/tmp/tmpan84jcsl']
[2022-02-09 20:42:27,610] {standard_task_runner.py:77} INFO - Job 120: Subtask local_to_gcs_task
[2022-02-09 20:42:27,793] {logging_mixin.py:109} INFO - Running <TaskInstance: green_taxi_gcs_dag.local_to_gcs_task scheduled__2019-01-02T00:00:00+00:00 [running]> on host 4f97b6b16bdb
[2022-02-09 20:42:27,975] {warnings.py:110} WARNING - /home/***/.local/lib/python3.7/site-packages/***/utils/context.py:152: AirflowContextDeprecationWarning: Accessing 'execution_date' from the template is deprecated and will be removed in a future version. Please use 'data_interval_start' or 'logical_date' instead.
  warnings.warn(_create_deprecation_warning(key, self._deprecation_replacements[key]))

[2022-02-09 20:42:28,047] {taskinstance.py:1426} INFO - Exporting the following env vars:
AIRFLOW_CTX_DAG_OWNER=***
AIRFLOW_CTX_DAG_ID=green_taxi_gcs_dag
AIRFLOW_CTX_TASK_ID=local_to_gcs_task
AIRFLOW_CTX_EXECUTION_DATE=2019-01-02T00:00:00+00:00
AIRFLOW_CTX_DAG_RUN_ID=scheduled__2019-01-02T00:00:00+00:00
[2022-02-09 20:42:29,801] {python.py:175} INFO - Done. Returned value was: None
[2022-02-09 20:42:29,831] {taskinstance.py:1277} INFO - Marking task as SUCCESS. dag_id=green_taxi_gcs_dag, task_id=local_to_gcs_task, execution_date=20190102T000000, start_date=20220209T204227, end_date=20220209T204229
[2022-02-09 20:42:29,890] {local_task_job.py:154} INFO - Task exited with return code 0
[2022-02-09 20:42:29,945] {local_task_job.py:264} INFO - 1 downstream tasks scheduled from follow-on schedule check
[2022-02-20 00:00:31,097] {taskinstance.py:1032} INFO - Dependencies all met for <TaskInstance: green_taxi_gcs_dag.local_to_gcs_task scheduled__2019-01-02T00:00:00+00:00 [queued]>
[2022-02-20 00:00:31,130] {taskinstance.py:1032} INFO - Dependencies all met for <TaskInstance: green_taxi_gcs_dag.local_to_gcs_task scheduled__2019-01-02T00:00:00+00:00 [queued]>
[2022-02-20 00:00:31,130] {taskinstance.py:1238} INFO - 
--------------------------------------------------------------------------------
[2022-02-20 00:00:31,130] {taskinstance.py:1239} INFO - Starting attempt 1 of 2
[2022-02-20 00:00:31,130] {taskinstance.py:1240} INFO - 
--------------------------------------------------------------------------------
[2022-02-20 00:00:31,174] {taskinstance.py:1259} INFO - Executing <Task(PythonOperator): local_to_gcs_task> on 2019-01-02 00:00:00+00:00
[2022-02-20 00:00:31,182] {standard_task_runner.py:52} INFO - Started process 326 to run task
[2022-02-20 00:00:31,191] {standard_task_runner.py:76} INFO - Running: ['***', 'tasks', 'run', 'green_taxi_gcs_dag', 'local_to_gcs_task', 'scheduled__2019-01-02T00:00:00+00:00', '--job-id', '312', '--raw', '--subdir', 'DAGS_FOLDER/green_gcs_dag.py', '--cfg-path', '/tmp/tmpciyyefre', '--error-file', '/tmp/tmp26ri06mq']
[2022-02-20 00:00:31,192] {standard_task_runner.py:77} INFO - Job 312: Subtask local_to_gcs_task
[2022-02-20 00:00:31,297] {logging_mixin.py:109} INFO - Running <TaskInstance: green_taxi_gcs_dag.local_to_gcs_task scheduled__2019-01-02T00:00:00+00:00 [running]> on host da07aa254901
[2022-02-20 00:00:31,355] {warnings.py:110} WARNING - /home/***/.local/lib/python3.7/site-packages/***/utils/context.py:152: AirflowContextDeprecationWarning: Accessing 'execution_date' from the template is deprecated and will be removed in a future version. Please use 'data_interval_start' or 'logical_date' instead.
  warnings.warn(_create_deprecation_warning(key, self._deprecation_replacements[key]))

[2022-02-20 00:00:31,387] {taskinstance.py:1426} INFO - Exporting the following env vars:
AIRFLOW_CTX_DAG_OWNER=***
AIRFLOW_CTX_DAG_ID=green_taxi_gcs_dag
AIRFLOW_CTX_TASK_ID=local_to_gcs_task
AIRFLOW_CTX_EXECUTION_DATE=2019-01-02T00:00:00+00:00
AIRFLOW_CTX_DAG_RUN_ID=scheduled__2019-01-02T00:00:00+00:00
[2022-02-20 00:00:33,084] {python.py:175} INFO - Done. Returned value was: None
[2022-02-20 00:00:33,128] {taskinstance.py:1277} INFO - Marking task as SUCCESS. dag_id=green_taxi_gcs_dag, task_id=local_to_gcs_task, execution_date=20190102T000000, start_date=20220220T000031, end_date=20220220T000033
[2022-02-20 00:00:33,174] {local_task_job.py:154} INFO - Task exited with return code 0
[2022-02-20 00:00:33,218] {local_task_job.py:264} INFO - 1 downstream tasks scheduled from follow-on schedule check
[2022-02-20 01:59:14,641] {taskinstance.py:1032} INFO - Dependencies all met for <TaskInstance: green_taxi_gcs_dag.local_to_gcs_task scheduled__2019-01-02T00:00:00+00:00 [queued]>
[2022-02-20 01:59:14,662] {taskinstance.py:1032} INFO - Dependencies all met for <TaskInstance: green_taxi_gcs_dag.local_to_gcs_task scheduled__2019-01-02T00:00:00+00:00 [queued]>
[2022-02-20 01:59:14,662] {taskinstance.py:1238} INFO - 
--------------------------------------------------------------------------------
[2022-02-20 01:59:14,662] {taskinstance.py:1239} INFO - Starting attempt 1 of 2
[2022-02-20 01:59:14,662] {taskinstance.py:1240} INFO - 
--------------------------------------------------------------------------------
[2022-02-20 01:59:14,682] {taskinstance.py:1259} INFO - Executing <Task(PythonOperator): local_to_gcs_task> on 2019-01-02 00:00:00+00:00
[2022-02-20 01:59:14,689] {standard_task_runner.py:52} INFO - Started process 222 to run task
[2022-02-20 01:59:14,693] {standard_task_runner.py:76} INFO - Running: ['***', 'tasks', 'run', 'green_taxi_gcs_dag', 'local_to_gcs_task', 'scheduled__2019-01-02T00:00:00+00:00', '--job-id', '520', '--raw', '--subdir', 'DAGS_FOLDER/green_gcs_dag.py', '--cfg-path', '/tmp/tmp_z3b1fme', '--error-file', '/tmp/tmpzrpg1lry']
[2022-02-20 01:59:14,694] {standard_task_runner.py:77} INFO - Job 520: Subtask local_to_gcs_task
[2022-02-20 01:59:14,836] {logging_mixin.py:109} INFO - Running <TaskInstance: green_taxi_gcs_dag.local_to_gcs_task scheduled__2019-01-02T00:00:00+00:00 [running]> on host 5484a3a1f7c3
[2022-02-20 01:59:14,953] {warnings.py:110} WARNING - /home/***/.local/lib/python3.7/site-packages/***/utils/context.py:152: AirflowContextDeprecationWarning: Accessing 'execution_date' from the template is deprecated and will be removed in a future version. Please use 'data_interval_start' or 'logical_date' instead.
  warnings.warn(_create_deprecation_warning(key, self._deprecation_replacements[key]))

[2022-02-20 01:59:15,046] {taskinstance.py:1426} INFO - Exporting the following env vars:
AIRFLOW_CTX_DAG_OWNER=***
AIRFLOW_CTX_DAG_ID=green_taxi_gcs_dag
AIRFLOW_CTX_TASK_ID=local_to_gcs_task
AIRFLOW_CTX_EXECUTION_DATE=2019-01-02T00:00:00+00:00
AIRFLOW_CTX_DAG_RUN_ID=scheduled__2019-01-02T00:00:00+00:00
[2022-02-20 01:59:16,909] {python.py:175} INFO - Done. Returned value was: None
[2022-02-20 01:59:16,928] {taskinstance.py:1277} INFO - Marking task as SUCCESS. dag_id=green_taxi_gcs_dag, task_id=local_to_gcs_task, execution_date=20190102T000000, start_date=20220220T015914, end_date=20220220T015916
[2022-02-20 01:59:16,974] {local_task_job.py:154} INFO - Task exited with return code 0
[2022-02-20 01:59:17,022] {local_task_job.py:264} INFO - 1 downstream tasks scheduled from follow-on schedule check
