[2022-02-09 20:26:36,113] {taskinstance.py:1032} INFO - Dependencies all met for <TaskInstance: green_taxi_gcs_dag.local_to_gcs_task scheduled__2019-01-02T00:00:00+00:00 [queued]>
[2022-02-09 20:26:36,137] {taskinstance.py:1032} INFO - Dependencies all met for <TaskInstance: green_taxi_gcs_dag.local_to_gcs_task scheduled__2019-01-02T00:00:00+00:00 [queued]>
[2022-02-09 20:26:36,138] {taskinstance.py:1238} INFO - 
--------------------------------------------------------------------------------
[2022-02-09 20:26:36,138] {taskinstance.py:1239} INFO - Starting attempt 2 of 3
[2022-02-09 20:26:36,138] {taskinstance.py:1240} INFO - 
--------------------------------------------------------------------------------
[2022-02-09 20:26:36,164] {taskinstance.py:1259} INFO - Executing <Task(PythonOperator): local_to_gcs_task> on 2019-01-02 00:00:00+00:00
[2022-02-09 20:26:36,175] {standard_task_runner.py:52} INFO - Started process 283 to run task
[2022-02-09 20:26:36,181] {standard_task_runner.py:76} INFO - Running: ['***', 'tasks', 'run', 'green_taxi_gcs_dag', 'local_to_gcs_task', 'scheduled__2019-01-02T00:00:00+00:00', '--job-id', '13', '--raw', '--subdir', 'DAGS_FOLDER/green_gcs_dag.py', '--cfg-path', '/tmp/tmpg2vccocg', '--error-file', '/tmp/tmpbdwis0_c']
[2022-02-09 20:26:36,182] {standard_task_runner.py:77} INFO - Job 13: Subtask local_to_gcs_task
[2022-02-09 20:26:36,322] {logging_mixin.py:109} INFO - Running <TaskInstance: green_taxi_gcs_dag.local_to_gcs_task scheduled__2019-01-02T00:00:00+00:00 [running]> on host c9ca302aeee6
[2022-02-09 20:26:36,416] {warnings.py:110} WARNING - /home/***/.local/lib/python3.7/site-packages/***/utils/context.py:152: AirflowContextDeprecationWarning: Accessing 'execution_date' from the template is deprecated and will be removed in a future version. Please use 'data_interval_start' or 'logical_date' instead.
  warnings.warn(_create_deprecation_warning(key, self._deprecation_replacements[key]))

[2022-02-09 20:26:36,454] {taskinstance.py:1426} INFO - Exporting the following env vars:
AIRFLOW_CTX_DAG_OWNER=***
AIRFLOW_CTX_DAG_ID=green_taxi_gcs_dag
AIRFLOW_CTX_TASK_ID=local_to_gcs_task
AIRFLOW_CTX_EXECUTION_DATE=2019-01-02T00:00:00+00:00
AIRFLOW_CTX_DAG_RUN_ID=scheduled__2019-01-02T00:00:00+00:00
[2022-02-09 20:26:36,484] {taskinstance.py:1700} ERROR - Task failed with exception
Traceback (most recent call last):
  File "/home/airflow/.local/lib/python3.7/site-packages/airflow/models/taskinstance.py", line 1329, in _run_raw_task
    self._execute_task_with_callbacks(context)
  File "/home/airflow/.local/lib/python3.7/site-packages/airflow/models/taskinstance.py", line 1455, in _execute_task_with_callbacks
    result = self._execute_task(context, self.task)
  File "/home/airflow/.local/lib/python3.7/site-packages/airflow/models/taskinstance.py", line 1511, in _execute_task
    result = execute_callable(context=context)
  File "/home/airflow/.local/lib/python3.7/site-packages/airflow/operators/python.py", line 174, in execute
    return_value = self.execute_callable()
  File "/home/airflow/.local/lib/python3.7/site-packages/airflow/operators/python.py", line 185, in execute_callable
    return self.python_callable(*self.op_args, **self.op_kwargs)
  File "/opt/airflow/dags/green_gcs_dag.py", line 49, in upload_to_gcs
    bucket = client.bucket(bucket)
  File "/home/airflow/.local/lib/python3.7/site-packages/google/cloud/storage/client.py", line 279, in bucket
    return Bucket(client=self, name=bucket_name, user_project=user_project)
  File "/home/airflow/.local/lib/python3.7/site-packages/google/cloud/storage/bucket.py", line 611, in __init__
    name = _validate_name(name)
  File "/home/airflow/.local/lib/python3.7/site-packages/google/cloud/storage/_helpers.py", line 80, in _validate_name
    if not all([name[0].isalnum(), name[-1].isalnum()]):
IndexError: string index out of range
[2022-02-09 20:26:36,527] {taskinstance.py:1277} INFO - Marking task as UP_FOR_RETRY. dag_id=green_taxi_gcs_dag, task_id=local_to_gcs_task, execution_date=20190102T000000, start_date=20220209T202636, end_date=20220209T202636
[2022-02-09 20:26:36,574] {standard_task_runner.py:92} ERROR - Failed to execute job 13 for task local_to_gcs_task
Traceback (most recent call last):
  File "/home/airflow/.local/lib/python3.7/site-packages/airflow/task/task_runner/standard_task_runner.py", line 85, in _start_by_fork
    args.func(args, dag=self.dag)
  File "/home/airflow/.local/lib/python3.7/site-packages/airflow/cli/cli_parser.py", line 48, in command
    return func(*args, **kwargs)
  File "/home/airflow/.local/lib/python3.7/site-packages/airflow/utils/cli.py", line 92, in wrapper
    return f(*args, **kwargs)
  File "/home/airflow/.local/lib/python3.7/site-packages/airflow/cli/commands/task_command.py", line 298, in task_run
    _run_task_by_selected_method(args, dag, ti)
  File "/home/airflow/.local/lib/python3.7/site-packages/airflow/cli/commands/task_command.py", line 107, in _run_task_by_selected_method
    _run_raw_task(args, ti)
  File "/home/airflow/.local/lib/python3.7/site-packages/airflow/cli/commands/task_command.py", line 184, in _run_raw_task
    error_file=args.error_file,
  File "/home/airflow/.local/lib/python3.7/site-packages/airflow/utils/session.py", line 70, in wrapper
    return func(*args, session=session, **kwargs)
  File "/home/airflow/.local/lib/python3.7/site-packages/airflow/models/taskinstance.py", line 1329, in _run_raw_task
    self._execute_task_with_callbacks(context)
  File "/home/airflow/.local/lib/python3.7/site-packages/airflow/models/taskinstance.py", line 1455, in _execute_task_with_callbacks
    result = self._execute_task(context, self.task)
  File "/home/airflow/.local/lib/python3.7/site-packages/airflow/models/taskinstance.py", line 1511, in _execute_task
    result = execute_callable(context=context)
  File "/home/airflow/.local/lib/python3.7/site-packages/airflow/operators/python.py", line 174, in execute
    return_value = self.execute_callable()
  File "/home/airflow/.local/lib/python3.7/site-packages/airflow/operators/python.py", line 185, in execute_callable
    return self.python_callable(*self.op_args, **self.op_kwargs)
  File "/opt/airflow/dags/green_gcs_dag.py", line 49, in upload_to_gcs
    bucket = client.bucket(bucket)
  File "/home/airflow/.local/lib/python3.7/site-packages/google/cloud/storage/client.py", line 279, in bucket
    return Bucket(client=self, name=bucket_name, user_project=user_project)
  File "/home/airflow/.local/lib/python3.7/site-packages/google/cloud/storage/bucket.py", line 611, in __init__
    name = _validate_name(name)
  File "/home/airflow/.local/lib/python3.7/site-packages/google/cloud/storage/_helpers.py", line 80, in _validate_name
    if not all([name[0].isalnum(), name[-1].isalnum()]):
IndexError: string index out of range
[2022-02-09 20:26:36,598] {local_task_job.py:154} INFO - Task exited with return code 1
[2022-02-09 20:26:36,854] {local_task_job.py:264} INFO - 0 downstream tasks scheduled from follow-on schedule check
