[2022-02-09 20:34:10,002] {taskinstance.py:1032} INFO - Dependencies all met for <TaskInstance: green_taxi_gcs_dag.download_dataset_task scheduled__2020-01-02T00:00:00+00:00 [queued]>
[2022-02-09 20:34:10,053] {taskinstance.py:1032} INFO - Dependencies all met for <TaskInstance: green_taxi_gcs_dag.download_dataset_task scheduled__2020-01-02T00:00:00+00:00 [queued]>
[2022-02-09 20:34:10,053] {taskinstance.py:1238} INFO - 
--------------------------------------------------------------------------------
[2022-02-09 20:34:10,053] {taskinstance.py:1239} INFO - Starting attempt 1 of 2
[2022-02-09 20:34:10,054] {taskinstance.py:1240} INFO - 
--------------------------------------------------------------------------------
[2022-02-09 20:34:10,087] {taskinstance.py:1259} INFO - Executing <Task(BashOperator): download_dataset_task> on 2020-01-02 00:00:00+00:00
[2022-02-09 20:34:10,103] {standard_task_runner.py:52} INFO - Started process 417 to run task
[2022-02-09 20:34:10,115] {standard_task_runner.py:76} INFO - Running: ['***', 'tasks', 'run', 'green_taxi_gcs_dag', 'download_dataset_task', 'scheduled__2020-01-02T00:00:00+00:00', '--job-id', '63', '--raw', '--subdir', 'DAGS_FOLDER/green_gcs_dag.py', '--cfg-path', '/tmp/tmpe2b3logg', '--error-file', '/tmp/tmpjjbkexru']
[2022-02-09 20:34:10,118] {standard_task_runner.py:77} INFO - Job 63: Subtask download_dataset_task
[2022-02-09 20:34:10,279] {logging_mixin.py:109} INFO - Running <TaskInstance: green_taxi_gcs_dag.download_dataset_task scheduled__2020-01-02T00:00:00+00:00 [running]> on host 4f97b6b16bdb
[2022-02-09 20:34:10,362] {warnings.py:110} WARNING - /home/***/.local/lib/python3.7/site-packages/***/utils/context.py:152: AirflowContextDeprecationWarning: Accessing 'execution_date' from the template is deprecated and will be removed in a future version. Please use 'data_interval_start' or 'logical_date' instead.
  warnings.warn(_create_deprecation_warning(key, self._deprecation_replacements[key]))

[2022-02-09 20:34:10,418] {taskinstance.py:1426} INFO - Exporting the following env vars:
AIRFLOW_CTX_DAG_OWNER=***
AIRFLOW_CTX_DAG_ID=green_taxi_gcs_dag
AIRFLOW_CTX_TASK_ID=download_dataset_task
AIRFLOW_CTX_EXECUTION_DATE=2020-01-02T00:00:00+00:00
AIRFLOW_CTX_DAG_RUN_ID=scheduled__2020-01-02T00:00:00+00:00
[2022-02-09 20:34:10,420] {subprocess.py:62} INFO - Tmp dir root location: 
 /tmp
[2022-02-09 20:34:10,425] {subprocess.py:74} INFO - Running command: ['bash', '-c', 'curl -sS https://s3.amazonaws.com/nyc-tlc/trip+data/green_tripdata_2020-01.csv > /opt/***/output_2020-01.csv']
[2022-02-09 20:34:10,458] {subprocess.py:85} INFO - Output:
[2022-02-09 22:08:55,340] {taskinstance.py:1032} INFO - Dependencies all met for <TaskInstance: green_taxi_gcs_dag.download_dataset_task scheduled__2020-01-02T00:00:00+00:00 [queued]>
[2022-02-09 22:08:55,390] {taskinstance.py:1032} INFO - Dependencies all met for <TaskInstance: green_taxi_gcs_dag.download_dataset_task scheduled__2020-01-02T00:00:00+00:00 [queued]>
[2022-02-09 22:08:55,392] {taskinstance.py:1238} INFO - 
--------------------------------------------------------------------------------
[2022-02-09 22:08:55,392] {taskinstance.py:1239} INFO - Starting attempt 1 of 2
[2022-02-09 22:08:55,392] {taskinstance.py:1240} INFO - 
--------------------------------------------------------------------------------
[2022-02-09 22:08:55,432] {taskinstance.py:1259} INFO - Executing <Task(BashOperator): download_dataset_task> on 2020-01-02 00:00:00+00:00
[2022-02-09 22:08:55,457] {standard_task_runner.py:52} INFO - Started process 2930 to run task
[2022-02-09 22:08:55,476] {standard_task_runner.py:76} INFO - Running: ['***', 'tasks', 'run', 'green_taxi_gcs_dag', 'download_dataset_task', 'scheduled__2020-01-02T00:00:00+00:00', '--job-id', '212', '--raw', '--subdir', 'DAGS_FOLDER/green_gcs_dag.py', '--cfg-path', '/tmp/tmpuxoaiwya', '--error-file', '/tmp/tmprp86hdc_']
[2022-02-09 22:08:55,478] {standard_task_runner.py:77} INFO - Job 212: Subtask download_dataset_task
[2022-02-09 22:08:59,891] {logging_mixin.py:109} INFO - Running <TaskInstance: green_taxi_gcs_dag.download_dataset_task scheduled__2020-01-02T00:00:00+00:00 [running]> on host 4f97b6b16bdb
[2022-02-09 22:09:03,052] {warnings.py:110} WARNING - /home/***/.local/lib/python3.7/site-packages/***/utils/context.py:152: AirflowContextDeprecationWarning: Accessing 'execution_date' from the template is deprecated and will be removed in a future version. Please use 'data_interval_start' or 'logical_date' instead.
  warnings.warn(_create_deprecation_warning(key, self._deprecation_replacements[key]))

[2022-02-09 22:09:06,970] {taskinstance.py:1426} INFO - Exporting the following env vars:
AIRFLOW_CTX_DAG_OWNER=***
AIRFLOW_CTX_DAG_ID=green_taxi_gcs_dag
AIRFLOW_CTX_TASK_ID=download_dataset_task
AIRFLOW_CTX_EXECUTION_DATE=2020-01-02T00:00:00+00:00
AIRFLOW_CTX_DAG_RUN_ID=scheduled__2020-01-02T00:00:00+00:00
[2022-02-09 22:09:06,980] {subprocess.py:62} INFO - Tmp dir root location: 
 /tmp
[2022-02-09 22:09:07,039] {subprocess.py:74} INFO - Running command: ['bash', '-c', 'curl -sS https://s3.amazonaws.com/nyc-tlc/trip+data/green_tripdata_2020-01.csv > /opt/***/output_2020-01.csv']
[2022-02-09 22:09:07,395] {subprocess.py:85} INFO - Output:
[2022-02-09 22:10:29,090] {base_job.py:230} ERROR - LocalTaskJob heartbeat got an exception
Traceback (most recent call last):
  File "/home/airflow/.local/lib/python3.7/site-packages/sqlalchemy/engine/base.py", line 2336, in _wrap_pool_connect
    return fn()
  File "/home/airflow/.local/lib/python3.7/site-packages/sqlalchemy/pool/base.py", line 364, in connect
    return _ConnectionFairy._checkout(self)
  File "/home/airflow/.local/lib/python3.7/site-packages/sqlalchemy/pool/base.py", line 778, in _checkout
    fairy = _ConnectionRecord.checkout(pool)
  File "/home/airflow/.local/lib/python3.7/site-packages/sqlalchemy/pool/base.py", line 495, in checkout
    rec = pool._do_get()
  File "/home/airflow/.local/lib/python3.7/site-packages/sqlalchemy/pool/impl.py", line 241, in _do_get
    return self._create_connection()
  File "/home/airflow/.local/lib/python3.7/site-packages/sqlalchemy/pool/base.py", line 309, in _create_connection
    return _ConnectionRecord(self)
  File "/home/airflow/.local/lib/python3.7/site-packages/sqlalchemy/pool/base.py", line 440, in __init__
    self.__connect(first_connect_check=True)
  File "/home/airflow/.local/lib/python3.7/site-packages/sqlalchemy/pool/base.py", line 661, in __connect
    pool.logger.debug("Error on connect(): %s", e)
  File "/home/airflow/.local/lib/python3.7/site-packages/sqlalchemy/util/langhelpers.py", line 70, in __exit__
    with_traceback=exc_tb,
  File "/home/airflow/.local/lib/python3.7/site-packages/sqlalchemy/util/compat.py", line 182, in raise_
    raise exception
  File "/home/airflow/.local/lib/python3.7/site-packages/sqlalchemy/pool/base.py", line 656, in __connect
    connection = pool._invoke_creator(self)
  File "/home/airflow/.local/lib/python3.7/site-packages/sqlalchemy/engine/strategies.py", line 114, in connect
    return dialect.connect(*cargs, **cparams)
  File "/home/airflow/.local/lib/python3.7/site-packages/sqlalchemy/engine/default.py", line 508, in connect
    return self.dbapi.connect(*cargs, **cparams)
  File "/home/airflow/.local/lib/python3.7/site-packages/psycopg2/__init__.py", line 122, in connect
    conn = _connect(dsn, connection_factory=connection_factory, **kwasync)
psycopg2.OperationalError: could not translate host name "postgres" to address: Temporary failure in name resolution


The above exception was the direct cause of the following exception:

Traceback (most recent call last):
  File "/home/airflow/.local/lib/python3.7/site-packages/airflow/jobs/base_job.py", line 202, in heartbeat
    session.merge(self)
  File "/home/airflow/.local/lib/python3.7/site-packages/sqlalchemy/orm/session.py", line 2171, in merge
    _resolve_conflict_map=_resolve_conflict_map,
  File "/home/airflow/.local/lib/python3.7/site-packages/sqlalchemy/orm/session.py", line 2244, in _merge
    merged = self.query(mapper.class_).get(key[1])
  File "/home/airflow/.local/lib/python3.7/site-packages/sqlalchemy/orm/query.py", line 1018, in get
    return self._get_impl(ident, loading.load_on_pk_identity)
  File "/home/airflow/.local/lib/python3.7/site-packages/sqlalchemy/orm/query.py", line 1135, in _get_impl
    return db_load_fn(self, primary_key_identity)
  File "/home/airflow/.local/lib/python3.7/site-packages/sqlalchemy/orm/loading.py", line 286, in load_on_pk_identity
    return q.one()
  File "/home/airflow/.local/lib/python3.7/site-packages/sqlalchemy/orm/query.py", line 3490, in one
    ret = self.one_or_none()
  File "/home/airflow/.local/lib/python3.7/site-packages/sqlalchemy/orm/query.py", line 3459, in one_or_none
    ret = list(self)
  File "/home/airflow/.local/lib/python3.7/site-packages/sqlalchemy/orm/query.py", line 3535, in __iter__
    return self._execute_and_instances(context)
  File "/home/airflow/.local/lib/python3.7/site-packages/sqlalchemy/orm/query.py", line 3557, in _execute_and_instances
    querycontext, self._connection_from_session, close_with_result=True
  File "/home/airflow/.local/lib/python3.7/site-packages/sqlalchemy/orm/query.py", line 3572, in _get_bind_args
    mapper=self._bind_mapper(), clause=querycontext.statement, **kw
  File "/home/airflow/.local/lib/python3.7/site-packages/sqlalchemy/orm/query.py", line 3550, in _connection_from_session
    conn = self.session.connection(**kw)
  File "/home/airflow/.local/lib/python3.7/site-packages/sqlalchemy/orm/session.py", line 1145, in connection
    execution_options=execution_options,
  File "/home/airflow/.local/lib/python3.7/site-packages/sqlalchemy/orm/session.py", line 1151, in _connection_for_bind
    engine, execution_options
  File "/home/airflow/.local/lib/python3.7/site-packages/sqlalchemy/orm/session.py", line 433, in _connection_for_bind
    conn = bind._contextual_connect()
  File "/home/airflow/.local/lib/python3.7/site-packages/sqlalchemy/engine/base.py", line 2302, in _contextual_connect
    self._wrap_pool_connect(self.pool.connect, None),
  File "/home/airflow/.local/lib/python3.7/site-packages/sqlalchemy/engine/base.py", line 2340, in _wrap_pool_connect
    e, dialect, self
  File "/home/airflow/.local/lib/python3.7/site-packages/sqlalchemy/engine/base.py", line 1584, in _handle_dbapi_exception_noconnection
    sqlalchemy_exception, with_traceback=exc_info[2], from_=e
  File "/home/airflow/.local/lib/python3.7/site-packages/sqlalchemy/util/compat.py", line 182, in raise_
    raise exception
  File "/home/airflow/.local/lib/python3.7/site-packages/sqlalchemy/engine/base.py", line 2336, in _wrap_pool_connect
    return fn()
  File "/home/airflow/.local/lib/python3.7/site-packages/sqlalchemy/pool/base.py", line 364, in connect
    return _ConnectionFairy._checkout(self)
  File "/home/airflow/.local/lib/python3.7/site-packages/sqlalchemy/pool/base.py", line 778, in _checkout
    fairy = _ConnectionRecord.checkout(pool)
  File "/home/airflow/.local/lib/python3.7/site-packages/sqlalchemy/pool/base.py", line 495, in checkout
    rec = pool._do_get()
  File "/home/airflow/.local/lib/python3.7/site-packages/sqlalchemy/pool/impl.py", line 241, in _do_get
    return self._create_connection()
  File "/home/airflow/.local/lib/python3.7/site-packages/sqlalchemy/pool/base.py", line 309, in _create_connection
    return _ConnectionRecord(self)
  File "/home/airflow/.local/lib/python3.7/site-packages/sqlalchemy/pool/base.py", line 440, in __init__
    self.__connect(first_connect_check=True)
  File "/home/airflow/.local/lib/python3.7/site-packages/sqlalchemy/pool/base.py", line 661, in __connect
    pool.logger.debug("Error on connect(): %s", e)
  File "/home/airflow/.local/lib/python3.7/site-packages/sqlalchemy/util/langhelpers.py", line 70, in __exit__
    with_traceback=exc_tb,
  File "/home/airflow/.local/lib/python3.7/site-packages/sqlalchemy/util/compat.py", line 182, in raise_
    raise exception
  File "/home/airflow/.local/lib/python3.7/site-packages/sqlalchemy/pool/base.py", line 656, in __connect
    connection = pool._invoke_creator(self)
  File "/home/airflow/.local/lib/python3.7/site-packages/sqlalchemy/engine/strategies.py", line 114, in connect
    return dialect.connect(*cargs, **cparams)
  File "/home/airflow/.local/lib/python3.7/site-packages/sqlalchemy/engine/default.py", line 508, in connect
    return self.dbapi.connect(*cargs, **cparams)
  File "/home/airflow/.local/lib/python3.7/site-packages/psycopg2/__init__.py", line 122, in connect
    conn = _connect(dsn, connection_factory=connection_factory, **kwasync)
sqlalchemy.exc.OperationalError: (psycopg2.OperationalError) could not translate host name "postgres" to address: Temporary failure in name resolution

(Background on this error at: http://sqlalche.me/e/13/e3q8)
[2022-02-09 22:15:12,045] {subprocess.py:93} INFO - Command exited with return code 0
[2022-02-09 22:15:12,220] {taskinstance.py:1277} INFO - Marking task as SUCCESS. dag_id=green_taxi_gcs_dag, task_id=download_dataset_task, execution_date=20200102T000000, start_date=20220209T220855, end_date=20220209T221512
[2022-02-09 22:15:12,336] {local_task_job.py:154} INFO - Task exited with return code 0
[2022-02-09 22:15:12,425] {local_task_job.py:264} INFO - 1 downstream tasks scheduled from follow-on schedule check
[2022-02-20 00:07:28,867] {taskinstance.py:1032} INFO - Dependencies all met for <TaskInstance: green_taxi_gcs_dag.download_dataset_task scheduled__2020-01-02T00:00:00+00:00 [queued]>
[2022-02-20 00:07:28,925] {taskinstance.py:1032} INFO - Dependencies all met for <TaskInstance: green_taxi_gcs_dag.download_dataset_task scheduled__2020-01-02T00:00:00+00:00 [queued]>
[2022-02-20 00:07:28,925] {taskinstance.py:1238} INFO - 
--------------------------------------------------------------------------------
[2022-02-20 00:07:28,925] {taskinstance.py:1239} INFO - Starting attempt 1 of 2
[2022-02-20 00:07:28,925] {taskinstance.py:1240} INFO - 
--------------------------------------------------------------------------------
[2022-02-20 00:07:28,949] {taskinstance.py:1259} INFO - Executing <Task(BashOperator): download_dataset_task> on 2020-01-02 00:00:00+00:00
[2022-02-20 00:07:28,958] {standard_task_runner.py:52} INFO - Started process 826 to run task
[2022-02-20 00:07:28,966] {standard_task_runner.py:76} INFO - Running: ['***', 'tasks', 'run', 'green_taxi_gcs_dag', 'download_dataset_task', 'scheduled__2020-01-02T00:00:00+00:00', '--job-id', '353', '--raw', '--subdir', 'DAGS_FOLDER/green_gcs_dag.py', '--cfg-path', '/tmp/tmpvoxy4kw5', '--error-file', '/tmp/tmp01cxaw4l']
[2022-02-20 00:07:28,970] {standard_task_runner.py:77} INFO - Job 353: Subtask download_dataset_task
[2022-02-20 00:07:29,121] {logging_mixin.py:109} INFO - Running <TaskInstance: green_taxi_gcs_dag.download_dataset_task scheduled__2020-01-02T00:00:00+00:00 [running]> on host da07aa254901
[2022-02-20 00:07:29,197] {warnings.py:110} WARNING - /home/***/.local/lib/python3.7/site-packages/***/utils/context.py:152: AirflowContextDeprecationWarning: Accessing 'execution_date' from the template is deprecated and will be removed in a future version. Please use 'data_interval_start' or 'logical_date' instead.
  warnings.warn(_create_deprecation_warning(key, self._deprecation_replacements[key]))

[2022-02-20 00:07:29,235] {taskinstance.py:1426} INFO - Exporting the following env vars:
AIRFLOW_CTX_DAG_OWNER=***
AIRFLOW_CTX_DAG_ID=green_taxi_gcs_dag
AIRFLOW_CTX_TASK_ID=download_dataset_task
AIRFLOW_CTX_EXECUTION_DATE=2020-01-02T00:00:00+00:00
AIRFLOW_CTX_DAG_RUN_ID=scheduled__2020-01-02T00:00:00+00:00
[2022-02-20 00:07:29,236] {subprocess.py:62} INFO - Tmp dir root location: 
 /tmp
[2022-02-20 00:07:29,236] {subprocess.py:74} INFO - Running command: ['bash', '-c', 'curl -sS https://s3.amazonaws.com/nyc-tlc/trip+data/green_tripdata_2020-01.csv > /opt/***/output_2020-01.csv']
[2022-02-20 00:07:29,250] {subprocess.py:85} INFO - Output:
[2022-02-20 00:07:34,351] {subprocess.py:93} INFO - Command exited with return code 0
[2022-02-20 00:07:34,416] {taskinstance.py:1277} INFO - Marking task as SUCCESS. dag_id=green_taxi_gcs_dag, task_id=download_dataset_task, execution_date=20200102T000000, start_date=20220220T000728, end_date=20220220T000734
[2022-02-20 00:07:34,507] {local_task_job.py:154} INFO - Task exited with return code 0
[2022-02-20 00:07:34,617] {local_task_job.py:264} INFO - 1 downstream tasks scheduled from follow-on schedule check
[2022-02-20 02:00:46,480] {taskinstance.py:1032} INFO - Dependencies all met for <TaskInstance: green_taxi_gcs_dag.download_dataset_task scheduled__2020-01-02T00:00:00+00:00 [queued]>
[2022-02-20 02:00:46,551] {taskinstance.py:1032} INFO - Dependencies all met for <TaskInstance: green_taxi_gcs_dag.download_dataset_task scheduled__2020-01-02T00:00:00+00:00 [queued]>
[2022-02-20 02:00:46,552] {taskinstance.py:1238} INFO - 
--------------------------------------------------------------------------------
[2022-02-20 02:00:46,552] {taskinstance.py:1239} INFO - Starting attempt 1 of 2
[2022-02-20 02:00:46,552] {taskinstance.py:1240} INFO - 
--------------------------------------------------------------------------------
[2022-02-20 02:00:46,627] {taskinstance.py:1259} INFO - Executing <Task(BashOperator): download_dataset_task> on 2020-01-02 00:00:00+00:00
[2022-02-20 02:00:46,639] {standard_task_runner.py:76} INFO - Running: ['***', 'tasks', 'run', 'green_taxi_gcs_dag', 'download_dataset_task', 'scheduled__2020-01-02T00:00:00+00:00', '--job-id', '556', '--raw', '--subdir', 'DAGS_FOLDER/green_gcs_dag.py', '--cfg-path', '/tmp/tmppmuhy1wh', '--error-file', '/tmp/tmpsv30lr27']
[2022-02-20 02:00:46,642] {standard_task_runner.py:77} INFO - Job 556: Subtask download_dataset_task
[2022-02-20 02:00:46,635] {standard_task_runner.py:52} INFO - Started process 485 to run task
[2022-02-20 02:00:46,827] {logging_mixin.py:109} INFO - Running <TaskInstance: green_taxi_gcs_dag.download_dataset_task scheduled__2020-01-02T00:00:00+00:00 [running]> on host 5484a3a1f7c3
[2022-02-20 02:00:46,919] {warnings.py:110} WARNING - /home/***/.local/lib/python3.7/site-packages/***/utils/context.py:152: AirflowContextDeprecationWarning: Accessing 'execution_date' from the template is deprecated and will be removed in a future version. Please use 'data_interval_start' or 'logical_date' instead.
  warnings.warn(_create_deprecation_warning(key, self._deprecation_replacements[key]))

[2022-02-20 02:00:46,964] {taskinstance.py:1426} INFO - Exporting the following env vars:
AIRFLOW_CTX_DAG_OWNER=***
AIRFLOW_CTX_DAG_ID=green_taxi_gcs_dag
AIRFLOW_CTX_TASK_ID=download_dataset_task
AIRFLOW_CTX_EXECUTION_DATE=2020-01-02T00:00:00+00:00
AIRFLOW_CTX_DAG_RUN_ID=scheduled__2020-01-02T00:00:00+00:00
[2022-02-20 02:00:46,965] {subprocess.py:62} INFO - Tmp dir root location: 
 /tmp
[2022-02-20 02:00:46,966] {subprocess.py:74} INFO - Running command: ['bash', '-c', 'curl -sS https://s3.amazonaws.com/nyc-tlc/trip+data/green_tripdata_2020-01.csv > /opt/***/output_2020-01.csv']
[2022-02-20 02:00:46,990] {subprocess.py:85} INFO - Output:
[2022-02-20 02:00:51,431] {subprocess.py:93} INFO - Command exited with return code 0
[2022-02-20 02:00:51,460] {taskinstance.py:1277} INFO - Marking task as SUCCESS. dag_id=green_taxi_gcs_dag, task_id=download_dataset_task, execution_date=20200102T000000, start_date=20220220T020046, end_date=20220220T020051
[2022-02-20 02:00:51,517] {local_task_job.py:154} INFO - Task exited with return code 0
[2022-02-20 02:00:51,571] {local_task_job.py:264} INFO - 1 downstream tasks scheduled from follow-on schedule check
