[2022-02-03 18:13:10,559] {taskinstance.py:1032} INFO - Dependencies all met for <TaskInstance: fhv_gcs_dag.download_dataset_task scheduled__2019-01-02T00:00:00+00:00 [queued]>
[2022-02-03 18:13:10,669] {taskinstance.py:1032} INFO - Dependencies all met for <TaskInstance: fhv_gcs_dag.download_dataset_task scheduled__2019-01-02T00:00:00+00:00 [queued]>
[2022-02-03 18:13:10,669] {taskinstance.py:1238} INFO - 
--------------------------------------------------------------------------------
[2022-02-03 18:13:10,669] {taskinstance.py:1239} INFO - Starting attempt 1 of 2
[2022-02-03 18:13:10,669] {taskinstance.py:1240} INFO - 
--------------------------------------------------------------------------------
[2022-02-03 18:13:10,851] {taskinstance.py:1259} INFO - Executing <Task(BashOperator): download_dataset_task> on 2019-01-02 00:00:00+00:00
[2022-02-03 18:13:10,884] {standard_task_runner.py:52} INFO - Started process 784 to run task
[2022-02-03 18:13:10,970] {standard_task_runner.py:76} INFO - Running: ['***', 'tasks', 'run', 'fhv_gcs_dag', 'download_dataset_task', 'scheduled__2019-01-02T00:00:00+00:00', '--job-id', '145', '--raw', '--subdir', 'DAGS_FOLDER/fhv_gcs_dag.py', '--cfg-path', '/tmp/tmp40h_28hi', '--error-file', '/tmp/tmpi1kwfqii']
[2022-02-03 18:13:11,000] {standard_task_runner.py:77} INFO - Job 145: Subtask download_dataset_task
[2022-02-03 18:13:11,473] {logging_mixin.py:109} INFO - Running <TaskInstance: fhv_gcs_dag.download_dataset_task scheduled__2019-01-02T00:00:00+00:00 [running]> on host bd2f56b76e32
[2022-02-03 18:13:11,673] {warnings.py:110} WARNING - /home/***/.local/lib/python3.7/site-packages/***/utils/context.py:152: AirflowContextDeprecationWarning: Accessing 'execution_date' from the template is deprecated and will be removed in a future version. Please use 'data_interval_start' or 'logical_date' instead.
  warnings.warn(_create_deprecation_warning(key, self._deprecation_replacements[key]))

[2022-02-03 18:13:11,747] {taskinstance.py:1426} INFO - Exporting the following env vars:
AIRFLOW_CTX_DAG_OWNER=***
AIRFLOW_CTX_DAG_ID=fhv_gcs_dag
AIRFLOW_CTX_TASK_ID=download_dataset_task
AIRFLOW_CTX_EXECUTION_DATE=2019-01-02T00:00:00+00:00
AIRFLOW_CTX_DAG_RUN_ID=scheduled__2019-01-02T00:00:00+00:00
[2022-02-03 18:13:11,748] {subprocess.py:62} INFO - Tmp dir root location: 
 /tmp
[2022-02-03 18:13:11,749] {subprocess.py:74} INFO - Running command: ['bash', '-c', 'curl -sS https://nyc-tlc.s3.amazonaws.com/trip+data/fhv_tripdata_2019-01.csv > /opt/***/output_2019-01.csv']
[2022-02-03 18:13:11,846] {subprocess.py:85} INFO - Output:
[2022-02-03 18:17:18,224] {subprocess.py:93} INFO - Command exited with return code 0
[2022-02-03 18:17:18,255] {taskinstance.py:1277} INFO - Marking task as SUCCESS. dag_id=fhv_gcs_dag, task_id=download_dataset_task, execution_date=20190102T000000, start_date=20220203T181310, end_date=20220203T181718
[2022-02-03 18:17:18,285] {local_task_job.py:154} INFO - Task exited with return code 0
[2022-02-03 18:17:18,333] {local_task_job.py:264} INFO - 1 downstream tasks scheduled from follow-on schedule check
[2022-02-23 19:08:26,757] {taskinstance.py:1032} INFO - Dependencies all met for <TaskInstance: fhv_gcs_dag.download_dataset_task scheduled__2019-01-02T00:00:00+00:00 [queued]>
[2022-02-23 19:08:26,779] {taskinstance.py:1032} INFO - Dependencies all met for <TaskInstance: fhv_gcs_dag.download_dataset_task scheduled__2019-01-02T00:00:00+00:00 [queued]>
[2022-02-23 19:08:26,779] {taskinstance.py:1238} INFO - 
--------------------------------------------------------------------------------
[2022-02-23 19:08:26,779] {taskinstance.py:1239} INFO - Starting attempt 1 of 2
[2022-02-23 19:08:26,779] {taskinstance.py:1240} INFO - 
--------------------------------------------------------------------------------
[2022-02-23 19:08:26,806] {taskinstance.py:1259} INFO - Executing <Task(BashOperator): download_dataset_task> on 2019-01-02 00:00:00+00:00
[2022-02-23 19:08:26,835] {standard_task_runner.py:52} INFO - Started process 120 to run task
[2022-02-23 19:08:26,853] {standard_task_runner.py:76} INFO - Running: ['***', 'tasks', 'run', 'fhv_gcs_dag', 'download_dataset_task', 'scheduled__2019-01-02T00:00:00+00:00', '--job-id', '613', '--raw', '--subdir', 'DAGS_FOLDER/fhv_gcs_dag.py', '--cfg-path', '/tmp/tmpkbm43zqo', '--error-file', '/tmp/tmpetwqqe01']
[2022-02-23 19:08:26,860] {standard_task_runner.py:77} INFO - Job 613: Subtask download_dataset_task
[2022-02-23 19:08:27,030] {logging_mixin.py:109} INFO - Running <TaskInstance: fhv_gcs_dag.download_dataset_task scheduled__2019-01-02T00:00:00+00:00 [running]> on host 4709b9a36f03
[2022-02-23 19:08:27,106] {warnings.py:110} WARNING - /home/***/.local/lib/python3.7/site-packages/***/utils/context.py:152: AirflowContextDeprecationWarning: Accessing 'execution_date' from the template is deprecated and will be removed in a future version. Please use 'data_interval_start' or 'logical_date' instead.
  warnings.warn(_create_deprecation_warning(key, self._deprecation_replacements[key]))

[2022-02-23 19:08:27,141] {taskinstance.py:1426} INFO - Exporting the following env vars:
AIRFLOW_CTX_DAG_OWNER=***
AIRFLOW_CTX_DAG_ID=fhv_gcs_dag
AIRFLOW_CTX_TASK_ID=download_dataset_task
AIRFLOW_CTX_EXECUTION_DATE=2019-01-02T00:00:00+00:00
AIRFLOW_CTX_DAG_RUN_ID=scheduled__2019-01-02T00:00:00+00:00
[2022-02-23 19:08:27,142] {subprocess.py:62} INFO - Tmp dir root location: 
 /tmp
[2022-02-23 19:08:27,143] {subprocess.py:74} INFO - Running command: ['bash', '-c', 'curl -sS https://nyc-tlc.s3.amazonaws.com/trip+data/fhv_tripdata_2019-01.csv > /opt/***/output_2019-01.csv']
[2022-02-23 19:08:27,166] {subprocess.py:85} INFO - Output:
[2022-02-23 19:11:20,096] {subprocess.py:89} INFO - curl: (56) OpenSSL SSL_read: SSL_ERROR_SYSCALL, errno 104
[2022-02-23 19:11:20,108] {subprocess.py:93} INFO - Command exited with return code 56
[2022-02-23 19:11:20,295] {taskinstance.py:1700} ERROR - Task failed with exception
Traceback (most recent call last):
  File "/home/airflow/.local/lib/python3.7/site-packages/airflow/models/taskinstance.py", line 1329, in _run_raw_task
    self._execute_task_with_callbacks(context)
  File "/home/airflow/.local/lib/python3.7/site-packages/airflow/models/taskinstance.py", line 1455, in _execute_task_with_callbacks
    result = self._execute_task(context, self.task)
  File "/home/airflow/.local/lib/python3.7/site-packages/airflow/models/taskinstance.py", line 1511, in _execute_task
    result = execute_callable(context=context)
  File "/home/airflow/.local/lib/python3.7/site-packages/airflow/operators/bash.py", line 188, in execute
    f'Bash command failed. The command returned a non-zero exit code {result.exit_code}.'
airflow.exceptions.AirflowException: Bash command failed. The command returned a non-zero exit code 56.
[2022-02-23 19:11:20,356] {taskinstance.py:1277} INFO - Marking task as UP_FOR_RETRY. dag_id=fhv_gcs_dag, task_id=download_dataset_task, execution_date=20190102T000000, start_date=20220223T190826, end_date=20220223T191120
[2022-02-23 19:11:20,528] {standard_task_runner.py:92} ERROR - Failed to execute job 613 for task download_dataset_task
Traceback (most recent call last):
  File "/home/airflow/.local/lib/python3.7/site-packages/airflow/task/task_runner/standard_task_runner.py", line 85, in _start_by_fork
    args.func(args, dag=self.dag)
  File "/home/airflow/.local/lib/python3.7/site-packages/airflow/cli/cli_parser.py", line 48, in command
    return func(*args, **kwargs)
  File "/home/airflow/.local/lib/python3.7/site-packages/airflow/utils/cli.py", line 92, in wrapper
    return f(*args, **kwargs)
  File "/home/airflow/.local/lib/python3.7/site-packages/airflow/cli/commands/task_command.py", line 298, in task_run
    _run_task_by_selected_method(args, dag, ti)
  File "/home/airflow/.local/lib/python3.7/site-packages/airflow/cli/commands/task_command.py", line 107, in _run_task_by_selected_method
    _run_raw_task(args, ti)
  File "/home/airflow/.local/lib/python3.7/site-packages/airflow/cli/commands/task_command.py", line 184, in _run_raw_task
    error_file=args.error_file,
  File "/home/airflow/.local/lib/python3.7/site-packages/airflow/utils/session.py", line 70, in wrapper
    return func(*args, session=session, **kwargs)
  File "/home/airflow/.local/lib/python3.7/site-packages/airflow/models/taskinstance.py", line 1329, in _run_raw_task
    self._execute_task_with_callbacks(context)
  File "/home/airflow/.local/lib/python3.7/site-packages/airflow/models/taskinstance.py", line 1455, in _execute_task_with_callbacks
    result = self._execute_task(context, self.task)
  File "/home/airflow/.local/lib/python3.7/site-packages/airflow/models/taskinstance.py", line 1511, in _execute_task
    result = execute_callable(context=context)
  File "/home/airflow/.local/lib/python3.7/site-packages/airflow/operators/bash.py", line 188, in execute
    f'Bash command failed. The command returned a non-zero exit code {result.exit_code}.'
airflow.exceptions.AirflowException: Bash command failed. The command returned a non-zero exit code 56.
[2022-02-23 19:11:20,617] {local_task_job.py:154} INFO - Task exited with return code 1
[2022-02-23 19:11:20,750] {local_task_job.py:264} INFO - 0 downstream tasks scheduled from follow-on schedule check
[2022-02-23 20:03:31,766] {taskinstance.py:1032} INFO - Dependencies all met for <TaskInstance: fhv_gcs_dag.download_dataset_task scheduled__2019-01-02T00:00:00+00:00 [queued]>
[2022-02-23 20:03:31,790] {taskinstance.py:1032} INFO - Dependencies all met for <TaskInstance: fhv_gcs_dag.download_dataset_task scheduled__2019-01-02T00:00:00+00:00 [queued]>
[2022-02-23 20:03:31,791] {taskinstance.py:1238} INFO - 
--------------------------------------------------------------------------------
[2022-02-23 20:03:31,791] {taskinstance.py:1239} INFO - Starting attempt 1 of 2
[2022-02-23 20:03:31,791] {taskinstance.py:1240} INFO - 
--------------------------------------------------------------------------------
[2022-02-23 20:03:31,823] {taskinstance.py:1259} INFO - Executing <Task(BashOperator): download_dataset_task> on 2019-01-02 00:00:00+00:00
[2022-02-23 20:03:31,836] {standard_task_runner.py:52} INFO - Started process 105 to run task
[2022-02-23 20:03:31,856] {standard_task_runner.py:76} INFO - Running: ['***', 'tasks', 'run', 'fhv_gcs_dag', 'download_dataset_task', 'scheduled__2019-01-02T00:00:00+00:00', '--job-id', '3', '--raw', '--subdir', 'DAGS_FOLDER/fhv_gcs_dag.py', '--cfg-path', '/tmp/tmptytoebsv', '--error-file', '/tmp/tmpxsikv7xi']
[2022-02-23 20:03:31,858] {standard_task_runner.py:77} INFO - Job 3: Subtask download_dataset_task
[2022-02-23 20:03:32,022] {logging_mixin.py:109} INFO - Running <TaskInstance: fhv_gcs_dag.download_dataset_task scheduled__2019-01-02T00:00:00+00:00 [running]> on host 1bb54b80b2ee
[2022-02-23 20:03:32,101] {warnings.py:110} WARNING - /home/***/.local/lib/python3.7/site-packages/***/utils/context.py:152: AirflowContextDeprecationWarning: Accessing 'execution_date' from the template is deprecated and will be removed in a future version. Please use 'data_interval_start' or 'logical_date' instead.
  warnings.warn(_create_deprecation_warning(key, self._deprecation_replacements[key]))

[2022-02-23 20:03:32,157] {taskinstance.py:1426} INFO - Exporting the following env vars:
AIRFLOW_CTX_DAG_OWNER=***
AIRFLOW_CTX_DAG_ID=fhv_gcs_dag
AIRFLOW_CTX_TASK_ID=download_dataset_task
AIRFLOW_CTX_EXECUTION_DATE=2019-01-02T00:00:00+00:00
AIRFLOW_CTX_DAG_RUN_ID=scheduled__2019-01-02T00:00:00+00:00
[2022-02-23 20:03:32,159] {subprocess.py:62} INFO - Tmp dir root location: 
 /tmp
[2022-02-23 20:03:32,159] {subprocess.py:74} INFO - Running command: ['bash', '-c', 'curl -sS https://nyc-tlc.s3.amazonaws.com/trip+data/fhv_tripdata_2019-01.csv > /opt/***/output_2019-01.csv']
[2022-02-23 20:03:32,185] {subprocess.py:85} INFO - Output:
[2022-02-23 20:03:57,471] {local_task_job.py:212} WARNING - State of this instance has been externally set to restarting. Terminating instance.
[2022-02-23 20:03:57,478] {process_utils.py:124} INFO - Sending Signals.SIGTERM to group 105. PIDs of all processes in the group: [109, 111, 105]
[2022-02-23 20:03:57,478] {process_utils.py:75} INFO - Sending the signal Signals.SIGTERM to group 105
[2022-02-23 20:03:57,479] {taskinstance.py:1408} ERROR - Received SIGTERM. Terminating subprocesses.
[2022-02-23 20:03:57,479] {subprocess.py:99} INFO - Sending SIGTERM signal to process group
[2022-02-23 20:03:57,487] {process_utils.py:70} INFO - Process psutil.Process(pid=111, status='terminated', started='20:03:32') (111) terminated with exit code None
[2022-02-23 20:03:57,571] {taskinstance.py:1700} ERROR - Task failed with exception
Traceback (most recent call last):
  File "/home/airflow/.local/lib/python3.7/site-packages/airflow/models/taskinstance.py", line 1329, in _run_raw_task
    self._execute_task_with_callbacks(context)
  File "/home/airflow/.local/lib/python3.7/site-packages/airflow/models/taskinstance.py", line 1455, in _execute_task_with_callbacks
    result = self._execute_task(context, self.task)
  File "/home/airflow/.local/lib/python3.7/site-packages/airflow/models/taskinstance.py", line 1511, in _execute_task
    result = execute_callable(context=context)
  File "/home/airflow/.local/lib/python3.7/site-packages/airflow/operators/bash.py", line 182, in execute
    cwd=self.cwd,
  File "/home/airflow/.local/lib/python3.7/site-packages/airflow/hooks/subprocess.py", line 87, in run_command
    for raw_line in iter(self.sub_process.stdout.readline, b''):
  File "/home/airflow/.local/lib/python3.7/site-packages/airflow/models/taskinstance.py", line 1410, in signal_handler
    raise AirflowException("Task received SIGTERM signal")
airflow.exceptions.AirflowException: Task received SIGTERM signal
[2022-02-23 20:03:57,616] {taskinstance.py:1277} INFO - Marking task as UP_FOR_RETRY. dag_id=fhv_gcs_dag, task_id=download_dataset_task, execution_date=20190102T000000, start_date=20220223T200331, end_date=20220223T200357
[2022-02-23 20:03:57,732] {standard_task_runner.py:92} ERROR - Failed to execute job 3 for task download_dataset_task
Traceback (most recent call last):
  File "/home/airflow/.local/lib/python3.7/site-packages/airflow/task/task_runner/standard_task_runner.py", line 85, in _start_by_fork
    args.func(args, dag=self.dag)
  File "/home/airflow/.local/lib/python3.7/site-packages/airflow/cli/cli_parser.py", line 48, in command
    return func(*args, **kwargs)
  File "/home/airflow/.local/lib/python3.7/site-packages/airflow/utils/cli.py", line 92, in wrapper
    return f(*args, **kwargs)
  File "/home/airflow/.local/lib/python3.7/site-packages/airflow/cli/commands/task_command.py", line 298, in task_run
    _run_task_by_selected_method(args, dag, ti)
  File "/home/airflow/.local/lib/python3.7/site-packages/airflow/cli/commands/task_command.py", line 107, in _run_task_by_selected_method
    _run_raw_task(args, ti)
  File "/home/airflow/.local/lib/python3.7/site-packages/airflow/cli/commands/task_command.py", line 184, in _run_raw_task
    error_file=args.error_file,
  File "/home/airflow/.local/lib/python3.7/site-packages/airflow/utils/session.py", line 70, in wrapper
    return func(*args, session=session, **kwargs)
  File "/home/airflow/.local/lib/python3.7/site-packages/airflow/models/taskinstance.py", line 1329, in _run_raw_task
    self._execute_task_with_callbacks(context)
  File "/home/airflow/.local/lib/python3.7/site-packages/airflow/models/taskinstance.py", line 1455, in _execute_task_with_callbacks
    result = self._execute_task(context, self.task)
  File "/home/airflow/.local/lib/python3.7/site-packages/airflow/models/taskinstance.py", line 1511, in _execute_task
    result = execute_callable(context=context)
  File "/home/airflow/.local/lib/python3.7/site-packages/airflow/operators/bash.py", line 182, in execute
    cwd=self.cwd,
  File "/home/airflow/.local/lib/python3.7/site-packages/airflow/hooks/subprocess.py", line 87, in run_command
    for raw_line in iter(self.sub_process.stdout.readline, b''):
  File "/home/airflow/.local/lib/python3.7/site-packages/airflow/models/taskinstance.py", line 1410, in signal_handler
    raise AirflowException("Task received SIGTERM signal")
airflow.exceptions.AirflowException: Task received SIGTERM signal
[2022-02-23 20:03:57,801] {process_utils.py:70} INFO - Process psutil.Process(pid=109, status='terminated', started='20:03:32') (109) terminated with exit code None
[2022-02-23 20:03:57,801] {process_utils.py:70} INFO - Process psutil.Process(pid=105, status='terminated', exitcode=1, started='20:03:31') (105) terminated with exit code 1
[2022-02-23 20:39:42,158] {taskinstance.py:1032} INFO - Dependencies all met for <TaskInstance: fhv_gcs_dag.download_dataset_task scheduled__2019-01-02T00:00:00+00:00 [queued]>
[2022-02-23 20:39:42,274] {taskinstance.py:1032} INFO - Dependencies all met for <TaskInstance: fhv_gcs_dag.download_dataset_task scheduled__2019-01-02T00:00:00+00:00 [queued]>
[2022-02-23 20:39:42,275] {taskinstance.py:1238} INFO - 
--------------------------------------------------------------------------------
[2022-02-23 20:39:42,275] {taskinstance.py:1239} INFO - Starting attempt 1 of 2
[2022-02-23 20:39:42,275] {taskinstance.py:1240} INFO - 
--------------------------------------------------------------------------------
[2022-02-23 20:39:42,344] {taskinstance.py:1259} INFO - Executing <Task(BashOperator): download_dataset_task> on 2019-01-02 00:00:00+00:00
[2022-02-23 20:39:42,374] {standard_task_runner.py:52} INFO - Started process 185 to run task
[2022-02-23 20:39:42,388] {standard_task_runner.py:76} INFO - Running: ['***', 'tasks', 'run', 'fhv_gcs_dag', 'download_dataset_task', 'scheduled__2019-01-02T00:00:00+00:00', '--job-id', '4', '--raw', '--subdir', 'DAGS_FOLDER/fhv_gcs_dag.py', '--cfg-path', '/tmp/tmpv8nsrbdy', '--error-file', '/tmp/tmpvft3r22r']
[2022-02-23 20:39:42,394] {standard_task_runner.py:77} INFO - Job 4: Subtask download_dataset_task
[2022-02-23 20:39:42,570] {logging_mixin.py:109} INFO - Running <TaskInstance: fhv_gcs_dag.download_dataset_task scheduled__2019-01-02T00:00:00+00:00 [running]> on host 1c172e0325c8
[2022-02-23 20:39:42,711] {warnings.py:110} WARNING - /home/***/.local/lib/python3.7/site-packages/***/utils/context.py:152: AirflowContextDeprecationWarning: Accessing 'execution_date' from the template is deprecated and will be removed in a future version. Please use 'data_interval_start' or 'logical_date' instead.
  warnings.warn(_create_deprecation_warning(key, self._deprecation_replacements[key]))

[2022-02-23 20:39:42,764] {taskinstance.py:1426} INFO - Exporting the following env vars:
AIRFLOW_CTX_DAG_OWNER=***
AIRFLOW_CTX_DAG_ID=fhv_gcs_dag
AIRFLOW_CTX_TASK_ID=download_dataset_task
AIRFLOW_CTX_EXECUTION_DATE=2019-01-02T00:00:00+00:00
AIRFLOW_CTX_DAG_RUN_ID=scheduled__2019-01-02T00:00:00+00:00
[2022-02-23 20:39:42,766] {subprocess.py:62} INFO - Tmp dir root location: 
 /tmp
[2022-02-23 20:39:42,767] {subprocess.py:74} INFO - Running command: ['bash', '-c', 'curl -sS https://nyc-tlc.s3.amazonaws.com/trip+data/fhv_tripdata_2019-01.csv > /opt/***/output_2019-01.csv']
[2022-02-23 20:39:42,831] {subprocess.py:85} INFO - Output:
[2022-02-23 20:44:23,958] {subprocess.py:93} INFO - Command exited with return code 0
[2022-02-23 20:44:23,991] {taskinstance.py:1277} INFO - Marking task as SUCCESS. dag_id=fhv_gcs_dag, task_id=download_dataset_task, execution_date=20190102T000000, start_date=20220223T203942, end_date=20220223T204423
[2022-02-23 20:44:24,021] {local_task_job.py:154} INFO - Task exited with return code 0
[2022-02-23 20:44:24,060] {local_task_job.py:264} INFO - 1 downstream tasks scheduled from follow-on schedule check
