[2022-02-23 19:17:43,839] {taskinstance.py:1032} INFO - Dependencies all met for <TaskInstance: fhv_gcs_dag.download_dataset_task scheduled__2019-01-02T00:00:00+00:00 [queued]>
[2022-02-23 19:17:43,881] {taskinstance.py:1032} INFO - Dependencies all met for <TaskInstance: fhv_gcs_dag.download_dataset_task scheduled__2019-01-02T00:00:00+00:00 [queued]>
[2022-02-23 19:17:43,881] {taskinstance.py:1238} INFO - 
--------------------------------------------------------------------------------
[2022-02-23 19:17:43,881] {taskinstance.py:1239} INFO - Starting attempt 3 of 3
[2022-02-23 19:17:43,881] {taskinstance.py:1240} INFO - 
--------------------------------------------------------------------------------
[2022-02-23 19:17:43,916] {taskinstance.py:1259} INFO - Executing <Task(BashOperator): download_dataset_task> on 2019-01-02 00:00:00+00:00
[2022-02-23 19:17:43,923] {standard_task_runner.py:52} INFO - Started process 81 to run task
[2022-02-23 19:17:43,930] {standard_task_runner.py:76} INFO - Running: ['***', 'tasks', 'run', 'fhv_gcs_dag', 'download_dataset_task', 'scheduled__2019-01-02T00:00:00+00:00', '--job-id', '620', '--raw', '--subdir', 'DAGS_FOLDER/fhv_gcs_dag.py', '--cfg-path', '/tmp/tmpirmdxfzs', '--error-file', '/tmp/tmpkat5mqow']
[2022-02-23 19:17:43,931] {standard_task_runner.py:77} INFO - Job 620: Subtask download_dataset_task
[2022-02-23 19:17:44,141] {logging_mixin.py:109} INFO - Running <TaskInstance: fhv_gcs_dag.download_dataset_task scheduled__2019-01-02T00:00:00+00:00 [running]> on host 537c9393f0b3
[2022-02-23 19:17:44,298] {warnings.py:110} WARNING - /home/***/.local/lib/python3.7/site-packages/***/utils/context.py:152: AirflowContextDeprecationWarning: Accessing 'execution_date' from the template is deprecated and will be removed in a future version. Please use 'data_interval_start' or 'logical_date' instead.
  warnings.warn(_create_deprecation_warning(key, self._deprecation_replacements[key]))

[2022-02-23 19:17:44,375] {taskinstance.py:1426} INFO - Exporting the following env vars:
AIRFLOW_CTX_DAG_OWNER=***
AIRFLOW_CTX_DAG_ID=fhv_gcs_dag
AIRFLOW_CTX_TASK_ID=download_dataset_task
AIRFLOW_CTX_EXECUTION_DATE=2019-01-02T00:00:00+00:00
AIRFLOW_CTX_DAG_RUN_ID=scheduled__2019-01-02T00:00:00+00:00
[2022-02-23 19:17:44,379] {subprocess.py:62} INFO - Tmp dir root location: 
 /tmp
[2022-02-23 19:17:44,379] {subprocess.py:74} INFO - Running command: ['bash', '-c', 'curl -sS https://nyc-tlc.s3.amazonaws.com/trip+data/fhv_tripdata_2019-01.csv > /opt/***/output_2019-01.csv']
[2022-02-23 19:17:44,460] {subprocess.py:85} INFO - Output:
[2022-02-23 19:19:20,673] {local_task_job.py:212} WARNING - State of this instance has been externally set to restarting. Terminating instance.
[2022-02-23 19:19:20,677] {process_utils.py:124} INFO - Sending Signals.SIGTERM to group 81. PIDs of all processes in the group: [82, 83, 81]
[2022-02-23 19:19:20,677] {process_utils.py:75} INFO - Sending the signal Signals.SIGTERM to group 81
[2022-02-23 19:19:20,677] {taskinstance.py:1408} ERROR - Received SIGTERM. Terminating subprocesses.
[2022-02-23 19:19:20,677] {subprocess.py:99} INFO - Sending SIGTERM signal to process group
[2022-02-23 19:19:20,679] {process_utils.py:70} INFO - Process psutil.Process(pid=83, status='terminated', started='19:17:44') (83) terminated with exit code None
[2022-02-23 19:19:20,698] {taskinstance.py:1700} ERROR - Task failed with exception
Traceback (most recent call last):
  File "/home/airflow/.local/lib/python3.7/site-packages/airflow/models/taskinstance.py", line 1329, in _run_raw_task
    self._execute_task_with_callbacks(context)
  File "/home/airflow/.local/lib/python3.7/site-packages/airflow/models/taskinstance.py", line 1455, in _execute_task_with_callbacks
    result = self._execute_task(context, self.task)
  File "/home/airflow/.local/lib/python3.7/site-packages/airflow/models/taskinstance.py", line 1511, in _execute_task
    result = execute_callable(context=context)
  File "/home/airflow/.local/lib/python3.7/site-packages/airflow/operators/bash.py", line 182, in execute
    cwd=self.cwd,
  File "/home/airflow/.local/lib/python3.7/site-packages/airflow/hooks/subprocess.py", line 87, in run_command
    for raw_line in iter(self.sub_process.stdout.readline, b''):
  File "/home/airflow/.local/lib/python3.7/site-packages/airflow/models/taskinstance.py", line 1410, in signal_handler
    raise AirflowException("Task received SIGTERM signal")
airflow.exceptions.AirflowException: Task received SIGTERM signal
[2022-02-23 19:19:20,709] {taskinstance.py:1277} INFO - Marking task as UP_FOR_RETRY. dag_id=fhv_gcs_dag, task_id=download_dataset_task, execution_date=20190102T000000, start_date=20220223T191743, end_date=20220223T191920
[2022-02-23 19:19:20,736] {standard_task_runner.py:92} ERROR - Failed to execute job 620 for task download_dataset_task
Traceback (most recent call last):
  File "/home/airflow/.local/lib/python3.7/site-packages/airflow/task/task_runner/standard_task_runner.py", line 85, in _start_by_fork
    args.func(args, dag=self.dag)
  File "/home/airflow/.local/lib/python3.7/site-packages/airflow/cli/cli_parser.py", line 48, in command
    return func(*args, **kwargs)
  File "/home/airflow/.local/lib/python3.7/site-packages/airflow/utils/cli.py", line 92, in wrapper
    return f(*args, **kwargs)
  File "/home/airflow/.local/lib/python3.7/site-packages/airflow/cli/commands/task_command.py", line 298, in task_run
    _run_task_by_selected_method(args, dag, ti)
  File "/home/airflow/.local/lib/python3.7/site-packages/airflow/cli/commands/task_command.py", line 107, in _run_task_by_selected_method
    _run_raw_task(args, ti)
  File "/home/airflow/.local/lib/python3.7/site-packages/airflow/cli/commands/task_command.py", line 184, in _run_raw_task
    error_file=args.error_file,
  File "/home/airflow/.local/lib/python3.7/site-packages/airflow/utils/session.py", line 70, in wrapper
    return func(*args, session=session, **kwargs)
  File "/home/airflow/.local/lib/python3.7/site-packages/airflow/models/taskinstance.py", line 1329, in _run_raw_task
    self._execute_task_with_callbacks(context)
  File "/home/airflow/.local/lib/python3.7/site-packages/airflow/models/taskinstance.py", line 1455, in _execute_task_with_callbacks
    result = self._execute_task(context, self.task)
  File "/home/airflow/.local/lib/python3.7/site-packages/airflow/models/taskinstance.py", line 1511, in _execute_task
    result = execute_callable(context=context)
  File "/home/airflow/.local/lib/python3.7/site-packages/airflow/operators/bash.py", line 182, in execute
    cwd=self.cwd,
  File "/home/airflow/.local/lib/python3.7/site-packages/airflow/hooks/subprocess.py", line 87, in run_command
    for raw_line in iter(self.sub_process.stdout.readline, b''):
  File "/home/airflow/.local/lib/python3.7/site-packages/airflow/models/taskinstance.py", line 1410, in signal_handler
    raise AirflowException("Task received SIGTERM signal")
airflow.exceptions.AirflowException: Task received SIGTERM signal
[2022-02-23 19:19:20,772] {process_utils.py:70} INFO - Process psutil.Process(pid=82, status='terminated', started='19:17:44') (82) terminated with exit code None
[2022-02-23 19:19:20,773] {process_utils.py:70} INFO - Process psutil.Process(pid=81, status='terminated', exitcode=1, started='19:17:43') (81) terminated with exit code 1
