[2022-02-09 20:23:57,285] {taskinstance.py:1032} INFO - Dependencies all met for <TaskInstance: green_taxi_gcs_dag.local_to_gcs_task scheduled__2019-02-02T00:00:00+00:00 [queued]>
[2022-02-09 20:23:57,315] {taskinstance.py:1032} INFO - Dependencies all met for <TaskInstance: green_taxi_gcs_dag.local_to_gcs_task scheduled__2019-02-02T00:00:00+00:00 [queued]>
[2022-02-09 20:23:57,316] {taskinstance.py:1238} INFO - 
--------------------------------------------------------------------------------
[2022-02-09 20:23:57,316] {taskinstance.py:1239} INFO - Starting attempt 1 of 2
[2022-02-09 20:23:57,317] {taskinstance.py:1240} INFO - 
--------------------------------------------------------------------------------
[2022-02-09 20:23:57,346] {taskinstance.py:1259} INFO - Executing <Task(PythonOperator): local_to_gcs_task> on 2019-02-02 00:00:00+00:00
[2022-02-09 20:23:57,356] {standard_task_runner.py:52} INFO - Started process 182 to run task
[2022-02-09 20:23:57,366] {standard_task_runner.py:76} INFO - Running: ['***', 'tasks', 'run', 'green_taxi_gcs_dag', 'local_to_gcs_task', 'scheduled__2019-02-02T00:00:00+00:00', '--job-id', '9', '--raw', '--subdir', 'DAGS_FOLDER/green_gcs_dag.py', '--cfg-path', '/tmp/tmp8ki7lrow', '--error-file', '/tmp/tmp1rvkdl_e']
[2022-02-09 20:23:57,367] {standard_task_runner.py:77} INFO - Job 9: Subtask local_to_gcs_task
[2022-02-09 20:23:57,492] {logging_mixin.py:109} INFO - Running <TaskInstance: green_taxi_gcs_dag.local_to_gcs_task scheduled__2019-02-02T00:00:00+00:00 [running]> on host c9ca302aeee6
[2022-02-09 20:23:57,583] {warnings.py:110} WARNING - /home/***/.local/lib/python3.7/site-packages/***/utils/context.py:152: AirflowContextDeprecationWarning: Accessing 'execution_date' from the template is deprecated and will be removed in a future version. Please use 'data_interval_start' or 'logical_date' instead.
  warnings.warn(_create_deprecation_warning(key, self._deprecation_replacements[key]))

[2022-02-09 20:23:57,620] {taskinstance.py:1426} INFO - Exporting the following env vars:
AIRFLOW_CTX_DAG_OWNER=***
AIRFLOW_CTX_DAG_ID=green_taxi_gcs_dag
AIRFLOW_CTX_TASK_ID=local_to_gcs_task
AIRFLOW_CTX_EXECUTION_DATE=2019-02-02T00:00:00+00:00
AIRFLOW_CTX_DAG_RUN_ID=scheduled__2019-02-02T00:00:00+00:00
[2022-02-09 20:23:57,636] {taskinstance.py:1700} ERROR - Task failed with exception
Traceback (most recent call last):
  File "/home/airflow/.local/lib/python3.7/site-packages/airflow/models/taskinstance.py", line 1329, in _run_raw_task
    self._execute_task_with_callbacks(context)
  File "/home/airflow/.local/lib/python3.7/site-packages/airflow/models/taskinstance.py", line 1455, in _execute_task_with_callbacks
    result = self._execute_task(context, self.task)
  File "/home/airflow/.local/lib/python3.7/site-packages/airflow/models/taskinstance.py", line 1511, in _execute_task
    result = execute_callable(context=context)
  File "/home/airflow/.local/lib/python3.7/site-packages/airflow/operators/python.py", line 174, in execute
    return_value = self.execute_callable()
  File "/home/airflow/.local/lib/python3.7/site-packages/airflow/operators/python.py", line 185, in execute_callable
    return self.python_callable(*self.op_args, **self.op_kwargs)
  File "/opt/airflow/dags/green_gcs_dag.py", line 49, in upload_to_gcs
    bucket = client.bucket(bucket)
  File "/home/airflow/.local/lib/python3.7/site-packages/google/cloud/storage/client.py", line 279, in bucket
    return Bucket(client=self, name=bucket_name, user_project=user_project)
  File "/home/airflow/.local/lib/python3.7/site-packages/google/cloud/storage/bucket.py", line 611, in __init__
    name = _validate_name(name)
  File "/home/airflow/.local/lib/python3.7/site-packages/google/cloud/storage/_helpers.py", line 80, in _validate_name
    if not all([name[0].isalnum(), name[-1].isalnum()]):
IndexError: string index out of range
[2022-02-09 20:23:57,660] {taskinstance.py:1277} INFO - Marking task as UP_FOR_RETRY. dag_id=green_taxi_gcs_dag, task_id=local_to_gcs_task, execution_date=20190202T000000, start_date=20220209T202357, end_date=20220209T202357
[2022-02-09 20:23:57,687] {standard_task_runner.py:92} ERROR - Failed to execute job 9 for task local_to_gcs_task
Traceback (most recent call last):
  File "/home/airflow/.local/lib/python3.7/site-packages/airflow/task/task_runner/standard_task_runner.py", line 85, in _start_by_fork
    args.func(args, dag=self.dag)
  File "/home/airflow/.local/lib/python3.7/site-packages/airflow/cli/cli_parser.py", line 48, in command
    return func(*args, **kwargs)
  File "/home/airflow/.local/lib/python3.7/site-packages/airflow/utils/cli.py", line 92, in wrapper
    return f(*args, **kwargs)
  File "/home/airflow/.local/lib/python3.7/site-packages/airflow/cli/commands/task_command.py", line 298, in task_run
    _run_task_by_selected_method(args, dag, ti)
  File "/home/airflow/.local/lib/python3.7/site-packages/airflow/cli/commands/task_command.py", line 107, in _run_task_by_selected_method
    _run_raw_task(args, ti)
  File "/home/airflow/.local/lib/python3.7/site-packages/airflow/cli/commands/task_command.py", line 184, in _run_raw_task
    error_file=args.error_file,
  File "/home/airflow/.local/lib/python3.7/site-packages/airflow/utils/session.py", line 70, in wrapper
    return func(*args, session=session, **kwargs)
  File "/home/airflow/.local/lib/python3.7/site-packages/airflow/models/taskinstance.py", line 1329, in _run_raw_task
    self._execute_task_with_callbacks(context)
  File "/home/airflow/.local/lib/python3.7/site-packages/airflow/models/taskinstance.py", line 1455, in _execute_task_with_callbacks
    result = self._execute_task(context, self.task)
  File "/home/airflow/.local/lib/python3.7/site-packages/airflow/models/taskinstance.py", line 1511, in _execute_task
    result = execute_callable(context=context)
  File "/home/airflow/.local/lib/python3.7/site-packages/airflow/operators/python.py", line 174, in execute
    return_value = self.execute_callable()
  File "/home/airflow/.local/lib/python3.7/site-packages/airflow/operators/python.py", line 185, in execute_callable
    return self.python_callable(*self.op_args, **self.op_kwargs)
  File "/opt/airflow/dags/green_gcs_dag.py", line 49, in upload_to_gcs
    bucket = client.bucket(bucket)
  File "/home/airflow/.local/lib/python3.7/site-packages/google/cloud/storage/client.py", line 279, in bucket
    return Bucket(client=self, name=bucket_name, user_project=user_project)
  File "/home/airflow/.local/lib/python3.7/site-packages/google/cloud/storage/bucket.py", line 611, in __init__
    name = _validate_name(name)
  File "/home/airflow/.local/lib/python3.7/site-packages/google/cloud/storage/_helpers.py", line 80, in _validate_name
    if not all([name[0].isalnum(), name[-1].isalnum()]):
IndexError: string index out of range
[2022-02-09 20:23:57,706] {local_task_job.py:154} INFO - Task exited with return code 1
[2022-02-09 20:23:57,786] {local_task_job.py:264} INFO - 0 downstream tasks scheduled from follow-on schedule check
[2022-02-09 20:42:34,776] {taskinstance.py:1032} INFO - Dependencies all met for <TaskInstance: green_taxi_gcs_dag.local_to_gcs_task scheduled__2019-02-02T00:00:00+00:00 [queued]>
[2022-02-09 20:42:34,812] {taskinstance.py:1032} INFO - Dependencies all met for <TaskInstance: green_taxi_gcs_dag.local_to_gcs_task scheduled__2019-02-02T00:00:00+00:00 [queued]>
[2022-02-09 20:42:34,813] {taskinstance.py:1238} INFO - 
--------------------------------------------------------------------------------
[2022-02-09 20:42:34,813] {taskinstance.py:1239} INFO - Starting attempt 1 of 2
[2022-02-09 20:42:34,813] {taskinstance.py:1240} INFO - 
--------------------------------------------------------------------------------
[2022-02-09 20:42:34,871] {taskinstance.py:1259} INFO - Executing <Task(PythonOperator): local_to_gcs_task> on 2019-02-02 00:00:00+00:00
[2022-02-09 20:42:34,886] {standard_task_runner.py:52} INFO - Started process 570 to run task
[2022-02-09 20:42:34,906] {standard_task_runner.py:76} INFO - Running: ['***', 'tasks', 'run', 'green_taxi_gcs_dag', 'local_to_gcs_task', 'scheduled__2019-02-02T00:00:00+00:00', '--job-id', '123', '--raw', '--subdir', 'DAGS_FOLDER/green_gcs_dag.py', '--cfg-path', '/tmp/tmphesedlht', '--error-file', '/tmp/tmpww5jmgyc']
[2022-02-09 20:42:34,917] {standard_task_runner.py:77} INFO - Job 123: Subtask local_to_gcs_task
[2022-02-09 20:42:35,103] {logging_mixin.py:109} INFO - Running <TaskInstance: green_taxi_gcs_dag.local_to_gcs_task scheduled__2019-02-02T00:00:00+00:00 [running]> on host 4f97b6b16bdb
[2022-02-09 20:42:35,183] {warnings.py:110} WARNING - /home/***/.local/lib/python3.7/site-packages/***/utils/context.py:152: AirflowContextDeprecationWarning: Accessing 'execution_date' from the template is deprecated and will be removed in a future version. Please use 'data_interval_start' or 'logical_date' instead.
  warnings.warn(_create_deprecation_warning(key, self._deprecation_replacements[key]))

[2022-02-09 20:42:35,234] {taskinstance.py:1426} INFO - Exporting the following env vars:
AIRFLOW_CTX_DAG_OWNER=***
AIRFLOW_CTX_DAG_ID=green_taxi_gcs_dag
AIRFLOW_CTX_TASK_ID=local_to_gcs_task
AIRFLOW_CTX_EXECUTION_DATE=2019-02-02T00:00:00+00:00
AIRFLOW_CTX_DAG_RUN_ID=scheduled__2019-02-02T00:00:00+00:00
[2022-02-09 20:42:36,994] {python.py:175} INFO - Done. Returned value was: None
[2022-02-09 20:42:37,021] {taskinstance.py:1277} INFO - Marking task as SUCCESS. dag_id=green_taxi_gcs_dag, task_id=local_to_gcs_task, execution_date=20190202T000000, start_date=20220209T204234, end_date=20220209T204237
[2022-02-09 20:42:37,114] {local_task_job.py:154} INFO - Task exited with return code 0
[2022-02-09 20:42:37,200] {local_task_job.py:264} INFO - 1 downstream tasks scheduled from follow-on schedule check
[2022-02-20 00:00:59,702] {taskinstance.py:1032} INFO - Dependencies all met for <TaskInstance: green_taxi_gcs_dag.local_to_gcs_task scheduled__2019-02-02T00:00:00+00:00 [queued]>
[2022-02-20 00:00:59,731] {taskinstance.py:1032} INFO - Dependencies all met for <TaskInstance: green_taxi_gcs_dag.local_to_gcs_task scheduled__2019-02-02T00:00:00+00:00 [queued]>
[2022-02-20 00:00:59,731] {taskinstance.py:1238} INFO - 
--------------------------------------------------------------------------------
[2022-02-20 00:00:59,731] {taskinstance.py:1239} INFO - Starting attempt 1 of 2
[2022-02-20 00:00:59,732] {taskinstance.py:1240} INFO - 
--------------------------------------------------------------------------------
[2022-02-20 00:00:59,752] {taskinstance.py:1259} INFO - Executing <Task(PythonOperator): local_to_gcs_task> on 2019-02-02 00:00:00+00:00
[2022-02-20 00:00:59,759] {standard_task_runner.py:52} INFO - Started process 367 to run task
[2022-02-20 00:00:59,763] {standard_task_runner.py:76} INFO - Running: ['***', 'tasks', 'run', 'green_taxi_gcs_dag', 'local_to_gcs_task', 'scheduled__2019-02-02T00:00:00+00:00', '--job-id', '316', '--raw', '--subdir', 'DAGS_FOLDER/green_gcs_dag.py', '--cfg-path', '/tmp/tmpf_w4fvl0', '--error-file', '/tmp/tmpm22q2v41']
[2022-02-20 00:00:59,765] {standard_task_runner.py:77} INFO - Job 316: Subtask local_to_gcs_task
[2022-02-20 00:00:59,889] {logging_mixin.py:109} INFO - Running <TaskInstance: green_taxi_gcs_dag.local_to_gcs_task scheduled__2019-02-02T00:00:00+00:00 [running]> on host da07aa254901
[2022-02-20 00:00:59,977] {warnings.py:110} WARNING - /home/***/.local/lib/python3.7/site-packages/***/utils/context.py:152: AirflowContextDeprecationWarning: Accessing 'execution_date' from the template is deprecated and will be removed in a future version. Please use 'data_interval_start' or 'logical_date' instead.
  warnings.warn(_create_deprecation_warning(key, self._deprecation_replacements[key]))

[2022-02-20 00:01:00,006] {taskinstance.py:1426} INFO - Exporting the following env vars:
AIRFLOW_CTX_DAG_OWNER=***
AIRFLOW_CTX_DAG_ID=green_taxi_gcs_dag
AIRFLOW_CTX_TASK_ID=local_to_gcs_task
AIRFLOW_CTX_EXECUTION_DATE=2019-02-02T00:00:00+00:00
AIRFLOW_CTX_DAG_RUN_ID=scheduled__2019-02-02T00:00:00+00:00
[2022-02-20 00:01:02,285] {python.py:175} INFO - Done. Returned value was: None
[2022-02-20 00:01:02,303] {taskinstance.py:1277} INFO - Marking task as SUCCESS. dag_id=green_taxi_gcs_dag, task_id=local_to_gcs_task, execution_date=20190202T000000, start_date=20220220T000059, end_date=20220220T000102
[2022-02-20 00:01:02,352] {local_task_job.py:154} INFO - Task exited with return code 0
[2022-02-20 00:01:02,395] {local_task_job.py:264} INFO - 1 downstream tasks scheduled from follow-on schedule check
[2022-02-20 01:59:11,715] {taskinstance.py:1032} INFO - Dependencies all met for <TaskInstance: green_taxi_gcs_dag.local_to_gcs_task scheduled__2019-02-02T00:00:00+00:00 [queued]>
[2022-02-20 01:59:11,751] {taskinstance.py:1032} INFO - Dependencies all met for <TaskInstance: green_taxi_gcs_dag.local_to_gcs_task scheduled__2019-02-02T00:00:00+00:00 [queued]>
[2022-02-20 01:59:11,754] {taskinstance.py:1238} INFO - 
--------------------------------------------------------------------------------
[2022-02-20 01:59:11,755] {taskinstance.py:1239} INFO - Starting attempt 1 of 2
[2022-02-20 01:59:11,755] {taskinstance.py:1240} INFO - 
--------------------------------------------------------------------------------
[2022-02-20 01:59:11,810] {taskinstance.py:1259} INFO - Executing <Task(PythonOperator): local_to_gcs_task> on 2019-02-02 00:00:00+00:00
[2022-02-20 01:59:11,827] {standard_task_runner.py:52} INFO - Started process 219 to run task
[2022-02-20 01:59:11,841] {standard_task_runner.py:76} INFO - Running: ['***', 'tasks', 'run', 'green_taxi_gcs_dag', 'local_to_gcs_task', 'scheduled__2019-02-02T00:00:00+00:00', '--job-id', '519', '--raw', '--subdir', 'DAGS_FOLDER/green_gcs_dag.py', '--cfg-path', '/tmp/tmp2wpvxpzn', '--error-file', '/tmp/tmpryz6_6wf']
[2022-02-20 01:59:11,844] {standard_task_runner.py:77} INFO - Job 519: Subtask local_to_gcs_task
[2022-02-20 01:59:11,947] {logging_mixin.py:109} INFO - Running <TaskInstance: green_taxi_gcs_dag.local_to_gcs_task scheduled__2019-02-02T00:00:00+00:00 [running]> on host 5484a3a1f7c3
[2022-02-20 01:59:12,024] {warnings.py:110} WARNING - /home/***/.local/lib/python3.7/site-packages/***/utils/context.py:152: AirflowContextDeprecationWarning: Accessing 'execution_date' from the template is deprecated and will be removed in a future version. Please use 'data_interval_start' or 'logical_date' instead.
  warnings.warn(_create_deprecation_warning(key, self._deprecation_replacements[key]))

[2022-02-20 01:59:12,116] {taskinstance.py:1426} INFO - Exporting the following env vars:
AIRFLOW_CTX_DAG_OWNER=***
AIRFLOW_CTX_DAG_ID=green_taxi_gcs_dag
AIRFLOW_CTX_TASK_ID=local_to_gcs_task
AIRFLOW_CTX_EXECUTION_DATE=2019-02-02T00:00:00+00:00
AIRFLOW_CTX_DAG_RUN_ID=scheduled__2019-02-02T00:00:00+00:00
[2022-02-20 01:59:13,768] {python.py:175} INFO - Done. Returned value was: None
[2022-02-20 01:59:13,787] {taskinstance.py:1277} INFO - Marking task as SUCCESS. dag_id=green_taxi_gcs_dag, task_id=local_to_gcs_task, execution_date=20190202T000000, start_date=20220220T015911, end_date=20220220T015913
[2022-02-20 01:59:13,864] {local_task_job.py:154} INFO - Task exited with return code 0
[2022-02-20 01:59:13,976] {local_task_job.py:264} INFO - 1 downstream tasks scheduled from follow-on schedule check
[2022-02-23 20:11:32,299] {taskinstance.py:1032} INFO - Dependencies all met for <TaskInstance: green_taxi_gcs_dag.local_to_gcs_task scheduled__2019-02-02T00:00:00+00:00 [queued]>
[2022-02-23 20:11:32,359] {taskinstance.py:1032} INFO - Dependencies all met for <TaskInstance: green_taxi_gcs_dag.local_to_gcs_task scheduled__2019-02-02T00:00:00+00:00 [queued]>
[2022-02-23 20:11:32,359] {taskinstance.py:1238} INFO - 
--------------------------------------------------------------------------------
[2022-02-23 20:11:32,361] {taskinstance.py:1239} INFO - Starting attempt 1 of 2
[2022-02-23 20:11:32,362] {taskinstance.py:1240} INFO - 
--------------------------------------------------------------------------------
[2022-02-23 20:11:32,410] {taskinstance.py:1259} INFO - Executing <Task(PythonOperator): local_to_gcs_task> on 2019-02-02 00:00:00+00:00
[2022-02-23 20:11:32,426] {standard_task_runner.py:52} INFO - Started process 515 to run task
[2022-02-23 20:11:32,432] {standard_task_runner.py:76} INFO - Running: ['***', 'tasks', 'run', 'green_taxi_gcs_dag', 'local_to_gcs_task', 'scheduled__2019-02-02T00:00:00+00:00', '--job-id', '24', '--raw', '--subdir', 'DAGS_FOLDER/green_gcs_dag.py', '--cfg-path', '/tmp/tmpa_19580n', '--error-file', '/tmp/tmpfaj06_ce']
[2022-02-23 20:11:32,438] {standard_task_runner.py:77} INFO - Job 24: Subtask local_to_gcs_task
[2022-02-23 20:11:32,566] {logging_mixin.py:109} INFO - Running <TaskInstance: green_taxi_gcs_dag.local_to_gcs_task scheduled__2019-02-02T00:00:00+00:00 [running]> on host 1bb54b80b2ee
[2022-02-23 20:11:32,678] {warnings.py:110} WARNING - /home/***/.local/lib/python3.7/site-packages/***/utils/context.py:152: AirflowContextDeprecationWarning: Accessing 'execution_date' from the template is deprecated and will be removed in a future version. Please use 'data_interval_start' or 'logical_date' instead.
  warnings.warn(_create_deprecation_warning(key, self._deprecation_replacements[key]))

[2022-02-23 20:11:32,744] {taskinstance.py:1426} INFO - Exporting the following env vars:
AIRFLOW_CTX_DAG_OWNER=***
AIRFLOW_CTX_DAG_ID=green_taxi_gcs_dag
AIRFLOW_CTX_TASK_ID=local_to_gcs_task
AIRFLOW_CTX_EXECUTION_DATE=2019-02-02T00:00:00+00:00
AIRFLOW_CTX_DAG_RUN_ID=scheduled__2019-02-02T00:00:00+00:00
[2022-02-23 20:11:33,314] {taskinstance.py:1700} ERROR - Task failed with exception
Traceback (most recent call last):
  File "/home/airflow/.local/lib/python3.7/site-packages/google/cloud/storage/blob.py", line 2594, in upload_from_file
    retry=retry,
  File "/home/airflow/.local/lib/python3.7/site-packages/google/cloud/storage/blob.py", line 2412, in _do_upload
    retry=retry,
  File "/home/airflow/.local/lib/python3.7/site-packages/google/cloud/storage/blob.py", line 2237, in _do_resumable_upload
    retry=retry,
  File "/home/airflow/.local/lib/python3.7/site-packages/google/cloud/storage/blob.py", line 2112, in _initiate_resumable_upload
    timeout=timeout,
  File "/home/airflow/.local/lib/python3.7/site-packages/google/resumable_media/requests/upload.py", line 421, in initiate
    retriable_request, self._get_status_code, self._retry_strategy
  File "/home/airflow/.local/lib/python3.7/site-packages/google/resumable_media/requests/_request_helpers.py", line 147, in wait_and_retry
    response = func()
  File "/home/airflow/.local/lib/python3.7/site-packages/google/resumable_media/requests/upload.py", line 416, in retriable_request
    self._process_initiate_response(result)
  File "/home/airflow/.local/lib/python3.7/site-packages/google/resumable_media/_upload.py", line 503, in _process_initiate_response
    callback=self._make_invalid,
  File "/home/airflow/.local/lib/python3.7/site-packages/google/resumable_media/_helpers.py", line 104, in require_status_code
    *status_codes
google.resumable_media.common.InvalidResponse: ('Request failed with status code', 403, 'Expected one of', <HTTPStatus.OK: 200>, <HTTPStatus.CREATED: 201>)

During handling of the above exception, another exception occurred:

Traceback (most recent call last):
  File "/home/airflow/.local/lib/python3.7/site-packages/airflow/models/taskinstance.py", line 1329, in _run_raw_task
    self._execute_task_with_callbacks(context)
  File "/home/airflow/.local/lib/python3.7/site-packages/airflow/models/taskinstance.py", line 1455, in _execute_task_with_callbacks
    result = self._execute_task(context, self.task)
  File "/home/airflow/.local/lib/python3.7/site-packages/airflow/models/taskinstance.py", line 1511, in _execute_task
    result = execute_callable(context=context)
  File "/home/airflow/.local/lib/python3.7/site-packages/airflow/operators/python.py", line 174, in execute
    return_value = self.execute_callable()
  File "/home/airflow/.local/lib/python3.7/site-packages/airflow/operators/python.py", line 185, in execute_callable
    return self.python_callable(*self.op_args, **self.op_kwargs)
  File "/opt/airflow/dags/green_gcs_dag.py", line 52, in upload_to_gcs
    blob.upload_from_filename(local_file)
  File "/home/airflow/.local/lib/python3.7/site-packages/google/cloud/storage/blob.py", line 2735, in upload_from_filename
    retry=retry,
  File "/home/airflow/.local/lib/python3.7/site-packages/google/cloud/storage/blob.py", line 2598, in upload_from_file
    _raise_from_invalid_response(exc)
  File "/home/airflow/.local/lib/python3.7/site-packages/google/cloud/storage/blob.py", line 4466, in _raise_from_invalid_response
    raise exceptions.from_http_status(response.status_code, message, response=response)
google.api_core.exceptions.Forbidden: 403 POST https://storage.googleapis.com/upload/storage/v1/b/data_lake_taxi_us/o?uploadType=resumable: {
  "error": {
    "code": 403,
    "message": "airflow-ingestion@clear-rock-338918.iam.gserviceaccount.com does not have storage.objects.create access to the Google Cloud Storage bucket.",
    "errors": [
      {
        "message": "airflow-ingestion@clear-rock-338918.iam.gserviceaccount.com does not have storage.objects.create access to the Google Cloud Storage bucket.",
        "domain": "global",
        "reason": "forbidden"
      }
    ]
  }
}
: ('Request failed with status code', 403, 'Expected one of', <HTTPStatus.OK: 200>, <HTTPStatus.CREATED: 201>)
[2022-02-23 20:11:33,366] {taskinstance.py:1277} INFO - Marking task as UP_FOR_RETRY. dag_id=green_taxi_gcs_dag, task_id=local_to_gcs_task, execution_date=20190202T000000, start_date=20220223T201132, end_date=20220223T201133
[2022-02-23 20:11:33,451] {standard_task_runner.py:92} ERROR - Failed to execute job 24 for task local_to_gcs_task
Traceback (most recent call last):
  File "/home/airflow/.local/lib/python3.7/site-packages/google/cloud/storage/blob.py", line 2594, in upload_from_file
    retry=retry,
  File "/home/airflow/.local/lib/python3.7/site-packages/google/cloud/storage/blob.py", line 2412, in _do_upload
    retry=retry,
  File "/home/airflow/.local/lib/python3.7/site-packages/google/cloud/storage/blob.py", line 2237, in _do_resumable_upload
    retry=retry,
  File "/home/airflow/.local/lib/python3.7/site-packages/google/cloud/storage/blob.py", line 2112, in _initiate_resumable_upload
    timeout=timeout,
  File "/home/airflow/.local/lib/python3.7/site-packages/google/resumable_media/requests/upload.py", line 421, in initiate
    retriable_request, self._get_status_code, self._retry_strategy
  File "/home/airflow/.local/lib/python3.7/site-packages/google/resumable_media/requests/_request_helpers.py", line 147, in wait_and_retry
    response = func()
  File "/home/airflow/.local/lib/python3.7/site-packages/google/resumable_media/requests/upload.py", line 416, in retriable_request
    self._process_initiate_response(result)
  File "/home/airflow/.local/lib/python3.7/site-packages/google/resumable_media/_upload.py", line 503, in _process_initiate_response
    callback=self._make_invalid,
  File "/home/airflow/.local/lib/python3.7/site-packages/google/resumable_media/_helpers.py", line 104, in require_status_code
    *status_codes
google.resumable_media.common.InvalidResponse: ('Request failed with status code', 403, 'Expected one of', <HTTPStatus.OK: 200>, <HTTPStatus.CREATED: 201>)

During handling of the above exception, another exception occurred:

Traceback (most recent call last):
  File "/home/airflow/.local/lib/python3.7/site-packages/airflow/task/task_runner/standard_task_runner.py", line 85, in _start_by_fork
    args.func(args, dag=self.dag)
  File "/home/airflow/.local/lib/python3.7/site-packages/airflow/cli/cli_parser.py", line 48, in command
    return func(*args, **kwargs)
  File "/home/airflow/.local/lib/python3.7/site-packages/airflow/utils/cli.py", line 92, in wrapper
    return f(*args, **kwargs)
  File "/home/airflow/.local/lib/python3.7/site-packages/airflow/cli/commands/task_command.py", line 298, in task_run
    _run_task_by_selected_method(args, dag, ti)
  File "/home/airflow/.local/lib/python3.7/site-packages/airflow/cli/commands/task_command.py", line 107, in _run_task_by_selected_method
    _run_raw_task(args, ti)
  File "/home/airflow/.local/lib/python3.7/site-packages/airflow/cli/commands/task_command.py", line 184, in _run_raw_task
    error_file=args.error_file,
  File "/home/airflow/.local/lib/python3.7/site-packages/airflow/utils/session.py", line 70, in wrapper
    return func(*args, session=session, **kwargs)
  File "/home/airflow/.local/lib/python3.7/site-packages/airflow/models/taskinstance.py", line 1329, in _run_raw_task
    self._execute_task_with_callbacks(context)
  File "/home/airflow/.local/lib/python3.7/site-packages/airflow/models/taskinstance.py", line 1455, in _execute_task_with_callbacks
    result = self._execute_task(context, self.task)
  File "/home/airflow/.local/lib/python3.7/site-packages/airflow/models/taskinstance.py", line 1511, in _execute_task
    result = execute_callable(context=context)
  File "/home/airflow/.local/lib/python3.7/site-packages/airflow/operators/python.py", line 174, in execute
    return_value = self.execute_callable()
  File "/home/airflow/.local/lib/python3.7/site-packages/airflow/operators/python.py", line 185, in execute_callable
    return self.python_callable(*self.op_args, **self.op_kwargs)
  File "/opt/airflow/dags/green_gcs_dag.py", line 52, in upload_to_gcs
    blob.upload_from_filename(local_file)
  File "/home/airflow/.local/lib/python3.7/site-packages/google/cloud/storage/blob.py", line 2735, in upload_from_filename
    retry=retry,
  File "/home/airflow/.local/lib/python3.7/site-packages/google/cloud/storage/blob.py", line 2598, in upload_from_file
    _raise_from_invalid_response(exc)
  File "/home/airflow/.local/lib/python3.7/site-packages/google/cloud/storage/blob.py", line 4466, in _raise_from_invalid_response
    raise exceptions.from_http_status(response.status_code, message, response=response)
google.api_core.exceptions.Forbidden: 403 POST https://storage.googleapis.com/upload/storage/v1/b/data_lake_taxi_us/o?uploadType=resumable: {
  "error": {
    "code": 403,
    "message": "airflow-ingestion@clear-rock-338918.iam.gserviceaccount.com does not have storage.objects.create access to the Google Cloud Storage bucket.",
    "errors": [
      {
        "message": "airflow-ingestion@clear-rock-338918.iam.gserviceaccount.com does not have storage.objects.create access to the Google Cloud Storage bucket.",
        "domain": "global",
        "reason": "forbidden"
      }
    ]
  }
}
: ('Request failed with status code', 403, 'Expected one of', <HTTPStatus.OK: 200>, <HTTPStatus.CREATED: 201>)
[2022-02-23 20:11:33,557] {local_task_job.py:154} INFO - Task exited with return code 1
[2022-02-23 20:11:33,790] {local_task_job.py:264} INFO - 0 downstream tasks scheduled from follow-on schedule check
