[2022-01-30 15:22:49,752] {taskinstance.py:1032} INFO - Dependencies all met for <TaskInstance: data_ingestion_gcs_dag.local_to_gcs_task scheduled__2022-01-29T00:00:00+00:00 [queued]>
[2022-01-30 15:22:49,763] {taskinstance.py:1032} INFO - Dependencies all met for <TaskInstance: data_ingestion_gcs_dag.local_to_gcs_task scheduled__2022-01-29T00:00:00+00:00 [queued]>
[2022-01-30 15:22:49,764] {taskinstance.py:1238} INFO - 
--------------------------------------------------------------------------------
[2022-01-30 15:22:49,764] {taskinstance.py:1239} INFO - Starting attempt 1 of 2
[2022-01-30 15:22:49,764] {taskinstance.py:1240} INFO - 
--------------------------------------------------------------------------------
[2022-01-30 15:22:49,777] {taskinstance.py:1259} INFO - Executing <Task(PythonOperator): local_to_gcs_task> on 2022-01-29 00:00:00+00:00
[2022-01-30 15:22:49,782] {standard_task_runner.py:52} INFO - Started process 86 to run task
[2022-01-30 15:22:49,786] {standard_task_runner.py:76} INFO - Running: ['***', 'tasks', 'run', 'data_ingestion_gcs_dag', 'local_to_gcs_task', 'scheduled__2022-01-29T00:00:00+00:00', '--job-id', '31', '--raw', '--subdir', 'DAGS_FOLDER/data_ingestion_gcs_dag.py', '--cfg-path', '/tmp/tmpve7u5388', '--error-file', '/tmp/tmpx1vpqbxa']
[2022-01-30 15:22:49,787] {standard_task_runner.py:77} INFO - Job 31: Subtask local_to_gcs_task
[2022-01-30 15:22:49,837] {logging_mixin.py:109} INFO - Running <TaskInstance: data_ingestion_gcs_dag.local_to_gcs_task scheduled__2022-01-29T00:00:00+00:00 [running]> on host b6db3711bc00
[2022-01-30 15:22:49,898] {taskinstance.py:1426} INFO - Exporting the following env vars:
AIRFLOW_CTX_DAG_OWNER=***
AIRFLOW_CTX_DAG_ID=data_ingestion_gcs_dag
AIRFLOW_CTX_TASK_ID=local_to_gcs_task
AIRFLOW_CTX_EXECUTION_DATE=2022-01-29T00:00:00+00:00
AIRFLOW_CTX_DAG_RUN_ID=scheduled__2022-01-29T00:00:00+00:00
[2022-01-30 15:22:52,906] {_metadata.py:104} WARNING - Compute Engine Metadata server unavailable on attempt 1 of 3. Reason: timed out
[2022-01-30 15:22:55,910] {_metadata.py:104} WARNING - Compute Engine Metadata server unavailable on attempt 2 of 3. Reason: timed out
[2022-01-30 15:22:58,913] {_metadata.py:104} WARNING - Compute Engine Metadata server unavailable on attempt 3 of 3. Reason: timed out
[2022-01-30 15:22:58,913] {_default.py:287} WARNING - Authentication failed using Compute Engine authentication due to unavailable metadata server.
[2022-01-30 15:22:58,914] {taskinstance.py:1700} ERROR - Task failed with exception
Traceback (most recent call last):
  File "/home/airflow/.local/lib/python3.7/site-packages/airflow/models/taskinstance.py", line 1329, in _run_raw_task
    self._execute_task_with_callbacks(context)
  File "/home/airflow/.local/lib/python3.7/site-packages/airflow/models/taskinstance.py", line 1455, in _execute_task_with_callbacks
    result = self._execute_task(context, self.task)
  File "/home/airflow/.local/lib/python3.7/site-packages/airflow/models/taskinstance.py", line 1511, in _execute_task
    result = execute_callable(context=context)
  File "/home/airflow/.local/lib/python3.7/site-packages/airflow/operators/python.py", line 174, in execute
    return_value = self.execute_callable()
  File "/home/airflow/.local/lib/python3.7/site-packages/airflow/operators/python.py", line 185, in execute_callable
    return self.python_callable(*self.op_args, **self.op_kwargs)
  File "/opt/airflow/dags/data_ingestion_gcs_dag.py", line 47, in upload_to_gcs
    client = storage.Client()
  File "/home/airflow/.local/lib/python3.7/site-packages/google/cloud/storage/client.py", line 128, in __init__
    _http=_http,
  File "/home/airflow/.local/lib/python3.7/site-packages/google/cloud/client.py", line 318, in __init__
    _ClientProjectMixin.__init__(self, project=project, credentials=credentials)
  File "/home/airflow/.local/lib/python3.7/site-packages/google/cloud/client.py", line 266, in __init__
    project = self._determine_default(project)
  File "/home/airflow/.local/lib/python3.7/site-packages/google/cloud/client.py", line 285, in _determine_default
    return _determine_default_project(project)
  File "/home/airflow/.local/lib/python3.7/site-packages/google/cloud/_helpers.py", line 186, in _determine_default_project
    _, project = google.auth.default()
  File "/home/airflow/.local/lib/python3.7/site-packages/google/auth/_default.py", line 488, in default
    raise exceptions.DefaultCredentialsError(_HELP_MESSAGE)
google.auth.exceptions.DefaultCredentialsError: Could not automatically determine credentials. Please set GOOGLE_APPLICATION_CREDENTIALS or explicitly create credentials and re-run the application. For more information, please see https://cloud.google.com/docs/authentication/getting-started
[2022-01-30 15:22:58,945] {taskinstance.py:1277} INFO - Marking task as UP_FOR_RETRY. dag_id=data_ingestion_gcs_dag, task_id=local_to_gcs_task, execution_date=20220129T000000, start_date=20220130T152249, end_date=20220130T152258
[2022-01-30 15:22:58,964] {standard_task_runner.py:92} ERROR - Failed to execute job 31 for task local_to_gcs_task
Traceback (most recent call last):
  File "/home/airflow/.local/lib/python3.7/site-packages/airflow/task/task_runner/standard_task_runner.py", line 85, in _start_by_fork
    args.func(args, dag=self.dag)
  File "/home/airflow/.local/lib/python3.7/site-packages/airflow/cli/cli_parser.py", line 48, in command
    return func(*args, **kwargs)
  File "/home/airflow/.local/lib/python3.7/site-packages/airflow/utils/cli.py", line 92, in wrapper
    return f(*args, **kwargs)
  File "/home/airflow/.local/lib/python3.7/site-packages/airflow/cli/commands/task_command.py", line 298, in task_run
    _run_task_by_selected_method(args, dag, ti)
  File "/home/airflow/.local/lib/python3.7/site-packages/airflow/cli/commands/task_command.py", line 107, in _run_task_by_selected_method
    _run_raw_task(args, ti)
  File "/home/airflow/.local/lib/python3.7/site-packages/airflow/cli/commands/task_command.py", line 184, in _run_raw_task
    error_file=args.error_file,
  File "/home/airflow/.local/lib/python3.7/site-packages/airflow/utils/session.py", line 70, in wrapper
    return func(*args, session=session, **kwargs)
  File "/home/airflow/.local/lib/python3.7/site-packages/airflow/models/taskinstance.py", line 1329, in _run_raw_task
    self._execute_task_with_callbacks(context)
  File "/home/airflow/.local/lib/python3.7/site-packages/airflow/models/taskinstance.py", line 1455, in _execute_task_with_callbacks
    result = self._execute_task(context, self.task)
  File "/home/airflow/.local/lib/python3.7/site-packages/airflow/models/taskinstance.py", line 1511, in _execute_task
    result = execute_callable(context=context)
  File "/home/airflow/.local/lib/python3.7/site-packages/airflow/operators/python.py", line 174, in execute
    return_value = self.execute_callable()
  File "/home/airflow/.local/lib/python3.7/site-packages/airflow/operators/python.py", line 185, in execute_callable
    return self.python_callable(*self.op_args, **self.op_kwargs)
  File "/opt/airflow/dags/data_ingestion_gcs_dag.py", line 47, in upload_to_gcs
    client = storage.Client()
  File "/home/airflow/.local/lib/python3.7/site-packages/google/cloud/storage/client.py", line 128, in __init__
    _http=_http,
  File "/home/airflow/.local/lib/python3.7/site-packages/google/cloud/client.py", line 318, in __init__
    _ClientProjectMixin.__init__(self, project=project, credentials=credentials)
  File "/home/airflow/.local/lib/python3.7/site-packages/google/cloud/client.py", line 266, in __init__
    project = self._determine_default(project)
  File "/home/airflow/.local/lib/python3.7/site-packages/google/cloud/client.py", line 285, in _determine_default
    return _determine_default_project(project)
  File "/home/airflow/.local/lib/python3.7/site-packages/google/cloud/_helpers.py", line 186, in _determine_default_project
    _, project = google.auth.default()
  File "/home/airflow/.local/lib/python3.7/site-packages/google/auth/_default.py", line 488, in default
    raise exceptions.DefaultCredentialsError(_HELP_MESSAGE)
google.auth.exceptions.DefaultCredentialsError: Could not automatically determine credentials. Please set GOOGLE_APPLICATION_CREDENTIALS or explicitly create credentials and re-run the application. For more information, please see https://cloud.google.com/docs/authentication/getting-started
[2022-01-30 15:22:58,993] {local_task_job.py:154} INFO - Task exited with return code 1
[2022-01-30 15:22:59,033] {local_task_job.py:264} INFO - 0 downstream tasks scheduled from follow-on schedule check
[2022-01-30 17:31:51,661] {taskinstance.py:1032} INFO - Dependencies all met for <TaskInstance: data_ingestion_gcs_dag.local_to_gcs_task scheduled__2022-01-29T00:00:00+00:00 [queued]>
[2022-01-30 17:31:51,700] {taskinstance.py:1032} INFO - Dependencies all met for <TaskInstance: data_ingestion_gcs_dag.local_to_gcs_task scheduled__2022-01-29T00:00:00+00:00 [queued]>
[2022-01-30 17:31:51,700] {taskinstance.py:1238} INFO - 
--------------------------------------------------------------------------------
[2022-01-30 17:31:51,700] {taskinstance.py:1239} INFO - Starting attempt 1 of 2
[2022-01-30 17:31:51,700] {taskinstance.py:1240} INFO - 
--------------------------------------------------------------------------------
[2022-01-30 17:31:51,736] {taskinstance.py:1259} INFO - Executing <Task(PythonOperator): local_to_gcs_task> on 2022-01-29 00:00:00+00:00
[2022-01-30 17:31:51,744] {standard_task_runner.py:52} INFO - Started process 228 to run task
[2022-01-30 17:31:51,752] {standard_task_runner.py:76} INFO - Running: ['***', 'tasks', 'run', 'data_ingestion_gcs_dag', 'local_to_gcs_task', 'scheduled__2022-01-29T00:00:00+00:00', '--job-id', '5', '--raw', '--subdir', 'DAGS_FOLDER/data_ingestion_gcs_dag.py', '--cfg-path', '/tmp/tmpeln1reej', '--error-file', '/tmp/tmpxuk0oqgy']
[2022-01-30 17:31:51,753] {standard_task_runner.py:77} INFO - Job 5: Subtask local_to_gcs_task
[2022-01-30 17:31:51,836] {logging_mixin.py:109} INFO - Running <TaskInstance: data_ingestion_gcs_dag.local_to_gcs_task scheduled__2022-01-29T00:00:00+00:00 [running]> on host 4d230e568692
[2022-01-30 17:31:51,927] {taskinstance.py:1426} INFO - Exporting the following env vars:
AIRFLOW_CTX_DAG_OWNER=***
AIRFLOW_CTX_DAG_ID=data_ingestion_gcs_dag
AIRFLOW_CTX_TASK_ID=local_to_gcs_task
AIRFLOW_CTX_EXECUTION_DATE=2022-01-29T00:00:00+00:00
AIRFLOW_CTX_DAG_RUN_ID=scheduled__2022-01-29T00:00:00+00:00
[2022-01-30 17:31:55,070] {python.py:175} INFO - Done. Returned value was: None
[2022-01-30 17:31:55,082] {taskinstance.py:1277} INFO - Marking task as SUCCESS. dag_id=data_ingestion_gcs_dag, task_id=local_to_gcs_task, execution_date=20220129T000000, start_date=20220130T173151, end_date=20220130T173155
[2022-01-30 17:31:55,134] {local_task_job.py:154} INFO - Task exited with return code 0
[2022-01-30 17:31:55,190] {local_task_job.py:264} INFO - 1 downstream tasks scheduled from follow-on schedule check
