[2022-02-19 23:37:42,162] {taskinstance.py:1032} INFO - Dependencies all met for <TaskInstance: fhv_gcs_dag.download_dataset_task scheduled__2019-03-02T00:00:00+00:00 [queued]>
[2022-02-19 23:37:42,943] {taskinstance.py:1032} INFO - Dependencies all met for <TaskInstance: fhv_gcs_dag.download_dataset_task scheduled__2019-03-02T00:00:00+00:00 [queued]>
[2022-02-19 23:37:42,944] {taskinstance.py:1238} INFO - 
--------------------------------------------------------------------------------
[2022-02-19 23:37:42,944] {taskinstance.py:1239} INFO - Starting attempt 2 of 2
[2022-02-19 23:37:42,944] {taskinstance.py:1240} INFO - 
--------------------------------------------------------------------------------
[2022-02-19 23:37:43,013] {taskinstance.py:1259} INFO - Executing <Task(BashOperator): download_dataset_task> on 2019-03-02 00:00:00+00:00
[2022-02-19 23:37:43,056] {standard_task_runner.py:52} INFO - Started process 301 to run task
[2022-02-19 23:37:43,088] {standard_task_runner.py:76} INFO - Running: ['***', 'tasks', 'run', 'fhv_gcs_dag', 'download_dataset_task', 'scheduled__2019-03-02T00:00:00+00:00', '--job-id', '222', '--raw', '--subdir', 'DAGS_FOLDER/fhv_gcs_dag.py', '--cfg-path', '/tmp/tmptl0lw59t', '--error-file', '/tmp/tmpbvzop6ld']
[2022-02-19 23:37:43,135] {standard_task_runner.py:77} INFO - Job 222: Subtask download_dataset_task
[2022-02-19 23:37:43,534] {logging_mixin.py:109} INFO - Running <TaskInstance: fhv_gcs_dag.download_dataset_task scheduled__2019-03-02T00:00:00+00:00 [running]> on host 812dd7ecce85
[2022-02-19 23:37:44,436] {warnings.py:110} WARNING - /home/***/.local/lib/python3.7/site-packages/***/utils/context.py:152: AirflowContextDeprecationWarning: Accessing 'execution_date' from the template is deprecated and will be removed in a future version. Please use 'data_interval_start' or 'logical_date' instead.
  warnings.warn(_create_deprecation_warning(key, self._deprecation_replacements[key]))

[2022-02-19 23:37:44,791] {taskinstance.py:1426} INFO - Exporting the following env vars:
AIRFLOW_CTX_DAG_OWNER=***
AIRFLOW_CTX_DAG_ID=fhv_gcs_dag
AIRFLOW_CTX_TASK_ID=download_dataset_task
AIRFLOW_CTX_EXECUTION_DATE=2019-03-02T00:00:00+00:00
AIRFLOW_CTX_DAG_RUN_ID=scheduled__2019-03-02T00:00:00+00:00
[2022-02-19 23:37:44,792] {subprocess.py:62} INFO - Tmp dir root location: 
 /tmp
[2022-02-19 23:37:44,810] {subprocess.py:74} INFO - Running command: ['bash', '-c', 'curl -sS https://nyc-tlc.s3.amazonaws.com/trip+data/fhv_tripdata_2019-03.csv > /opt/***/output_2019-03.csv']
[2022-02-19 23:37:45,158] {subprocess.py:85} INFO - Output:
[2022-02-19 23:38:16,126] {subprocess.py:93} INFO - Command exited with return code 0
[2022-02-19 23:38:16,689] {taskinstance.py:1277} INFO - Marking task as SUCCESS. dag_id=fhv_gcs_dag, task_id=download_dataset_task, execution_date=20190302T000000, start_date=20220219T233742, end_date=20220219T233816
[2022-02-19 23:38:16,770] {local_task_job.py:154} INFO - Task exited with return code 0
[2022-02-19 23:38:16,888] {local_task_job.py:264} INFO - 1 downstream tasks scheduled from follow-on schedule check
[2022-02-23 19:12:25,765] {taskinstance.py:1032} INFO - Dependencies all met for <TaskInstance: fhv_gcs_dag.download_dataset_task scheduled__2019-03-02T00:00:00+00:00 [queued]>
[2022-02-23 19:12:25,790] {taskinstance.py:1032} INFO - Dependencies all met for <TaskInstance: fhv_gcs_dag.download_dataset_task scheduled__2019-03-02T00:00:00+00:00 [queued]>
[2022-02-23 19:12:25,791] {taskinstance.py:1238} INFO - 
--------------------------------------------------------------------------------
[2022-02-23 19:12:25,791] {taskinstance.py:1239} INFO - Starting attempt 2 of 3
[2022-02-23 19:12:25,791] {taskinstance.py:1240} INFO - 
--------------------------------------------------------------------------------
[2022-02-23 19:12:25,817] {taskinstance.py:1259} INFO - Executing <Task(BashOperator): download_dataset_task> on 2019-03-02 00:00:00+00:00
[2022-02-23 19:12:25,826] {standard_task_runner.py:52} INFO - Started process 284 to run task
[2022-02-23 19:12:25,836] {standard_task_runner.py:76} INFO - Running: ['***', 'tasks', 'run', 'fhv_gcs_dag', 'download_dataset_task', 'scheduled__2019-03-02T00:00:00+00:00', '--job-id', '617', '--raw', '--subdir', 'DAGS_FOLDER/fhv_gcs_dag.py', '--cfg-path', '/tmp/tmp2i2me36s', '--error-file', '/tmp/tmp1f95hj_5']
[2022-02-23 19:12:25,838] {standard_task_runner.py:77} INFO - Job 617: Subtask download_dataset_task
[2022-02-23 19:12:25,979] {logging_mixin.py:109} INFO - Running <TaskInstance: fhv_gcs_dag.download_dataset_task scheduled__2019-03-02T00:00:00+00:00 [running]> on host 4709b9a36f03
[2022-02-23 19:12:26,098] {warnings.py:110} WARNING - /home/***/.local/lib/python3.7/site-packages/***/utils/context.py:152: AirflowContextDeprecationWarning: Accessing 'execution_date' from the template is deprecated and will be removed in a future version. Please use 'data_interval_start' or 'logical_date' instead.
  warnings.warn(_create_deprecation_warning(key, self._deprecation_replacements[key]))

[2022-02-23 19:12:26,155] {taskinstance.py:1426} INFO - Exporting the following env vars:
AIRFLOW_CTX_DAG_OWNER=***
AIRFLOW_CTX_DAG_ID=fhv_gcs_dag
AIRFLOW_CTX_TASK_ID=download_dataset_task
AIRFLOW_CTX_EXECUTION_DATE=2019-03-02T00:00:00+00:00
AIRFLOW_CTX_DAG_RUN_ID=scheduled__2019-03-02T00:00:00+00:00
[2022-02-23 19:12:26,157] {subprocess.py:62} INFO - Tmp dir root location: 
 /tmp
[2022-02-23 19:12:26,158] {subprocess.py:74} INFO - Running command: ['bash', '-c', 'curl -sS https://nyc-tlc.s3.amazonaws.com/trip+data/fhv_tripdata_2019-03.csv > /opt/***/output_2019-03.csv']
[2022-02-23 19:12:26,177] {subprocess.py:85} INFO - Output:
[2022-02-23 19:12:46,312] {subprocess.py:89} INFO - curl: (6) Could not resolve host: nyc-tlc.s3.amazonaws.com
[2022-02-23 19:12:46,325] {subprocess.py:93} INFO - Command exited with return code 6
[2022-02-23 19:12:46,359] {taskinstance.py:1700} ERROR - Task failed with exception
Traceback (most recent call last):
  File "/home/airflow/.local/lib/python3.7/site-packages/airflow/models/taskinstance.py", line 1329, in _run_raw_task
    self._execute_task_with_callbacks(context)
  File "/home/airflow/.local/lib/python3.7/site-packages/airflow/models/taskinstance.py", line 1455, in _execute_task_with_callbacks
    result = self._execute_task(context, self.task)
  File "/home/airflow/.local/lib/python3.7/site-packages/airflow/models/taskinstance.py", line 1511, in _execute_task
    result = execute_callable(context=context)
  File "/home/airflow/.local/lib/python3.7/site-packages/airflow/operators/bash.py", line 188, in execute
    f'Bash command failed. The command returned a non-zero exit code {result.exit_code}.'
airflow.exceptions.AirflowException: Bash command failed. The command returned a non-zero exit code 6.
[2022-02-23 19:12:46,382] {taskinstance.py:1277} INFO - Marking task as UP_FOR_RETRY. dag_id=fhv_gcs_dag, task_id=download_dataset_task, execution_date=20190302T000000, start_date=20220223T191225, end_date=20220223T191246
[2022-02-23 19:12:46,408] {standard_task_runner.py:92} ERROR - Failed to execute job 617 for task download_dataset_task
Traceback (most recent call last):
  File "/home/airflow/.local/lib/python3.7/site-packages/airflow/task/task_runner/standard_task_runner.py", line 85, in _start_by_fork
    args.func(args, dag=self.dag)
  File "/home/airflow/.local/lib/python3.7/site-packages/airflow/cli/cli_parser.py", line 48, in command
    return func(*args, **kwargs)
  File "/home/airflow/.local/lib/python3.7/site-packages/airflow/utils/cli.py", line 92, in wrapper
    return f(*args, **kwargs)
  File "/home/airflow/.local/lib/python3.7/site-packages/airflow/cli/commands/task_command.py", line 298, in task_run
    _run_task_by_selected_method(args, dag, ti)
  File "/home/airflow/.local/lib/python3.7/site-packages/airflow/cli/commands/task_command.py", line 107, in _run_task_by_selected_method
    _run_raw_task(args, ti)
  File "/home/airflow/.local/lib/python3.7/site-packages/airflow/cli/commands/task_command.py", line 184, in _run_raw_task
    error_file=args.error_file,
  File "/home/airflow/.local/lib/python3.7/site-packages/airflow/utils/session.py", line 70, in wrapper
    return func(*args, session=session, **kwargs)
  File "/home/airflow/.local/lib/python3.7/site-packages/airflow/models/taskinstance.py", line 1329, in _run_raw_task
    self._execute_task_with_callbacks(context)
  File "/home/airflow/.local/lib/python3.7/site-packages/airflow/models/taskinstance.py", line 1455, in _execute_task_with_callbacks
    result = self._execute_task(context, self.task)
  File "/home/airflow/.local/lib/python3.7/site-packages/airflow/models/taskinstance.py", line 1511, in _execute_task
    result = execute_callable(context=context)
  File "/home/airflow/.local/lib/python3.7/site-packages/airflow/operators/bash.py", line 188, in execute
    f'Bash command failed. The command returned a non-zero exit code {result.exit_code}.'
airflow.exceptions.AirflowException: Bash command failed. The command returned a non-zero exit code 6.
[2022-02-23 19:12:46,437] {local_task_job.py:154} INFO - Task exited with return code 1
[2022-02-23 19:12:46,499] {local_task_job.py:264} INFO - 0 downstream tasks scheduled from follow-on schedule check
