[2022-02-19 23:37:44,347] {taskinstance.py:1032} INFO - Dependencies all met for <TaskInstance: fhv_gcs_dag.download_dataset_task scheduled__2019-02-02T00:00:00+00:00 [queued]>
[2022-02-19 23:37:44,365] {taskinstance.py:1032} INFO - Dependencies all met for <TaskInstance: fhv_gcs_dag.download_dataset_task scheduled__2019-02-02T00:00:00+00:00 [queued]>
[2022-02-19 23:37:44,365] {taskinstance.py:1238} INFO - 
--------------------------------------------------------------------------------
[2022-02-19 23:37:44,365] {taskinstance.py:1239} INFO - Starting attempt 2 of 2
[2022-02-19 23:37:44,365] {taskinstance.py:1240} INFO - 
--------------------------------------------------------------------------------
[2022-02-19 23:37:44,406] {taskinstance.py:1259} INFO - Executing <Task(BashOperator): download_dataset_task> on 2019-02-02 00:00:00+00:00
[2022-02-19 23:37:44,525] {standard_task_runner.py:52} INFO - Started process 303 to run task
[2022-02-19 23:37:44,641] {standard_task_runner.py:76} INFO - Running: ['***', 'tasks', 'run', 'fhv_gcs_dag', 'download_dataset_task', 'scheduled__2019-02-02T00:00:00+00:00', '--job-id', '225', '--raw', '--subdir', 'DAGS_FOLDER/fhv_gcs_dag.py', '--cfg-path', '/tmp/tmpvokerdet', '--error-file', '/tmp/tmpxkms5b5g']
[2022-02-19 23:37:44,642] {standard_task_runner.py:77} INFO - Job 225: Subtask download_dataset_task
[2022-02-19 23:37:45,017] {logging_mixin.py:109} INFO - Running <TaskInstance: fhv_gcs_dag.download_dataset_task scheduled__2019-02-02T00:00:00+00:00 [running]> on host 812dd7ecce85
[2022-02-19 23:37:45,336] {warnings.py:110} WARNING - /home/***/.local/lib/python3.7/site-packages/***/utils/context.py:152: AirflowContextDeprecationWarning: Accessing 'execution_date' from the template is deprecated and will be removed in a future version. Please use 'data_interval_start' or 'logical_date' instead.
  warnings.warn(_create_deprecation_warning(key, self._deprecation_replacements[key]))

[2022-02-19 23:37:45,519] {taskinstance.py:1426} INFO - Exporting the following env vars:
AIRFLOW_CTX_DAG_OWNER=***
AIRFLOW_CTX_DAG_ID=fhv_gcs_dag
AIRFLOW_CTX_TASK_ID=download_dataset_task
AIRFLOW_CTX_EXECUTION_DATE=2019-02-02T00:00:00+00:00
AIRFLOW_CTX_DAG_RUN_ID=scheduled__2019-02-02T00:00:00+00:00
[2022-02-19 23:37:45,520] {subprocess.py:62} INFO - Tmp dir root location: 
 /tmp
[2022-02-19 23:37:45,521] {subprocess.py:74} INFO - Running command: ['bash', '-c', 'curl -sS https://nyc-tlc.s3.amazonaws.com/trip+data/fhv_tripdata_2019-02.csv > /opt/***/output_2019-02.csv']
[2022-02-19 23:37:45,631] {subprocess.py:85} INFO - Output:
[2022-02-19 23:38:28,167] {subprocess.py:93} INFO - Command exited with return code 0
[2022-02-19 23:38:28,252] {taskinstance.py:1277} INFO - Marking task as SUCCESS. dag_id=fhv_gcs_dag, task_id=download_dataset_task, execution_date=20190202T000000, start_date=20220219T233744, end_date=20220219T233828
[2022-02-19 23:38:28,357] {local_task_job.py:154} INFO - Task exited with return code 0
[2022-02-19 23:38:28,437] {local_task_job.py:264} INFO - 1 downstream tasks scheduled from follow-on schedule check
[2022-02-23 19:12:19,784] {taskinstance.py:1032} INFO - Dependencies all met for <TaskInstance: fhv_gcs_dag.download_dataset_task scheduled__2019-02-02T00:00:00+00:00 [queued]>
[2022-02-23 19:12:19,808] {taskinstance.py:1032} INFO - Dependencies all met for <TaskInstance: fhv_gcs_dag.download_dataset_task scheduled__2019-02-02T00:00:00+00:00 [queued]>
[2022-02-23 19:12:19,808] {taskinstance.py:1238} INFO - 
--------------------------------------------------------------------------------
[2022-02-23 19:12:19,808] {taskinstance.py:1239} INFO - Starting attempt 2 of 3
[2022-02-23 19:12:19,809] {taskinstance.py:1240} INFO - 
--------------------------------------------------------------------------------
[2022-02-23 19:12:19,829] {taskinstance.py:1259} INFO - Executing <Task(BashOperator): download_dataset_task> on 2019-02-02 00:00:00+00:00
[2022-02-23 19:12:19,836] {standard_task_runner.py:52} INFO - Started process 269 to run task
[2022-02-23 19:12:19,840] {standard_task_runner.py:76} INFO - Running: ['***', 'tasks', 'run', 'fhv_gcs_dag', 'download_dataset_task', 'scheduled__2019-02-02T00:00:00+00:00', '--job-id', '616', '--raw', '--subdir', 'DAGS_FOLDER/fhv_gcs_dag.py', '--cfg-path', '/tmp/tmpitauoiei', '--error-file', '/tmp/tmpfhbu_ke0']
[2022-02-23 19:12:19,842] {standard_task_runner.py:77} INFO - Job 616: Subtask download_dataset_task
[2022-02-23 19:12:19,909] {logging_mixin.py:109} INFO - Running <TaskInstance: fhv_gcs_dag.download_dataset_task scheduled__2019-02-02T00:00:00+00:00 [running]> on host 4709b9a36f03
[2022-02-23 19:12:19,955] {warnings.py:110} WARNING - /home/***/.local/lib/python3.7/site-packages/***/utils/context.py:152: AirflowContextDeprecationWarning: Accessing 'execution_date' from the template is deprecated and will be removed in a future version. Please use 'data_interval_start' or 'logical_date' instead.
  warnings.warn(_create_deprecation_warning(key, self._deprecation_replacements[key]))

[2022-02-23 19:12:19,974] {taskinstance.py:1426} INFO - Exporting the following env vars:
AIRFLOW_CTX_DAG_OWNER=***
AIRFLOW_CTX_DAG_ID=fhv_gcs_dag
AIRFLOW_CTX_TASK_ID=download_dataset_task
AIRFLOW_CTX_EXECUTION_DATE=2019-02-02T00:00:00+00:00
AIRFLOW_CTX_DAG_RUN_ID=scheduled__2019-02-02T00:00:00+00:00
[2022-02-23 19:12:19,975] {subprocess.py:62} INFO - Tmp dir root location: 
 /tmp
[2022-02-23 19:12:19,976] {subprocess.py:74} INFO - Running command: ['bash', '-c', 'curl -sS https://nyc-tlc.s3.amazonaws.com/trip+data/fhv_tripdata_2019-02.csv > /opt/***/output_2019-02.csv']
[2022-02-23 19:12:19,990] {subprocess.py:85} INFO - Output:
[2022-02-23 19:12:40,128] {subprocess.py:89} INFO - curl: (6) Could not resolve host: nyc-tlc.s3.amazonaws.com
[2022-02-23 19:12:40,129] {subprocess.py:93} INFO - Command exited with return code 6
[2022-02-23 19:12:40,146] {taskinstance.py:1700} ERROR - Task failed with exception
Traceback (most recent call last):
  File "/home/airflow/.local/lib/python3.7/site-packages/airflow/models/taskinstance.py", line 1329, in _run_raw_task
    self._execute_task_with_callbacks(context)
  File "/home/airflow/.local/lib/python3.7/site-packages/airflow/models/taskinstance.py", line 1455, in _execute_task_with_callbacks
    result = self._execute_task(context, self.task)
  File "/home/airflow/.local/lib/python3.7/site-packages/airflow/models/taskinstance.py", line 1511, in _execute_task
    result = execute_callable(context=context)
  File "/home/airflow/.local/lib/python3.7/site-packages/airflow/operators/bash.py", line 188, in execute
    f'Bash command failed. The command returned a non-zero exit code {result.exit_code}.'
airflow.exceptions.AirflowException: Bash command failed. The command returned a non-zero exit code 6.
[2022-02-23 19:12:40,157] {taskinstance.py:1277} INFO - Marking task as UP_FOR_RETRY. dag_id=fhv_gcs_dag, task_id=download_dataset_task, execution_date=20190202T000000, start_date=20220223T191219, end_date=20220223T191240
[2022-02-23 19:12:40,178] {standard_task_runner.py:92} ERROR - Failed to execute job 616 for task download_dataset_task
Traceback (most recent call last):
  File "/home/airflow/.local/lib/python3.7/site-packages/airflow/task/task_runner/standard_task_runner.py", line 85, in _start_by_fork
    args.func(args, dag=self.dag)
  File "/home/airflow/.local/lib/python3.7/site-packages/airflow/cli/cli_parser.py", line 48, in command
    return func(*args, **kwargs)
  File "/home/airflow/.local/lib/python3.7/site-packages/airflow/utils/cli.py", line 92, in wrapper
    return f(*args, **kwargs)
  File "/home/airflow/.local/lib/python3.7/site-packages/airflow/cli/commands/task_command.py", line 298, in task_run
    _run_task_by_selected_method(args, dag, ti)
  File "/home/airflow/.local/lib/python3.7/site-packages/airflow/cli/commands/task_command.py", line 107, in _run_task_by_selected_method
    _run_raw_task(args, ti)
  File "/home/airflow/.local/lib/python3.7/site-packages/airflow/cli/commands/task_command.py", line 184, in _run_raw_task
    error_file=args.error_file,
  File "/home/airflow/.local/lib/python3.7/site-packages/airflow/utils/session.py", line 70, in wrapper
    return func(*args, session=session, **kwargs)
  File "/home/airflow/.local/lib/python3.7/site-packages/airflow/models/taskinstance.py", line 1329, in _run_raw_task
    self._execute_task_with_callbacks(context)
  File "/home/airflow/.local/lib/python3.7/site-packages/airflow/models/taskinstance.py", line 1455, in _execute_task_with_callbacks
    result = self._execute_task(context, self.task)
  File "/home/airflow/.local/lib/python3.7/site-packages/airflow/models/taskinstance.py", line 1511, in _execute_task
    result = execute_callable(context=context)
  File "/home/airflow/.local/lib/python3.7/site-packages/airflow/operators/bash.py", line 188, in execute
    f'Bash command failed. The command returned a non-zero exit code {result.exit_code}.'
airflow.exceptions.AirflowException: Bash command failed. The command returned a non-zero exit code 6.
[2022-02-23 19:12:40,192] {local_task_job.py:154} INFO - Task exited with return code 1
[2022-02-23 19:12:40,241] {local_task_job.py:264} INFO - 0 downstream tasks scheduled from follow-on schedule check
