[2022-02-03 18:14:32,517] {taskinstance.py:1032} INFO - Dependencies all met for <TaskInstance: fhv_gcs_dag.local_to_gcs_task scheduled__2019-03-02T00:00:00+00:00 [queued]>
[2022-02-03 18:14:32,541] {taskinstance.py:1032} INFO - Dependencies all met for <TaskInstance: fhv_gcs_dag.local_to_gcs_task scheduled__2019-03-02T00:00:00+00:00 [queued]>
[2022-02-03 18:14:32,541] {taskinstance.py:1238} INFO - 
--------------------------------------------------------------------------------
[2022-02-03 18:14:32,541] {taskinstance.py:1239} INFO - Starting attempt 1 of 2
[2022-02-03 18:14:32,541] {taskinstance.py:1240} INFO - 
--------------------------------------------------------------------------------
[2022-02-03 18:14:32,575] {taskinstance.py:1259} INFO - Executing <Task(PythonOperator): local_to_gcs_task> on 2019-03-02 00:00:00+00:00
[2022-02-03 18:14:32,585] {standard_task_runner.py:52} INFO - Started process 893 to run task
[2022-02-03 18:14:32,596] {standard_task_runner.py:76} INFO - Running: ['***', 'tasks', 'run', 'fhv_gcs_dag', 'local_to_gcs_task', 'scheduled__2019-03-02T00:00:00+00:00', '--job-id', '156', '--raw', '--subdir', 'DAGS_FOLDER/fhv_gcs_dag.py', '--cfg-path', '/tmp/tmp_kprq_qg', '--error-file', '/tmp/tmp2csght7l']
[2022-02-03 18:14:32,598] {standard_task_runner.py:77} INFO - Job 156: Subtask local_to_gcs_task
[2022-02-03 18:14:32,773] {logging_mixin.py:109} INFO - Running <TaskInstance: fhv_gcs_dag.local_to_gcs_task scheduled__2019-03-02T00:00:00+00:00 [running]> on host bd2f56b76e32
[2022-02-03 18:14:32,918] {warnings.py:110} WARNING - /home/***/.local/lib/python3.7/site-packages/***/utils/context.py:152: AirflowContextDeprecationWarning: Accessing 'execution_date' from the template is deprecated and will be removed in a future version. Please use 'data_interval_start' or 'logical_date' instead.
  warnings.warn(_create_deprecation_warning(key, self._deprecation_replacements[key]))

[2022-02-03 18:14:32,958] {taskinstance.py:1426} INFO - Exporting the following env vars:
AIRFLOW_CTX_DAG_OWNER=***
AIRFLOW_CTX_DAG_ID=fhv_gcs_dag
AIRFLOW_CTX_TASK_ID=local_to_gcs_task
AIRFLOW_CTX_EXECUTION_DATE=2019-03-02T00:00:00+00:00
AIRFLOW_CTX_DAG_RUN_ID=scheduled__2019-03-02T00:00:00+00:00
[2022-02-03 18:14:34,796] {python.py:175} INFO - Done. Returned value was: None
[2022-02-03 18:14:34,841] {taskinstance.py:1277} INFO - Marking task as SUCCESS. dag_id=fhv_gcs_dag, task_id=local_to_gcs_task, execution_date=20190302T000000, start_date=20220203T181432, end_date=20220203T181434
[2022-02-03 18:14:34,926] {local_task_job.py:154} INFO - Task exited with return code 0
[2022-02-03 18:14:35,064] {local_task_job.py:264} INFO - 1 downstream tasks scheduled from follow-on schedule check
<<<<<<< HEAD
[2022-02-23 19:18:09,684] {taskinstance.py:1032} INFO - Dependencies all met for <TaskInstance: fhv_gcs_dag.local_to_gcs_task scheduled__2019-03-02T00:00:00+00:00 [queued]>
[2022-02-23 19:18:09,702] {taskinstance.py:1032} INFO - Dependencies all met for <TaskInstance: fhv_gcs_dag.local_to_gcs_task scheduled__2019-03-02T00:00:00+00:00 [queued]>
[2022-02-23 19:18:09,703] {taskinstance.py:1238} INFO - 
--------------------------------------------------------------------------------
[2022-02-23 19:18:09,703] {taskinstance.py:1239} INFO - Starting attempt 1 of 2
[2022-02-23 19:18:09,703] {taskinstance.py:1240} INFO - 
--------------------------------------------------------------------------------
[2022-02-23 19:18:09,728] {taskinstance.py:1259} INFO - Executing <Task(PythonOperator): local_to_gcs_task> on 2019-03-02 00:00:00+00:00
[2022-02-23 19:18:09,758] {standard_task_runner.py:76} INFO - Running: ['***', 'tasks', 'run', 'fhv_gcs_dag', 'local_to_gcs_task', 'scheduled__2019-03-02T00:00:00+00:00', '--job-id', '624', '--raw', '--subdir', 'DAGS_FOLDER/fhv_gcs_dag.py', '--cfg-path', '/tmp/tmp8w5g_02m', '--error-file', '/tmp/tmpixb6cw19']
[2022-02-23 19:18:09,759] {standard_task_runner.py:77} INFO - Job 624: Subtask local_to_gcs_task
[2022-02-23 19:18:09,755] {standard_task_runner.py:52} INFO - Started process 114 to run task
[2022-02-23 19:18:09,868] {logging_mixin.py:109} INFO - Running <TaskInstance: fhv_gcs_dag.local_to_gcs_task scheduled__2019-03-02T00:00:00+00:00 [running]> on host 537c9393f0b3
[2022-02-23 19:18:09,922] {warnings.py:110} WARNING - /home/***/.local/lib/python3.7/site-packages/***/utils/context.py:152: AirflowContextDeprecationWarning: Accessing 'execution_date' from the template is deprecated and will be removed in a future version. Please use 'data_interval_start' or 'logical_date' instead.
  warnings.warn(_create_deprecation_warning(key, self._deprecation_replacements[key]))

[2022-02-23 19:18:09,952] {taskinstance.py:1426} INFO - Exporting the following env vars:
AIRFLOW_CTX_DAG_OWNER=***
AIRFLOW_CTX_DAG_ID=fhv_gcs_dag
AIRFLOW_CTX_TASK_ID=local_to_gcs_task
AIRFLOW_CTX_EXECUTION_DATE=2019-03-02T00:00:00+00:00
AIRFLOW_CTX_DAG_RUN_ID=scheduled__2019-03-02T00:00:00+00:00
[2022-02-23 19:18:10,060] {taskinstance.py:1700} ERROR - Task failed with exception
Traceback (most recent call last):
  File "/home/airflow/.local/lib/python3.7/site-packages/airflow/models/taskinstance.py", line 1329, in _run_raw_task
    self._execute_task_with_callbacks(context)
  File "/home/airflow/.local/lib/python3.7/site-packages/airflow/models/taskinstance.py", line 1455, in _execute_task_with_callbacks
    result = self._execute_task(context, self.task)
  File "/home/airflow/.local/lib/python3.7/site-packages/airflow/models/taskinstance.py", line 1511, in _execute_task
    result = execute_callable(context=context)
  File "/home/airflow/.local/lib/python3.7/site-packages/airflow/operators/python.py", line 174, in execute
    return_value = self.execute_callable()
  File "/home/airflow/.local/lib/python3.7/site-packages/airflow/operators/python.py", line 185, in execute_callable
    return self.python_callable(*self.op_args, **self.op_kwargs)
  File "/opt/airflow/dags/fhv_gcs_dag.py", line 49, in upload_to_gcs
    blob.upload_from_filename(local_file)
  File "/home/airflow/.local/lib/python3.7/site-packages/google/cloud/storage/blob.py", line 2735, in upload_from_filename
    retry=retry,
  File "/home/airflow/.local/lib/python3.7/site-packages/google/cloud/storage/blob.py", line 2594, in upload_from_file
    retry=retry,
  File "/home/airflow/.local/lib/python3.7/site-packages/google/cloud/storage/blob.py", line 2412, in _do_upload
    retry=retry,
  File "/home/airflow/.local/lib/python3.7/site-packages/google/cloud/storage/blob.py", line 2237, in _do_resumable_upload
    retry=retry,
  File "/home/airflow/.local/lib/python3.7/site-packages/google/cloud/storage/blob.py", line 2112, in _initiate_resumable_upload
    timeout=timeout,
  File "/home/airflow/.local/lib/python3.7/site-packages/google/resumable_media/requests/upload.py", line 421, in initiate
    retriable_request, self._get_status_code, self._retry_strategy
  File "/home/airflow/.local/lib/python3.7/site-packages/google/resumable_media/requests/_request_helpers.py", line 147, in wait_and_retry
    response = func()
  File "/home/airflow/.local/lib/python3.7/site-packages/google/resumable_media/requests/upload.py", line 413, in retriable_request
    method, url, data=payload, headers=headers, timeout=timeout
  File "/home/airflow/.local/lib/python3.7/site-packages/google/auth/transport/requests.py", line 476, in request
    self.credentials.before_request(auth_request, method, url, request_headers)
  File "/home/airflow/.local/lib/python3.7/site-packages/google/auth/credentials.py", line 133, in before_request
    self.refresh(request)
  File "/home/airflow/.local/lib/python3.7/site-packages/google/oauth2/service_account.py", line 409, in refresh
    request, self._token_uri, assertion
  File "/home/airflow/.local/lib/python3.7/site-packages/google/oauth2/_client.py", line 193, in jwt_grant
    response_data = _token_endpoint_request(request, token_uri, body)
  File "/home/airflow/.local/lib/python3.7/site-packages/google/oauth2/_client.py", line 165, in _token_endpoint_request
    _handle_error_response(response_data)
  File "/home/airflow/.local/lib/python3.7/site-packages/google/oauth2/_client.py", line 60, in _handle_error_response
    raise exceptions.RefreshError(error_details, response_data)
google.auth.exceptions.RefreshError: ('invalid_grant: Invalid grant: account not found', {'error': 'invalid_grant', 'error_description': 'Invalid grant: account not found'})
[2022-02-23 19:18:10,080] {taskinstance.py:1277} INFO - Marking task as UP_FOR_RETRY. dag_id=fhv_gcs_dag, task_id=local_to_gcs_task, execution_date=20190302T000000, start_date=20220223T191809, end_date=20220223T191810
[2022-02-23 19:18:10,100] {standard_task_runner.py:92} ERROR - Failed to execute job 624 for task local_to_gcs_task
Traceback (most recent call last):
  File "/home/airflow/.local/lib/python3.7/site-packages/airflow/task/task_runner/standard_task_runner.py", line 85, in _start_by_fork
    args.func(args, dag=self.dag)
  File "/home/airflow/.local/lib/python3.7/site-packages/airflow/cli/cli_parser.py", line 48, in command
    return func(*args, **kwargs)
  File "/home/airflow/.local/lib/python3.7/site-packages/airflow/utils/cli.py", line 92, in wrapper
    return f(*args, **kwargs)
  File "/home/airflow/.local/lib/python3.7/site-packages/airflow/cli/commands/task_command.py", line 298, in task_run
    _run_task_by_selected_method(args, dag, ti)
  File "/home/airflow/.local/lib/python3.7/site-packages/airflow/cli/commands/task_command.py", line 107, in _run_task_by_selected_method
    _run_raw_task(args, ti)
  File "/home/airflow/.local/lib/python3.7/site-packages/airflow/cli/commands/task_command.py", line 184, in _run_raw_task
    error_file=args.error_file,
  File "/home/airflow/.local/lib/python3.7/site-packages/airflow/utils/session.py", line 70, in wrapper
    return func(*args, session=session, **kwargs)
  File "/home/airflow/.local/lib/python3.7/site-packages/airflow/models/taskinstance.py", line 1329, in _run_raw_task
    self._execute_task_with_callbacks(context)
  File "/home/airflow/.local/lib/python3.7/site-packages/airflow/models/taskinstance.py", line 1455, in _execute_task_with_callbacks
    result = self._execute_task(context, self.task)
  File "/home/airflow/.local/lib/python3.7/site-packages/airflow/models/taskinstance.py", line 1511, in _execute_task
    result = execute_callable(context=context)
  File "/home/airflow/.local/lib/python3.7/site-packages/airflow/operators/python.py", line 174, in execute
    return_value = self.execute_callable()
  File "/home/airflow/.local/lib/python3.7/site-packages/airflow/operators/python.py", line 185, in execute_callable
    return self.python_callable(*self.op_args, **self.op_kwargs)
  File "/opt/airflow/dags/fhv_gcs_dag.py", line 49, in upload_to_gcs
    blob.upload_from_filename(local_file)
  File "/home/airflow/.local/lib/python3.7/site-packages/google/cloud/storage/blob.py", line 2735, in upload_from_filename
    retry=retry,
  File "/home/airflow/.local/lib/python3.7/site-packages/google/cloud/storage/blob.py", line 2594, in upload_from_file
    retry=retry,
  File "/home/airflow/.local/lib/python3.7/site-packages/google/cloud/storage/blob.py", line 2412, in _do_upload
    retry=retry,
  File "/home/airflow/.local/lib/python3.7/site-packages/google/cloud/storage/blob.py", line 2237, in _do_resumable_upload
    retry=retry,
  File "/home/airflow/.local/lib/python3.7/site-packages/google/cloud/storage/blob.py", line 2112, in _initiate_resumable_upload
    timeout=timeout,
  File "/home/airflow/.local/lib/python3.7/site-packages/google/resumable_media/requests/upload.py", line 421, in initiate
    retriable_request, self._get_status_code, self._retry_strategy
  File "/home/airflow/.local/lib/python3.7/site-packages/google/resumable_media/requests/_request_helpers.py", line 147, in wait_and_retry
    response = func()
  File "/home/airflow/.local/lib/python3.7/site-packages/google/resumable_media/requests/upload.py", line 413, in retriable_request
    method, url, data=payload, headers=headers, timeout=timeout
  File "/home/airflow/.local/lib/python3.7/site-packages/google/auth/transport/requests.py", line 476, in request
    self.credentials.before_request(auth_request, method, url, request_headers)
  File "/home/airflow/.local/lib/python3.7/site-packages/google/auth/credentials.py", line 133, in before_request
    self.refresh(request)
  File "/home/airflow/.local/lib/python3.7/site-packages/google/oauth2/service_account.py", line 409, in refresh
    request, self._token_uri, assertion
  File "/home/airflow/.local/lib/python3.7/site-packages/google/oauth2/_client.py", line 193, in jwt_grant
    response_data = _token_endpoint_request(request, token_uri, body)
  File "/home/airflow/.local/lib/python3.7/site-packages/google/oauth2/_client.py", line 165, in _token_endpoint_request
    _handle_error_response(response_data)
  File "/home/airflow/.local/lib/python3.7/site-packages/google/oauth2/_client.py", line 60, in _handle_error_response
    raise exceptions.RefreshError(error_details, response_data)
google.auth.exceptions.RefreshError: ('invalid_grant: Invalid grant: account not found', {'error': 'invalid_grant', 'error_description': 'Invalid grant: account not found'})
[2022-02-23 19:18:10,144] {local_task_job.py:154} INFO - Task exited with return code 1
[2022-02-23 19:18:10,198] {local_task_job.py:264} INFO - 0 downstream tasks scheduled from follow-on schedule check
[2022-02-23 20:04:07,082] {taskinstance.py:1032} INFO - Dependencies all met for <TaskInstance: fhv_gcs_dag.local_to_gcs_task scheduled__2019-03-02T00:00:00+00:00 [queued]>
[2022-02-23 20:04:07,175] {taskinstance.py:1032} INFO - Dependencies all met for <TaskInstance: fhv_gcs_dag.local_to_gcs_task scheduled__2019-03-02T00:00:00+00:00 [queued]>
[2022-02-23 20:04:07,176] {taskinstance.py:1238} INFO - 
--------------------------------------------------------------------------------
[2022-02-23 20:04:07,176] {taskinstance.py:1239} INFO - Starting attempt 1 of 2
[2022-02-23 20:04:07,176] {taskinstance.py:1240} INFO - 
--------------------------------------------------------------------------------
[2022-02-23 20:04:07,238] {taskinstance.py:1259} INFO - Executing <Task(PythonOperator): local_to_gcs_task> on 2019-03-02 00:00:00+00:00
[2022-02-23 20:04:07,257] {standard_task_runner.py:52} INFO - Started process 152 to run task
[2022-02-23 20:04:07,267] {standard_task_runner.py:76} INFO - Running: ['***', 'tasks', 'run', 'fhv_gcs_dag', 'local_to_gcs_task', 'scheduled__2019-03-02T00:00:00+00:00', '--job-id', '8', '--raw', '--subdir', 'DAGS_FOLDER/fhv_gcs_dag.py', '--cfg-path', '/tmp/tmph9_k5g7w', '--error-file', '/tmp/tmp3klonvd9']
[2022-02-23 20:04:07,269] {standard_task_runner.py:77} INFO - Job 8: Subtask local_to_gcs_task
[2022-02-23 20:04:07,607] {logging_mixin.py:109} INFO - Running <TaskInstance: fhv_gcs_dag.local_to_gcs_task scheduled__2019-03-02T00:00:00+00:00 [running]> on host 1bb54b80b2ee
[2022-02-23 20:04:07,717] {warnings.py:110} WARNING - /home/***/.local/lib/python3.7/site-packages/***/utils/context.py:152: AirflowContextDeprecationWarning: Accessing 'execution_date' from the template is deprecated and will be removed in a future version. Please use 'data_interval_start' or 'logical_date' instead.
  warnings.warn(_create_deprecation_warning(key, self._deprecation_replacements[key]))

[2022-02-23 20:04:07,794] {taskinstance.py:1426} INFO - Exporting the following env vars:
AIRFLOW_CTX_DAG_OWNER=***
AIRFLOW_CTX_DAG_ID=fhv_gcs_dag
AIRFLOW_CTX_TASK_ID=local_to_gcs_task
AIRFLOW_CTX_EXECUTION_DATE=2019-03-02T00:00:00+00:00
AIRFLOW_CTX_DAG_RUN_ID=scheduled__2019-03-02T00:00:00+00:00
[2022-02-23 20:04:08,182] {taskinstance.py:1700} ERROR - Task failed with exception
Traceback (most recent call last):
  File "/home/airflow/.local/lib/python3.7/site-packages/google/cloud/storage/blob.py", line 2594, in upload_from_file
    retry=retry,
  File "/home/airflow/.local/lib/python3.7/site-packages/google/cloud/storage/blob.py", line 2412, in _do_upload
    retry=retry,
  File "/home/airflow/.local/lib/python3.7/site-packages/google/cloud/storage/blob.py", line 2237, in _do_resumable_upload
    retry=retry,
  File "/home/airflow/.local/lib/python3.7/site-packages/google/cloud/storage/blob.py", line 2112, in _initiate_resumable_upload
    timeout=timeout,
  File "/home/airflow/.local/lib/python3.7/site-packages/google/resumable_media/requests/upload.py", line 421, in initiate
    retriable_request, self._get_status_code, self._retry_strategy
  File "/home/airflow/.local/lib/python3.7/site-packages/google/resumable_media/requests/_request_helpers.py", line 147, in wait_and_retry
    response = func()
  File "/home/airflow/.local/lib/python3.7/site-packages/google/resumable_media/requests/upload.py", line 416, in retriable_request
    self._process_initiate_response(result)
  File "/home/airflow/.local/lib/python3.7/site-packages/google/resumable_media/_upload.py", line 503, in _process_initiate_response
    callback=self._make_invalid,
  File "/home/airflow/.local/lib/python3.7/site-packages/google/resumable_media/_helpers.py", line 104, in require_status_code
    *status_codes
google.resumable_media.common.InvalidResponse: ('Request failed with status code', 403, 'Expected one of', <HTTPStatus.OK: 200>, <HTTPStatus.CREATED: 201>)

During handling of the above exception, another exception occurred:

Traceback (most recent call last):
  File "/home/airflow/.local/lib/python3.7/site-packages/airflow/models/taskinstance.py", line 1329, in _run_raw_task
    self._execute_task_with_callbacks(context)
  File "/home/airflow/.local/lib/python3.7/site-packages/airflow/models/taskinstance.py", line 1455, in _execute_task_with_callbacks
    result = self._execute_task(context, self.task)
  File "/home/airflow/.local/lib/python3.7/site-packages/airflow/models/taskinstance.py", line 1511, in _execute_task
    result = execute_callable(context=context)
  File "/home/airflow/.local/lib/python3.7/site-packages/airflow/operators/python.py", line 174, in execute
    return_value = self.execute_callable()
  File "/home/airflow/.local/lib/python3.7/site-packages/airflow/operators/python.py", line 185, in execute_callable
    return self.python_callable(*self.op_args, **self.op_kwargs)
  File "/opt/airflow/dags/fhv_gcs_dag.py", line 49, in upload_to_gcs
    blob.upload_from_filename(local_file)
  File "/home/airflow/.local/lib/python3.7/site-packages/google/cloud/storage/blob.py", line 2735, in upload_from_filename
    retry=retry,
  File "/home/airflow/.local/lib/python3.7/site-packages/google/cloud/storage/blob.py", line 2598, in upload_from_file
    _raise_from_invalid_response(exc)
  File "/home/airflow/.local/lib/python3.7/site-packages/google/cloud/storage/blob.py", line 4466, in _raise_from_invalid_response
    raise exceptions.from_http_status(response.status_code, message, response=response)
google.api_core.exceptions.Forbidden: 403 POST https://storage.googleapis.com/upload/storage/v1/b/data_lake_taxi_us/o?uploadType=resumable: {
  "error": {
    "code": 403,
    "message": "airflow-ingestion@clear-rock-338918.iam.gserviceaccount.com does not have storage.objects.create access to the Google Cloud Storage bucket.",
    "errors": [
      {
        "message": "airflow-ingestion@clear-rock-338918.iam.gserviceaccount.com does not have storage.objects.create access to the Google Cloud Storage bucket.",
        "domain": "global",
        "reason": "forbidden"
      }
    ]
  }
}
: ('Request failed with status code', 403, 'Expected one of', <HTTPStatus.OK: 200>, <HTTPStatus.CREATED: 201>)
[2022-02-23 20:04:08,221] {taskinstance.py:1277} INFO - Marking task as UP_FOR_RETRY. dag_id=fhv_gcs_dag, task_id=local_to_gcs_task, execution_date=20190302T000000, start_date=20220223T200407, end_date=20220223T200408
[2022-02-23 20:04:08,244] {standard_task_runner.py:92} ERROR - Failed to execute job 8 for task local_to_gcs_task
Traceback (most recent call last):
  File "/home/airflow/.local/lib/python3.7/site-packages/google/cloud/storage/blob.py", line 2594, in upload_from_file
    retry=retry,
  File "/home/airflow/.local/lib/python3.7/site-packages/google/cloud/storage/blob.py", line 2412, in _do_upload
    retry=retry,
  File "/home/airflow/.local/lib/python3.7/site-packages/google/cloud/storage/blob.py", line 2237, in _do_resumable_upload
    retry=retry,
  File "/home/airflow/.local/lib/python3.7/site-packages/google/cloud/storage/blob.py", line 2112, in _initiate_resumable_upload
    timeout=timeout,
  File "/home/airflow/.local/lib/python3.7/site-packages/google/resumable_media/requests/upload.py", line 421, in initiate
    retriable_request, self._get_status_code, self._retry_strategy
  File "/home/airflow/.local/lib/python3.7/site-packages/google/resumable_media/requests/_request_helpers.py", line 147, in wait_and_retry
    response = func()
  File "/home/airflow/.local/lib/python3.7/site-packages/google/resumable_media/requests/upload.py", line 416, in retriable_request
    self._process_initiate_response(result)
  File "/home/airflow/.local/lib/python3.7/site-packages/google/resumable_media/_upload.py", line 503, in _process_initiate_response
    callback=self._make_invalid,
  File "/home/airflow/.local/lib/python3.7/site-packages/google/resumable_media/_helpers.py", line 104, in require_status_code
    *status_codes
google.resumable_media.common.InvalidResponse: ('Request failed with status code', 403, 'Expected one of', <HTTPStatus.OK: 200>, <HTTPStatus.CREATED: 201>)

During handling of the above exception, another exception occurred:

Traceback (most recent call last):
  File "/home/airflow/.local/lib/python3.7/site-packages/airflow/task/task_runner/standard_task_runner.py", line 85, in _start_by_fork
    args.func(args, dag=self.dag)
  File "/home/airflow/.local/lib/python3.7/site-packages/airflow/cli/cli_parser.py", line 48, in command
    return func(*args, **kwargs)
  File "/home/airflow/.local/lib/python3.7/site-packages/airflow/utils/cli.py", line 92, in wrapper
    return f(*args, **kwargs)
  File "/home/airflow/.local/lib/python3.7/site-packages/airflow/cli/commands/task_command.py", line 298, in task_run
    _run_task_by_selected_method(args, dag, ti)
  File "/home/airflow/.local/lib/python3.7/site-packages/airflow/cli/commands/task_command.py", line 107, in _run_task_by_selected_method
    _run_raw_task(args, ti)
  File "/home/airflow/.local/lib/python3.7/site-packages/airflow/cli/commands/task_command.py", line 184, in _run_raw_task
    error_file=args.error_file,
  File "/home/airflow/.local/lib/python3.7/site-packages/airflow/utils/session.py", line 70, in wrapper
    return func(*args, session=session, **kwargs)
  File "/home/airflow/.local/lib/python3.7/site-packages/airflow/models/taskinstance.py", line 1329, in _run_raw_task
    self._execute_task_with_callbacks(context)
  File "/home/airflow/.local/lib/python3.7/site-packages/airflow/models/taskinstance.py", line 1455, in _execute_task_with_callbacks
    result = self._execute_task(context, self.task)
  File "/home/airflow/.local/lib/python3.7/site-packages/airflow/models/taskinstance.py", line 1511, in _execute_task
    result = execute_callable(context=context)
  File "/home/airflow/.local/lib/python3.7/site-packages/airflow/operators/python.py", line 174, in execute
    return_value = self.execute_callable()
  File "/home/airflow/.local/lib/python3.7/site-packages/airflow/operators/python.py", line 185, in execute_callable
    return self.python_callable(*self.op_args, **self.op_kwargs)
  File "/opt/airflow/dags/fhv_gcs_dag.py", line 49, in upload_to_gcs
    blob.upload_from_filename(local_file)
  File "/home/airflow/.local/lib/python3.7/site-packages/google/cloud/storage/blob.py", line 2735, in upload_from_filename
    retry=retry,
  File "/home/airflow/.local/lib/python3.7/site-packages/google/cloud/storage/blob.py", line 2598, in upload_from_file
    _raise_from_invalid_response(exc)
  File "/home/airflow/.local/lib/python3.7/site-packages/google/cloud/storage/blob.py", line 4466, in _raise_from_invalid_response
    raise exceptions.from_http_status(response.status_code, message, response=response)
google.api_core.exceptions.Forbidden: 403 POST https://storage.googleapis.com/upload/storage/v1/b/data_lake_taxi_us/o?uploadType=resumable: {
  "error": {
    "code": 403,
    "message": "airflow-ingestion@clear-rock-338918.iam.gserviceaccount.com does not have storage.objects.create access to the Google Cloud Storage bucket.",
    "errors": [
      {
        "message": "airflow-ingestion@clear-rock-338918.iam.gserviceaccount.com does not have storage.objects.create access to the Google Cloud Storage bucket.",
        "domain": "global",
        "reason": "forbidden"
      }
    ]
  }
}
: ('Request failed with status code', 403, 'Expected one of', <HTTPStatus.OK: 200>, <HTTPStatus.CREATED: 201>)
[2022-02-23 20:04:08,292] {local_task_job.py:154} INFO - Task exited with return code 1
[2022-02-23 20:04:08,354] {local_task_job.py:264} INFO - 0 downstream tasks scheduled from follow-on schedule check
[2022-02-23 20:40:02,057] {taskinstance.py:1032} INFO - Dependencies all met for <TaskInstance: fhv_gcs_dag.local_to_gcs_task scheduled__2019-03-02T00:00:00+00:00 [queued]>
[2022-02-23 20:40:02,075] {taskinstance.py:1032} INFO - Dependencies all met for <TaskInstance: fhv_gcs_dag.local_to_gcs_task scheduled__2019-03-02T00:00:00+00:00 [queued]>
[2022-02-23 20:40:02,075] {taskinstance.py:1238} INFO - 
--------------------------------------------------------------------------------
[2022-02-23 20:40:02,075] {taskinstance.py:1239} INFO - Starting attempt 1 of 2
[2022-02-23 20:40:02,075] {taskinstance.py:1240} INFO - 
--------------------------------------------------------------------------------
[2022-02-23 20:40:02,097] {taskinstance.py:1259} INFO - Executing <Task(PythonOperator): local_to_gcs_task> on 2019-03-02 00:00:00+00:00
[2022-02-23 20:40:02,105] {standard_task_runner.py:52} INFO - Started process 214 to run task
[2022-02-23 20:40:02,109] {standard_task_runner.py:76} INFO - Running: ['***', 'tasks', 'run', 'fhv_gcs_dag', 'local_to_gcs_task', 'scheduled__2019-03-02T00:00:00+00:00', '--job-id', '7', '--raw', '--subdir', 'DAGS_FOLDER/fhv_gcs_dag.py', '--cfg-path', '/tmp/tmpkdokelwe', '--error-file', '/tmp/tmpo5j4f_3k']
[2022-02-23 20:40:02,111] {standard_task_runner.py:77} INFO - Job 7: Subtask local_to_gcs_task
[2022-02-23 20:40:02,170] {logging_mixin.py:109} INFO - Running <TaskInstance: fhv_gcs_dag.local_to_gcs_task scheduled__2019-03-02T00:00:00+00:00 [running]> on host 1c172e0325c8
[2022-02-23 20:40:02,209] {warnings.py:110} WARNING - /home/***/.local/lib/python3.7/site-packages/***/utils/context.py:152: AirflowContextDeprecationWarning: Accessing 'execution_date' from the template is deprecated and will be removed in a future version. Please use 'data_interval_start' or 'logical_date' instead.
  warnings.warn(_create_deprecation_warning(key, self._deprecation_replacements[key]))

[2022-02-23 20:40:02,231] {taskinstance.py:1426} INFO - Exporting the following env vars:
AIRFLOW_CTX_DAG_OWNER=***
AIRFLOW_CTX_DAG_ID=fhv_gcs_dag
AIRFLOW_CTX_TASK_ID=local_to_gcs_task
AIRFLOW_CTX_EXECUTION_DATE=2019-03-02T00:00:00+00:00
AIRFLOW_CTX_DAG_RUN_ID=scheduled__2019-03-02T00:00:00+00:00
[2022-02-23 20:40:05,430] {python.py:175} INFO - Done. Returned value was: None
[2022-02-23 20:40:05,448] {taskinstance.py:1277} INFO - Marking task as SUCCESS. dag_id=fhv_gcs_dag, task_id=local_to_gcs_task, execution_date=20190302T000000, start_date=20220223T204002, end_date=20220223T204005
[2022-02-23 20:40:05,511] {local_task_job.py:154} INFO - Task exited with return code 0
[2022-02-23 20:40:05,569] {local_task_job.py:264} INFO - 1 downstream tasks scheduled from follow-on schedule check
=======
>>>>>>> origin/master
